Workbook

Sheet Demand
A1: Antigen | B1: 2000 | C1: 2001 | D1: 2002 | E1: 2003 | F1: 2004 | G1: 2005 | H1: 2006 | I1: 2007 | J1: 2008 | K1: 2009 | L1: 2010 | M1: 2011 | N1: 2012 | O1: 2013 | P1: 2014 | Q1: 2015 | R1: 2016 | S1: 2017 | T1: 2018 | U1: 2019 | V1: 2020 | W1: 2021 | X1: 2022 | Y1: 2023
A2: Measles | B2: =ROUND('antigen demand calcs'!C40,0) -> 110184355 | C2: =ROUND('antigen demand calcs'!D40,0) -> 114307142 | D2: =ROUND('antigen demand calcs'!E40,0) -> 112328294 | E2: =ROUND('antigen demand calcs'!F40,0) -> 120587958 | F2: =ROUND('antigen demand calcs'!G40,0) -> 129895993 | G2: =ROUND('antigen demand calcs'!H40,0) -> 148890003 | H2: =ROUND('antigen demand calcs'!I40,0) -> 155481077 | I2: =ROUND('antigen demand calcs'!J40,0) -> 159027889 | ... Y2: =ROUND('antigen demand calcs'!Z40,0) -> 394831633
A3: Mumps | B3: =ROUND('antigen demand calcs'!C41,0) -> 14895547 | C3: =ROUND('antigen demand calcs'!D41,0) -> 15916937 | D3: =ROUND('antigen demand calcs'!E41,0) -> 16440302 | E3: =ROUND('antigen demand calcs'!F41,0) -> 17051794 | F3: =ROUND('antigen demand calcs'!G41,0) -> 25753121 | G3: =ROUND('antigen demand calcs'!H41,0) -> 26516485 | H3: =ROUND('antigen demand calcs'!I41,0) -> 28053836 | I3: =ROUND('antigen demand calcs'!J41,0) -> 27963867 | ... Y3: =ROUND('antigen demand calcs'!Z41,0) -> 25785425
A4: Rubella | B4: =ROUND('antigen demand calcs'!C42,0) -> 31604096 | C4: =ROUND('antigen demand calcs'!D42,0) -> 32625821 | D4: =ROUND('antigen demand calcs'!E42,0) -> 33061541 | E4: =ROUND('antigen demand calcs'!F42,0) -> 33964093 | F4: =ROUND('antigen demand calcs'!G42,0) -> 43743914 | G4: =ROUND('antigen demand calcs'!H42,0) -> 58741080 | H4: =ROUND('antigen demand calcs'!I42,0) -> 64064132 | I4: =ROUND('antigen demand calcs'!J42,0) -> 63602346 | ... Y4: =ROUND('antigen demand calcs'!Z42,0) -> 304621416
A5: Diphtheria | B5: =ROUND('antigen demand calcs'!C43,0) -> 420502653 | C5: =ROUND('antigen demand calcs'!D43,0) -> 430423519 | D5: =ROUND('antigen demand calcs'!E43,0) -> 422659120 | E5: =ROUND('antigen demand calcs'!F43,0) -> 442151969 | F5: =ROUND('antigen demand calcs'!G43,0) -> 485071830 | G5: =ROUND('antigen demand calcs'!H43,0) -> 506451337 | H5: =ROUND('antigen demand calcs'!I43,0) -> 487823186 | I5: =ROUND('antigen demand calcs'!J43,0) -> 483645320 | ... Y5: =ROUND('antigen demand calcs'!Z43,0) -> 626455401
A6: Tetanus | B6: =ROUND('antigen demand calcs'!C44,0) -> 498662082 | C6: =ROUND('antigen demand calcs'!D44,0) -> 510178451 | D6: =ROUND('antigen demand calcs'!E44,0) -> 505231192 | E6: =ROUND('antigen demand calcs'!F44,0) -> 527899341 | F6: =ROUND('antigen demand calcs'!G44,0) -> 573895332 | G6: =ROUND('antigen demand calcs'!H44,0) -> 597432163 | H6: =ROUND('antigen demand calcs'!I44,0) -> 581257411 | I6: =ROUND('antigen demand calcs'!J44,0) -> 581750577 | ... Y6: =ROUND('antigen demand calcs'!Z44,0) -> 633278479
A7: Pertussis | B7: =ROUND('antigen demand calcs'!C45,0) -> 348814438 | C7: =ROUND('antigen demand calcs'!D45,0) -> 359116487 | D7: =ROUND('antigen demand calcs'!E45,0) -> 352212313 | E7: =ROUND('antigen demand calcs'!F45,0) -> 369903178 | F7: =ROUND('antigen demand calcs'!G45,0) -> 396047209 | G7: =ROUND('antigen demand calcs'!H45,0) -> 419499805 | H7: =ROUND('antigen demand calcs'!I45,0) -> 412793682 | I7: =ROUND('antigen demand calcs'!J45,0) -> 410544078 | ... Y7: =ROUND('antigen demand calcs'!Z45,0) -> 352464578
A8: Hepatitis_B | B8: =ROUND('antigen demand calcs'!C46,0) -> 53534395 | C8: =ROUND('antigen demand calcs'!D46,0) -> 65035577 | D8: =ROUND('antigen demand calcs'!E46,0) -> 142552460 | E8: =ROUND('antigen demand calcs'!F46,0) -> 176861989 | F8: =ROUND('antigen demand calcs'!G46,0) -> 210343448 | G8: =ROUND('antigen demand calcs'!H46,0) -> 242350719 | H8: =ROUND('antigen demand calcs'!I46,0) -> 250960256 | I8: =ROUND('antigen demand calcs'!J46,0) -> 265949497 | ... Y8: =ROUND('antigen demand calcs'!Z46,0) -> 351717780
A9: Hib | B9: =ROUND('antigen demand calcs'!C47,0) -> 10972631 | C9: =ROUND('antigen demand calcs'!D47,0) -> 14749478 | D9: =ROUND('antigen demand calcs'!E47,0) -> 24848263 | E9: =ROUND('antigen demand calcs'!F47,0) -> 29092822 | F9: =ROUND('antigen demand calcs'!G47,0) -> 41843072 | G9: =ROUND('antigen demand calcs'!H47,0) -> 51014896 | H9: =ROUND('antigen demand calcs'!I47,0) -> 52364656 | I9: =ROUND('antigen demand calcs'!J47,0) -> 79540844 | ... Y9: =ROUND('antigen demand calcs'!Z47,0) -> 287252889
A10: Polio | B10: 3.016948e+08 | C10: 3.2502067e+08 | D10: 3.3051618e+08 | E10: 3.4522736e+08 | F10: 3.7012296e+08 | G10: 3.7992919e+08 | H10: 3.7711609e+08 | I10: 3.832422e+08 | J10: 3.8313196e+08 | K10: 3.9770698e+08 | L10: 3.8673892e+08 | M10: 4.0261133e+08 | N10: 3.4551449e+08 | O10: 3.545115e+08 | P10: 3.551861e+08 | Q10: 3.7159167e+08 | R10: 4.5914821e+08 | S10: 5.1074954e+08 | T10: 5.2061614e+08 | U10: 5.4589236e+08 | V10: 5.2568108e+08 | W10: 5.2218201e+08 | X10: 5.8218228e+08 | Y10: 6.0863176e+08
A11: HPV | B11: =ROUND('antigen demand calcs'!C49,0) -> 0 | C11: =ROUND('antigen demand calcs'!D49,0) -> 0 | D11: =ROUND('antigen demand calcs'!E49,0) -> 0 | E11: =ROUND('antigen demand calcs'!F49,0) -> 0 | F11: =ROUND('antigen demand calcs'!G49,0) -> 0 | G11: =ROUND('antigen demand calcs'!H49,0) -> 0 | H11: =ROUND('antigen demand calcs'!I49,0) -> 0 | I11: =ROUND('antigen demand calcs'!J49,0) -> 0 | ... Y11: =ROUND('antigen demand calcs'!Z49,0) -> 27459977
A12: Rotavirus | B12: =ROUND('antigen demand calcs'!C50,0) -> 0 | C12: =ROUND('antigen demand calcs'!D50,0) -> 0 | D12: =ROUND('antigen demand calcs'!E50,0) -> 0 | E12: =ROUND('antigen demand calcs'!F50,0) -> 0 | F12: =ROUND('antigen demand calcs'!G50,0) -> 0 | G12: =ROUND('antigen demand calcs'!H50,0) -> 0 | H12: =ROUND('antigen demand calcs'!I50,0) -> 3029896 | I12: =ROUND('antigen demand calcs'!J50,0) -> 7758596 | ... Y12: =ROUND('antigen demand calcs'!Z50,0) -> 173751395
A13: PCV | B13: =ROUND('antigen demand calcs'!C51,0) -> 0 | C13: =ROUND('antigen demand calcs'!D51,0) -> 0 | D13: =ROUND('antigen demand calcs'!E51,0) -> 0 | E13: =ROUND('antigen demand calcs'!F51,0) -> 0 | F13: =ROUND('antigen demand calcs'!G51,0) -> 0 | G13: =ROUND('antigen demand calcs'!H51,0) -> 0 | H13: =ROUND('antigen demand calcs'!I51,0) -> 0 | I13: =ROUND('antigen demand calcs'!J51,0) -> 0 | ... Y13: =ROUND('antigen demand calcs'!Z51,0) -> 209165466

Sheet antigen demand calcs
A1: Vaccine | B1: wb_status | C1: 2000 | D1: 2001 | E1: 2002 | F1: 2003 | G1: 2004 | H1: 2005 | I1: 2006 | J1: 2007 | K1: 2008 | L1: 2009 | M1: 2010 | N1: 2011 | O1: 2012 | P1: 2013 | Q1: 2014 | R1: 2015 | S1: 2016 | T1: 2017 | U1: 2018 | V1: 2019 | W1: 2020 | X1: 2021 | Y1: 2022 | Z1: 2023 | AA1: 2024 | AB1: 2025 | AC1: 2026 | AD1: 2027 | AE1: 2028 | AF1: 2029 | AG1: 2030
A2: bOPV | B2: Low Income | S2: 72730018 | T2: 1.0570712e+08 | U2: 1.051229e+08 | V2: 1.1719715e+08 | W2: 1.0988395e+08 | X2: 1.0245493e+08 | Y2: 1.0451565e+08 | Z2: 1.1158238e+08 | AA2: 1.1227561e+08 | AB2: 1.1406168e+08 | AC2: 1.0751713e+08
A3: bOPV | B3: Lower Middle Income | S3: 2.4814683e+08 | T3: 3.5337387e+08 | U3: 3.5043672e+08 | V3: 3.4662104e+08 | W3: 3.3593955e+08 | X3: 3.3594803e+08 | Y3: 3.6575567e+08 | Z3: 3.6623113e+08 | AA3: 3.4781636e+08 | AB3: 3.4731021e+08 | AC3: 3.3650907e+08
A4: DT | B4: Low Income | C4: 17559921 | D4: 1530590.5 | E4: 1386901.7 | F4: 1320690.4 | G4: 678429.41 | H4: 468765.33 | I4: 473725.65 | J4: 343604.27 | K4: 340659.15 | L4: 359787.73 | M4: 367309.28 | N4: 377112.44 | O4: 390295.27 | P4: 390036.34 | Q4: 428852.85 | R4: 264882.34 | V4: 674796.85 | W4: 4156434.5 | X4: 4315320.2 | Y4: 4110923.5 | Z4: 4246029.6 | AA4: 4705085.7 | AB4: 4789178.8 | AC4: 718943.29 | AD4: 759633.2 | AE4: 785092.08 | AF4: 821841.37 | AG4: 863986.72
A5: DT | B5: Lower Middle Income | C5: 3364029.3 | D5: 19002103 | E5: 18724673 | F5: 18071980 | G5: 18376274 | H5: 18225152 | I5: 19831936 | J5: 19572618 | K5: 19597297 | L5: 19465616 | M5: 18787990 | N5: 18949188 | O5: 1565811.3 | P5: 1478823.8 | Q5: 1472017.6 | R5: 1622398.4 | S5: 1784486.6 | T5: 2200512.6 | U5: 2217689.2 | V5: 1502990.7 | W5: 906377.51 | X5: 2089581.7 | Y5: 2331416 | Z5: 2295538.3 | AA5: 1554268.8 | AB5: 1550926 | AC5: 5699436.3 | AD5: 5324019.7 | AE5: 5339861.9 | AF5: 5355310.6 | AG5: 5370201.9
A6: DTwP | B6: Low Income | C6: 2.6975463e+08 | D6: 2.2354762e+08 | E6: 1.9153656e+08 | F6: 1.7465685e+08 | G6: 1.6283034e+08 | H6: 1.4872301e+08 | I6: 1.3922249e+08 | J6: 1.2420992e+08 | K6: 1.2640711e+08 | L6: 4726272 | M6: 5302588 | N6: 2799845 | O6: 2089677 | P6: 1099248.7 | Q6: 1116399.3 | R6: 1057920.2 | S6: 1205402.6 | T6: 1198261.3 | U6: 1203338.8 | V6: 1488312.8 | W6: 990784.97 | X6: 1000720.2 | Y6: 540136.76 | Z6: 550198.35 | AA6: 868326.13 | AB6: 877675.33 | AC6: 887468.02 | AD6: 892701.99 | AE6: 902401.62 | AF6: 912272 | AG6: 924903.77
A7: DTwP | B7: Lower Middle Income | C7: 41844188 | D7: 91365590 | E7: 83561666 | F7: 88214606 | G7: 98298298 | H7: 1.08315e+08 | I7: 1.0411446e+08 | J7: 1.0359087e+08 | K7: 99538287 | L7: 2.2808726e+08 | M7: 2.3002554e+08 | N7: 2.3015768e+08 | O7: 1.4232815e+08 | P7: 1.4109257e+08 | Q7: 1.3786961e+08 | R7: 90250034 | S7: 63748764 | T7: 65432154 | U7: 65252371 | V7: 64388026 | W7: 60521191 | X7: 61053431 | Y7: 64873850 | Z7: 65291644 | AA7: 61084402 | AB7: 59641976 | AC7: 57111113 | AD7: 57225194 | AE7: 56990919 | AF7: 56836559 | AG7: 56671594
A8: DTwP-HepB | B8: Low Income | C8: 4022337.4 | D8: 9132803 | E8: 32774906 | F8: 59966730 | G8: 74805232 | H8: 72923950 | I8: 79632873 | J8: 79699130 | K8: 74627086 | L8: 27533932 | M8: 4311581.6 | N8: 4075044.5
A9: DTwP-HepB | B9: Lower Middle Income | C9: 23024915 | D9: 21135404 | E9: 20282204 | F9: 18717847 | G9: 19067877 | H9: 39316459 | I9: 38266526 | J9: 39001298 | K9: 38257392 | L9: 35187107 | M9: 49160759 | N9: 47687538 | O9: 42390888 | P9: 32664573 | Q9: 9459058.5
A10: DTwP-HepB-Hib | B10: Low Income | C10: 1268703 | D10: 4305415.7 | E10: 12713494 | F10: 13209616 | G10: 14428616 | H10: 20795854 | I10: 23601783 | J10: 32989731 | K10: 47402129 | L10: 94686290 | M10: 86371467 | N10: 79360205 | O10: 78464864 | P10: 79671724 | Q10: 83288701 | R10: 82852505 | S10: 66992001 | T10: 69306694 | U10: 70472115 | V10: 76836516 | W10: 72833944 | X10: 65525121 | Y10: 67056769 | Z10: 71525747 | AA10: 71197101 | AB10: 72182552 | AC10: 67897098 | AD10: 63701819 | AE10: 65137551 | AF10: 66756003 | AG10: 68258991
A11: DTwP-HepB-Hib | B11: Lower Middle Income | C11: 4329681.2 | D11: 7015866.3 | E11: 9028693.1 | F11: 10144469 | G11: 19885297 | H11: 23596036 | I11: 25566672 | J11: 28370794 | K11: 20860421 | L11: 27191373 | M11: 37361829 | N11: 50484937 | O11: 64341882 | P11: 71556824 | Q11: 92204378 | R11: 1.5128082e+08 | S11: 1.9428433e+08 | T11: 1.9745086e+08 | U11: 2.0496682e+08 | V11: 2.0332514e+08 | W11: 1.9618265e+08 | X11: 1.8725689e+08 | Y11: 2.0912663e+08 | Z11: 2.092424e+08 | AA11: 1.9665218e+08 | AB11: 1.9594688e+08 | AC11: 1.9590304e+08 | AD11: 2.0313958e+08 | AE11: 1.99243e+08 | AF11: 2.0087072e+08 | AG11: 2.0231063e+08
A12: DTwP-Hib | B12: Low Income | G12: 1556935 | V12: 2577182.4 | W12: 2545600.6 | X12: 3007587.1 | Y12: 3039919.6 | Z12: 3128143.7 | AA12: 3222722.9 | AB12: 3317314 | AC12: 3413368.9 | AD12: 3509043.3 | AE12: 3602125.6 | AF12: 3694964.4 | AG12: 3781590.9
A13: DTwP-Hib | B13: Lower Middle Income | C13: 4569986.5 | D13: 2613786 | E13: 2314794.7 | F13: 4993056.6 | G13: 5174614.6 | H13: 5829500.6 | I13: 2388879.2 | J13: 2682334 | K13: 5503855 | L13: 6149962.6 | M13: 2755123.1 | N13: 3016433.5 | O13: 2770511.6 | P13: 2616817.9 | X13: 2818989.8 | Y13: 2776716.8 | Z13: 2726441.2 | AA13: 2674099.1 | AB13: 2608856.6 | AC13: 2540714 | AD13: 2482740.1 | AE13: 2432924 | AF13: 2391715.8 | AG13: 2364272.5
A14: HepB | B14: Low Income | C14: 4331476.1 | D14: 6232568.6 | E14: 7573656.9 | F14: 8589234.5 | G14: 8337475.9 | H14: 5921398.1 | I14: 7214281.6 | J14: 7538299.5 | K14: 26377575 | L14: 9809642.4 | M14: 3487804.8 | N14: 1299037.6 | O14: 1181339 | P14: 1318899.3 | Q14: 2110042.1 | R14: 2295045.4 | S14: 2030761.8 | T14: 2451159.5 | U14: 2498551.1 | V14: 3063973 | W14: 2971735.8 | X14: 2464479.4 | Y14: 3343214 | Z14: 7632520.8 | AA14: 8361209.6 | AB14: 8058386.7 | AC14: 8258917.1 | AD14: 8449841.9 | AE14: 8610263.4 | AF14: 8770774.6 | AG14: 8918362.8
A15: HepB | B15: Lower Middle Income | C15: 16557281 | D15: 17213520 | E15: 60179506 | F15: 66234092 | G15: 73818949 | H15: 79797021 | I15: 76678121 | J15: 78350244 | K15: 76448047 | L15: 1.0530429e+08 | M15: 1.07385e+08 | N15: 1.5595153e+08 | O15: 1.2242813e+08 | P15: 1.2180132e+08 | Q15: 1.1759314e+08 | R15: 70158224 | S15: 47608205 | T15: 49612878 | U15: 54400359 | V15: 56833893 | W15: 57301981 | X15: 57038073 | Y15: 63481542 | Z15: 63317108 | AA15: 58484918 | AB15: 57987736 | AC15: 56088061 | AD15: 56731242 | AE15: 55209697 | AF15: 55817447 | AG15: 56037443
A16: Hib | B16: Low Income | D16: 396598.78 | E16: 370781.45 | F16: 377404.37
A17: Hib | B17: Lower Middle Income | C17: 804259.79 | D17: 417810.79 | E17: 420500.28 | F17: 368275.5 | G17: 797608.28 | H17: 793505.36 | I17: 807322.46 | J17: 15497985 | K17: 23015254 | L17: 29554013 | M17: 28143333 | N17: 27963364 | O17: 287270.78 | P17: 295912.23 | Q17: 313516.51 | R17: 300997.52 | S17: 430151.71 | T17: 1240330.4 | U17: 1797781.7 | V17: 1041960.4 | W17: 903155.61 | X17: 927637.83 | Y17: 777066.98 | Z17: 630153.09 | AA17: 3543.6963 | AB17: 3783.6458 | AC17: 4031.9913
A18: HPV | B18: Low Income | Q18: 139870.96 | R18: 377461.87 | S18: 634814.46 | T18: 1033940.1 | U18: 5003730.1 | V18: 5393319.7 | W18: 5003570.8 | X18: 8445039.9 | Y18: 8068490.5 | Z18: 8697354 | AA18: 8639302 | AB18: 8865939.6 | AC18: 13281006 | AD18: 15657631 | AE18: 14215990 | AF18: 7927817.9 | AG18: 9024207.2
A19: HPV | B19: Lower Middle Income | K19: 9436.6316 | L19: 15032.895 | M19: 7007.8355 | N19: 15317.591 | O19: 60837.39 | P19: 181340.94 | Q19: 210053.61 | R19: 137191.65 | S19: 910842.81 | T19: 1453860.8 | U19: 1955986.6 | V19: 4882640.8 | W19: 7008411.1 | X19: 10543170 | Y19: 10711344 | Z19: 18762623 | AA19: 64210185 | AB19: 83804666 | AC19: 51422768 | AD19: 26579344 | AE19: 28152444 | AF19: 25802649 | AG19: 26014338
A20: IPV | B20: Low Income | Q20: 182557.13 | R20: 5620506 | S20: 11783969 | T20: 13589576 | U20: 17163411 | V20: 30497092 | W20: 28965671 | X20: 21892027 | Y20: 35370386 | Z20: 43383048 | AA20: 44168093 | AB20: 44456828 | AC20: 42173052 | AD20: 39813929 | AE20: 40842161 | AF20: 41967859 | AG20: 42986086
A21: IPV | B21: Lower Middle Income | I21: 538568.8 | J21: 572237.68 | K21: 1564054.1 | L21: 1802422.6 | M21: 1596326.4 | N21: 1432203.2 | O21: 1193206.4 | P21: 1051750 | Q21: 655606.6 | R21: 8514221.2 | S21: 33776311 | T21: 38078979 | U21: 47893109 | V21: 51577087 | W21: 50891907 | X21: 61887020 | Y21: 76540581 | Z21: 87435210 | AA21: 86151312 | AB21: 85634775 | AC21: 86020717 | AD21: 90723780 | AE21: 87674087 | AF21: 88839419 | AG21: 89969890
A22: Measles | B22: Low Income | C22: 63561708 | D22: 65863053 | E22: 66234990 | F22: 70545808 | G22: 74569463 | H22: 72218159 | I22: 75752536 | J22: 75573263 | K22: 99140522 | L22: 58385337 | M22: 46905841 | N22: 37625576 | O22: 38086071 | P22: 38514086 | Q22: 34224621 | R22: 59441116 | S22: 76295810 | T22: 51515829 | U22: 36648359 | V22: 50476128 | W22: 43812591 | X22: 29085303 | Y22: 55790517 | Z22: 71801072 | AA22: 32068651 | AB22: 48376248 | AC22: 11006235 | AD22: 5751303.3 | AE22: 829582.93 | AF22: 854456.6 | AG22: 882693.02
A23: Measles | B23: Lower Middle Income | C23: 15018551 | D23: 15818268 | E23: 13031763 | F23: 16078057 | G23: 11582616 | H23: 17930764 | I23: 15664409 | J23: 19852279 | K23: 21254444 | L23: 51794489 | M23: 77873446 | N23: 1.0878593e+08 | O23: 87849290 | P23: 1.088964e+08 | Q23: 91757360 | R23: 1.5358586e+08 | S23: 1.2083923e+08 | T23: 1.425375e+08 | U23: 1.1556112e+08 | V23: 70545562 | W23: 34562151 | X23: 33680396 | Y23: 48814950 | Z23: 18409145 | AA23: 37130706 | AB23: 37845518 | AC23: 9937258.7 | AD23: 6686267 | AE23: 70126.467 | AF23: 69021.517 | AG23: 68866.2
A24: MMR | B24: Low Income | C24: 494428.58 | D24: 1252693.4 | E24: 1431844.2 | F24: 1643920.6 | G24: 735200.85 | H24: 473640.31 | I24: 1876588.8 | J24: 1433166.1 | K24: 1334602.9 | L24: 1208205.2 | M24: 1747397.4 | N24: 201954.98 | O24: 214970.91 | P24: 224150.07 | Q24: 219907.2 | V24: 702827.93 | W24: 1095366.4 | X24: 1621323.6 | Y24: 837918.02 | Z24: 938540.61 | AA24: 1767344.8 | AB24: 1722886.3 | AC24: 1846729.1 | AD24: 1948070.2 | AE24: 2019683.9 | AF24: 2086697.6 | AG24: 2148068.1
A25: MMR | B25: Lower Middle Income | C25: 14401118 | D25: 14664243 | E25: 15008458 | F25: 15407874 | G25: 25017921 | H25: 26042845 | I25: 26177247 | J25: 26530701 | K25: 38119786 | L25: 40004904 | M25: 41179348 | N25: 42683232 | O25: 21933812 | P25: 21881492 | Q25: 19617870 | R25: 26434485 | S25: 20737739 | T25: 20303126 | U25: 23934205 | V25: 21090144 | W25: 17599593 | X25: 24430832 | Y25: 25788481 | Z25: 24846884 | AA25: 23500756 | AB25: 21813355 | AC25: 14358687 | AD25: 16702359 | AE25: 6889945.6 | AF25: 8631762.2 | AG25: 10829591
A26: MR | B26: Low Income | C26: 14865737 | D26: 190382.67 | E26: 186142.83 | F26: 176643.37 | G26: 170095.33 | H26: 166748.63 | I26: 182480.23 | J26: 178017.32 | K26: 422733.04 | L26: 1017321.6 | M26: 1071927.9 | N26: 1119766.7 | O26: 3944766.9 | P26: 2160744 | Q26: 20609940 | R26: 44346457 | S26: 17555529 | T26: 32760231 | U26: 38573931 | V26: 88974682 | W26: 27081268 | X26: 18124657 | Y26: 31843809 | Z26: 55432028 | AA26: 49867200 | AB26: 78223394 | AC26: 1.5433708e+08 | AD26: 69304118 | AE26: 1.2262746e+08 | AF26: 77770558 | AG26: 84871746
A27: MR | B27: Lower Middle Income | C27: 1842811.9 | D27: 16518502 | E27: 16435096 | F27: 16735655 | G27: 17820697 | H27: 32057846 | I27: 35827815 | J27: 35460462 | K27: 20670530 | L27: 21335803 | M27: 21312763 | N27: 19963824 | O27: 303293.88 | P27: 12923805 | Q27: 3492314 | R27: 57521927 | S27: 71950369 | T27: 1.3357989e+08 | U27: 3.7159602e+08 | V27: 2.4345075e+08 | W27: 1.6720978e+08 | X27: 3.1315449e+08 | Y27: 1.9554121e+08 | Z27: 2.2340396e+08 | AA27: 2.017585e+08 | AB27: 1.8958767e+08 | AC27: 2.160002e+08 | AD27: 1.7112005e+08 | AE27: 2.5415433e+08 | AF27: 2.0110336e+08 | AG27: 2.2800721e+08
A28: PCV | B28: Low Income | L28: 200203.1 | M28: 792873.5 | N28: 3573120.6 | O28: 13105393 | P28: 23519864 | Q28: 35445643 | R28: 49433123 | S28: 45314501 | T28: 48142460 | U28: 49917921 | V28: 54728261 | W28: 52263909 | X28: 50129919 | Y28: 50973687 | Z28: 57598467 | AA28: 57002192 | AB28: 62929823 | AC28: 57826520 | AD28: 54316313 | AE28: 55351627 | AF28: 56397188 | AG28: 57292566
A29: PCV | B29: Lower Middle Income | K29: 6300.6316 | L29: 1516684.8 | M29: 786662.91 | N29: 5754403.2 | O29: 10042216 | P29: 17650152 | Q29: 30776493 | R29: 40323260 | S29: 62289480 | T29: 79184760 | U29: 86610946 | V29: 90834244 | W29: 89547924 | X29: 1.1067031e+08 | Y29: 1.3602241e+08 | Z29: 1.51567e+08 | AA29: 1.4893626e+08 | AB29: 1.5806884e+08 | AC29: 1.6128006e+08 | AD29: 1.679548e+08 | AE29: 1.6198394e+08 | AF29: 1.6236738e+08 | AG29: 1.6294169e+08
A30: Rota | B30: Low Income | I30: 208687.76 | O30: 1054459.2 | P30: 7440100.5 | Q30: 19819134 | R30: 26144223 | S30: 24700701 | T30: 25890435 | U30: 29803933 | V30: 36884669 | W30: 39808137 | X30: 37309764 | Y30: 44236371 | Z30: 46707304 | AA30: 47358196 | AB30: 50033722 | AC30: 49087678 | AD30: 45162149 | AE30: 46076439 | AF30: 47168670 | AG30: 48207997
A31: Rota | B31: Lower Middle Income | I31: 2821208.1 | J31: 7758595.7 | K31: 1545856.4 | L31: 4340799.7 | M31: 3509131.3 | N31: 5934020.8 | O31: 10716830 | P31: 13794965 | Q31: 15321985 | R31: 18353546 | S31: 30641223 | T31: 40774102 | U31: 63288976 | V31: 89640997 | W31: 1.0245318e+08 | X31: 1.0516924e+08 | Y31: 1.2218571e+08 | Z31: 1.2704409e+08 | AA31: 1.3897017e+08 | AB31: 1.4763457e+08 | AC31: 1.5656465e+08 | AD31: 1.643907e+08 | AE31: 1.6127911e+08 | AF31: 1.6243762e+08 | AG31: 1.6359484e+08
A32: Td | B32: Low Income | C32: 12520130 | D32: 18459326 | E32: 17806694 | F32: 18064525 | G32: 13686781 | H32: 5480536.1 | I32: 5341472.3 | J32: 4073879.6 | K32: 3935782.4 | L32: 3709156.6 | M32: 4644192.5 | N32: 2730191 | O32: 2014157.8 | P32: 2305720.5 | Q32: 2817138.6 | R32: 4801489 | S32: 9978901 | T32: 11568981 | U32: 16792319 | V32: 34386709 | W32: 50231661 | X32: 54546919 | Y32: 54263004 | Z32: 64555189 | AA32: 63941710 | AB32: 64166708 | AC32: 57647264 | AD32: 57101205 | AE32: 58421305 | AF32: 59881165 | AG32: 61286058
A33: Td | B33: Lower Middle Income | C33: 38244136 | D33: 32315012 | E33: 32528538 | F33: 34791597 | G33: 56283137 | H33: 62777079 | I33: 49382370 | J33: 49111140 | K33: 34422404 | L33: 32579984 | M33: 27203350 | N33: 27147858 | O33: 25210493 | P33: 26083717 | Q33: 26224815 | R33: 30127177 | S33: 64806005 | T33: 82501135 | U33: 1.1319642e+08 | V33: 2.1008635e+08 | W33: 2.1860237e+08 | X33: 1.8893559e+08 | Y33: 2.1142055e+08 | Z33: 2.0289407e+08 | AA33: 1.883188e+08 | AB33: 1.9061813e+08 | AC33: 1.950018e+08 | AD33: 1.9866236e+08 | AE33: 1.9509893e+08 | AF33: 1.9718683e+08 | AG33: 1.9832674e+08
A34: tOPV | B34: Low Income | C34: 2.1668946e+08 | D34: 1.948458e+08 | E34: 2.0304457e+08 | F34: 2.1437949e+08 | G34: 2.2027414e+08 | H34: 2.1203657e+08 | I34: 2.1304702e+08 | J34: 2.1163017e+08 | K34: 2.2045201e+08 | L34: 1.4972549e+08 | M34: 1.1034946e+08 | N34: 99981438 | O34: 95750492 | P34: 98195403 | Q34: 1.0363215e+08 | R34: 1.0534095e+08 | S34: 21214862
A35: tOPV | B35: Lower Middle Income | C35: 85005337 | D35: 1.3017487e+08 | E35: 1.2747161e+08 | F35: 1.3084787e+08 | G35: 1.4984882e+08 | H35: 1.6789262e+08 | I35: 1.635305e+08 | J35: 1.7103979e+08 | K35: 1.611159e+08 | L35: 2.4617907e+08 | M35: 2.7479314e+08 | N35: 3.0119769e+08 | O35: 2.4857079e+08 | P35: 2.5526435e+08 | Q35: 2.5071579e+08 | R35: 2.52116e+08 | S35: 71496217
A36: TT | B36: Low Income | C36: 65679323 | D36: 68123874 | E36: 70683569 | F36: 72599025 | G36: 75483536 | H36: 66019820 | I36: 68769180 | J36: 70830372 | K36: 73233979 | L36: 74316021 | M36: 52508675 | N36: 48238566 | O36: 48637177 | P36: 50304857 | Q36: 52977579 | R36: 50448965 | S36: 36387971 | T36: 45284117 | U36: 43999216 | V36: 24480959 | W36: 5818058.4 | X36: 3014599.3 | Y36: 2707332.1 | Z36: 2778167.9 | AA36: 2854336.8 | AB36: 2892677.8 | AC36: 2936861.2 | AD36: 2979573.4 | AE36: 3019022.7 | AF36: 3057248.7 | AG36: 3089470.2
A37: TT | B37: Lower Middle Income | C37: 12480105 | D37: 11631058 | E37: 11888503 | F37: 13148346 | G37: 13339965 | H37: 24961006 | I37: 24665045 | J37: 27274885 | K37: 27844467 | L37: 30266776 | M37: 53267510 | N37: 87134275 | O37: 99945546 | P37: 1.139779e+08 | Q37: 1.2057347e+08 | R37: 1.2743673e+08 | S37: 1.1344354e+08 | T37: 1.4080131e+08 | U37: 1.2076904e+08 | V37: 18018801 | W37: 4700849.2 | X37: 4165431.4 | Y37: 4103707.7 | Z37: 4044909.9 | AA37: 3981825
A38: DTaP-HepB-Hib-IPV | B38: Lower Middle Income | C38: 77147.62 | D38: 78898.44 | E38: 77949.26 | R38: 14724.55 | S38: 213958.16 | U38: 896285.53 | V38: 160009.85 | AA38: 278213.57 | AB38: 280005.61 | AC38: 283015.82 | AD38: 286417.42
A40: Measles | C40: =C23+C22+C24+C25+C26+C27 -> 1.1018435e+08 | D40: =D23+D22+D24+D25+D26+D27 -> 1.1430714e+08 | E40: =E23+E22+E24+E25+E26+E27 -> 1.1232829e+08 | F40: =F23+F22+F24+F25+F26+F27 -> 1.2058796e+08 | G40: =G23+G22+G24+G25+G26+G27 -> 1.2989599e+08 | H40: =H23+H22+H24+H25+H26+H27 -> 1.4889e+08 | I40: =I23+I22+I24+I25+I26+I27 -> 1.5548108e+08 | J40: =J23+J22+J24+J25+J26+J27 -> 1.5902789e+08 | ... AG40: =AG23+AG22+AG24+AG25+AG26+AG27 -> 3.2680817e+08
A41: Mumps | C41: =C25+C24 -> 14895547 | D41: =D25+D24 -> 15916937 | E41: =E25+E24 -> 16440302 | F41: =F25+F24 -> 17051794 | G41: =G25+G24 -> 25753121 | H41: =H25+H24 -> 26516485 | I41: =I25+I24 -> 28053836 | J41: =J25+J24 -> 27963867 | ... AG41: =AG25+AG24 -> 12977659
...
