Workbook
Name GAVI_countries: #REF!
Name GAVI_countries: #REF!
Name GAVI_countries: #REF!
Name GAVI_countries: #REF!
Name GAVI_countries: #REF!
Name GAVI_countries: #REF!

Sheet vaccine-producer list
A1: Vaccine | B1: Serum Institute of India Pvt. Ltd. | C1: PT Bio Farma (Persero) | D1: GlaxoSmithKline Biologicals SA | E1: Biological E. Limited | F1: Merck Sharp & Dohme LLC | G1: Sanofi Pasteur | H1: BB- NCIPD Ltd. (Bulgaria) | I1: LG Chem Ltd | J1: Panacea Biotec Ltd. | K1: AJ Vaccines A/S | L1: Bilthoven Biologicals B.V. | M1: Sanofi Healthcare India Private Limited | N1: Beijing Institute of Biological Products Co., Ltd. | O1: Bharat Biotech International Limited | P1: Haffkine Bio Pharmaceutical Corporation Ltd | Q1: Xiamen Innovax Biotech Co. Ltd. | R1: Centro de Ingenieria Genetica y Biotecnologia | S1: Pfizer | T1: Innovative Biotech
A2: Measles | B2: 1 | C2: 1
A3: Measles and Rubella | B3: 1 | E3: 1
A4: Measles, Mumps and Rubella | B4: 1 | D4: 1
A5: Tetanus Toxoid | B5: 1 | C5: 1 | H5: 1
A6: Haemophilus influenzae type b | B6: 1 | G6: 1 | R6: 1
A7: Polio Vaccine - Inactivated (IPV) | I7: 1 | K7: 1 | L7: 1 | M7: 1
A8: Polio Vaccine - Oral (OPV) Bivalent Types 1 and 3 | B8: 1 | C8: 1 | D8: 1 | G8: 1 | J8: 1 | N8: 1 | O8: 1 | P8: 1
A9: Hepatitis B (Pediatric or non-adult specific) | B9: 1 | I9: 1
A10: Tetanus-Diphtheria (Td) | B10: 1 | C10: 1 | H10: 1
A11: Diphtheria-Tetanus (DT) | B11: 1 | C11: 1 | H11: 1
A12: Diphtheria-Tetanus (reduced antigen content) | B12: 1 | C12: 1 | E12: 1 | G12: 1 | H12: 1
A13: Diphtheria-Tetanus-Pertussis (acellular) + (whole cell) | B13: 1 | E13: 1
A14: Diphtheria-Tetanus-Pertussis (whole cell)-Haemophilus influenzae type b | B14: 1
A15: Diphtheria-Tetanus-Pertussis (whole cell)-Hepatitis B-Haemophilus influenzae type b | B15: 1 | C15: 1 | E15: 1 | I15: 1 | J15: 1
A16: Diphtheria-Tetanus-Pertussis (acellular)-Hepatitis B-Haemophilus influenzae type b-Polio (Inactivated) | G16: 1
A17: Human Papillomavirus (Bivalent) + (Quadrivalent) | D17: 1 | F17: 1 | Q17: 1 | T17: 1
A18: Rotavirus | B18: 1 | D18: 1 | O18: 1
A19: Pneumococcal Conjugate vaccine | B19: 1 | D19: 1 | S19: 1

Sheet vaccine-antigen list
A1: Vaccine | B1: Measles | C1: Mumps | D1: Rubella | E1: HPV | F1: Polio | G1: Diptheria | H1: Tetanus | I1: Pertussus | J1: Hib | K1: HepB | L1: Rotavirus | M1: PCV
A2: Measles | B2: 1
A3: Measles and Rubella | B3: 1 | D3: 1
A4: Measles, Mumps and Rubella | B4: 1 | C4: 1 | D4: 1
A5: Tetanus Toxoid | H5: 1
A6: Tetanus-Diphtheria | G6: 1 | H6: 1
A7: Diphtheria-Tetanus | G7: 1 | H7: 1
A8: Diphtheria-Tetanus (reduced antigen content) | G8: 1 | H8: 1
A9: Diphtheria-Tetanus-Pertussis (acellular) + (whole cell) | G9: 1 | H9: 1 | I9: 1
A10: Diphtheria-Tetanus-Pertussis (whole cell)-Haemophilus influenzae type b | G10: 1 | H10: 1 | I10: 1 | J10: 1
A11: Diphtheria-Tetanus-Pertussis (whole cell)-Hepatitis B-Haemophilus influenzae type b | G11: 1 | H11: 1 | I11: 1 | J11: 1 | K11: 1
A12: Diphtheria-Tetanus-Pertussis (acellular)-Hepatitis B-Haemophilus influenzae type b-Polio (Inactivated) | F12: 1 | G12: 1 | H12: 1 | I12: 1 | J12: 1 | K12: 1
A13: Polio Vaccine - Inactivated (IPV) | F13: 1
A14: Polio Vaccine - Oral (OPV) Bivalent Types 1 and 3 | F14: 1
A15: Human Papillomavirus (Bivalent) (Quadrivalent) | E15: 1
A16: Hepatitis B (Pediatric or non-adult specific) | K16: 1
A17: Haemophilus influenzae type b | J17: 1
A18: Rotavirus | L18: 1
A19: Pneumococcal Conjugate vaccine | M19: 1

Sheet total_capacity_calcs
B1: Vaccine | C1: wb_status | D1: 2000 | E1: 2001 | F1: 2002 | G1: 2003 | H1: 2004 | I1: 2005 | J1: 2006 | K1: 2007 | L1: 2008 | M1: 2009 | N1: 2010 | O1: 2011 | P1: 2012 | Q1: 2013 | R1: 2014 | S1: 2015 | T1: 2016 | U1: 2017 | V1: 2018 | W1: 2019 | X1: 2020 | Y1: 2021 | Z1: 2022 | AA1: 2023 | AB1: 2024 | AC1: 2025 | AD1: 2026 | AE1: 2027 | AF1: 2028 | AG1: 2029 | AH1: 2030
B2: BCG | C2: -- | D2: 1042187.6 | E2: 1098514.4 | F2: 1139316.4 | G2: 1056462.3 | H2: 1051701.1 | I2: 1036770.5 | J2: 1028029.1 | K2: 1034736.5 | L2: 829922.19 | M2: 867969.62 | N2: 906053.75 | O2: 953703.5 | P2: 862649.67
B3: BCG | C3: High Income | D3: 2545256.6 | E3: 2559662.2 | F3: 2567818.1 | G3: 3399581.7 | H3: 3266002 | I3: 3223511.3 | J3: 3997948.8 | K3: 4078264.1 | L3: 4184322.8 | M3: 4886389.4 | N3: 5108451.9 | O3: 5663738.8 | P3: 5593898.1 | Q3: 5597533.3 | R3: 18987275 | S3: 15562187 | T3: 18480295 | U3: 5499455.8 | V3: 5364867.6 | W3: 6118707.9 | X3: 5286760.6 | Y3: 5785197.8 | Z3: 4993197.9 | AA3: 5858970.7 | AB3: 5818085.5 | AC3: 17983748 | AD3: 22592241 | AE3: 22444567 | AF3: 27261596 | AG3: 27027895 | AH3: 26819201
B4: BCG | C4: Low Income | D4: 1.5860127e+08 | E4: 1.6317939e+08 | F4: 1.7324226e+08 | G4: 1.7956992e+08 | H4: 1.8284175e+08 | I4: 1.6901377e+08 | J4: 1.700889e+08 | K4: 1.7099241e+08 | L4: 1.7454134e+08 | M4: 1.124793e+08 | N4: 85851850 | O4: 79000882 | P4: 76001633 | Q4: 74802167 | R4: 76940109 | S4: 77059752 | T4: 56233339 | U4: 57316201 | V4: 57753367 | W4: 62882877 | X4: 61763126 | Y4: 53246786 | Z4: 53584035 | AA4: 57329428 | AB4: 57632881 | AC4: 58594379 | AD4: 55244165 | AE4: 52333722 | AF4: 53523179 | AG4: 54783761 | AH4: 56018233
B5: BCG | C5: Lower Middle Income | D5: 58901554 | E5: 73089048 | F5: 67602896 | G5: 73879000 | H5: 98274085 | I5: 1.2093176e+08 | J5: 1.0555346e+08 | K5: 1.077091e+08 | L5: 87513041 | M5: 1.55432e+08 | N5: 1.7861927e+08 | O5: 1.8363475e+08 | P5: 1.6048051e+08 | Q5: 1.576214e+08 | R5: 1.4965217e+08 | S5: 1.4688243e+08 | T5: 1.7674045e+08 | U5: 1.8028509e+08 | V5: 1.8378947e+08 | W5: 1.7947828e+08 | X5: 1.7477241e+08 | Y5: 1.5947614e+08 | Z5: 1.8695217e+08 | AA5: 1.8622383e+08 | AB5: 1.6496186e+08 | AC5: 1.6479985e+08 | AD5: 1.6692721e+08 | AE5: 1.7240711e+08 | AF5: 1.6770392e+08 | AG5: 1.6958938e+08 | AH5: 1.7056571e+08
B6: BCG | C6: Upper Middle Income | D6: 40069259 | E6: 37199082 | F6: 41553820 | G6: 32932249 | H6: 11678133 | I6: 11693811 | J6: 30792555 | K6: 31674944 | L6: 54018151 | M6: 54304173 | N6: 59948778 | O6: 64281097 | P6: 90583182 | Q6: 93769359 | R6: 83737644 | S6: 83038288 | T6: 76793202 | U6: 89165212 | V6: 83714957 | W6: 77594157 | X6: 72034157 | Y6: 86134881 | Z6: 62365638 | AA6: 61872426 | AB6: 86002095 | AC6: 75926566 | AD6: 75865839 | AE6: 76859246 | AF6: 78957461 | AG6: 79477821 | AH6: 79877181
B7: bOPV | C7: High Income | T7: 18545880 | U7: 7903173.2 | V7: 5841854.2 | W7: 8610580.6 | X7: 5286878.2 | Y7: 5217133 | Z7: 4921402.6 | AA7: 5052108.6 | AB7: 4998867.7 | AC7: 43876574 | AD7: 51349717
B8: bOPV | C8: Low Income | T8: 72730018 | U8: 1.0570712e+08 | V8: 1.051229e+08 | W8: 1.1719715e+08 | X8: 1.0988395e+08 | Y8: 1.0245493e+08 | Z8: 1.0451565e+08 | AA8: 1.1158238e+08 | AB8: 1.1227561e+08 | AC8: 1.1406168e+08 | AD8: 1.0751713e+08
B9: bOPV | C9: Lower Middle Income | T9: 2.4814683e+08 | U9: 3.5337387e+08 | V9: 3.5043672e+08 | W9: 3.4662104e+08 | X9: 3.3593955e+08 | Y9: 3.3594803e+08 | Z9: 3.6575567e+08 | AA9: 3.6623113e+08 | AB9: 3.4781636e+08 | AC9: 3.4731021e+08 | AD9: 3.3650907e+08
B10: bOPV | C10: Upper Middle Income | T10: 1.1121093e+08 | U10: 1.7289435e+08 | V10: 1.3716887e+08 | W10: 1.2840844e+08 | X10: 1.2021655e+08 | Y10: 1.1577119e+08 | Z10: 89829782 | AA10: 89069211 | AB10: 1.1323213e+08 | AC10: 79625745 | AD10: 97021995
B11: Covid-19 | C11: High Income | X11: 7999629 | Y11: 2230537402 | Z11: 715448467 | AA11: 6.7224673e+08 | AB11: 6.7392758e+08 | AC11: 1.321223e+09 | AD11: 1.3435292e+09 | AE11: 1.3500028e+09 | AF11: 1.3952377e+09 | AG11: 1.400862e+09 | AH11: 1.4032704e+09
B12: Covid-19 | C12: Low Income | X12: 0 | Y12: 89460329 | Z12: 185668356 | AA12: 38756602 | AB12: 39462261 | AC12: 40346977 | AD12: 39721223 | AE12: 38658305 | AF12: 40005995 | AG12: 41580964 | AH12: 43232783
B13: Covid-19 | C13: Lower Middle Income | X13: 0 | Y13: 2654167495 | Z13: 2145751721 | AA13: 7.8264747e+08 | AB13: 7.5033441e+08 | AC13: 7.5297362e+08 | AD13: 7.5857573e+08 | AE13: 7.6908394e+08 | AF13: 7.6835446e+08 | AG13: 7.7884283e+08 | AH13: 7.8920493e+08
B14: Covid-19 | C14: Upper Middle Income | X14: 5098885 | Y14: 5050596480 | Z14: 1296608309 | AA14: 1.1175877e+09 | AB14: 1.1430276e+09 | AC14: 5.1551474e+08 | AD14: 5.1004924e+08 | AE14: 5.1567869e+08 | AF14: 4.9168109e+08 | AG14: 4.962824e+08 | AH14: 5.0081454e+08
B15: Dengue | C15: Lower Middle Income | T15: 2997892 | U15: 3030877.3
B16: Diphtheria | C16: High Income | D16: 45403.453 | E16: 48815.357 | F16: 51631.175 | G16: 52212.651 | H16: 53024.236 | I16: 55945.586 | J16: 57930.892 | K16: 61982.616 | L16: 64672.091 | M16: 67670.596 | N16: 68592.101 | O16: 69972.99 | P16: 76957.952 | Q16: 90017.238 | R16: 101145.22
B17: DT | C17: -- | D17: 94961.4 | E17: 90582.75 | F17: 92029.83 | G17: 119291.91 | H17: 111120 | I17: 98792.175 | J17: 82772.925 | K17: 96983.893
B18: DT | C18: High Income | D18: 1119051.8 | E18: 1222940.2 | F18: 1203400 | G18: 1217230.5 | H18: 1232734 | I18: 1231197.2 | J18: 1230059.9 | K18: 1219766.4 | L18: 1222583.4 | M18: 1268276 | N18: 1261043.9 | O18: 1265252.7 | P18: 1263631 | Q18: 1231828.8 | R18: 5094081 | S18: 5139940.4 | T18: 5130065 | U18: 1220097.5 | V18: 1223262.6 | W18: 1232125.9 | X18: 1208354 | Y18: 1212068.2 | Z18: 1195551.8 | AA18: 1189483.9 | AB18: 1192320.6 | AC18: 16729064 | AD18: 15711239 | AE18: 13744450 | AF18: 13089724 | AG18: 12920093 | AH18: 12788294
B19: DT | C19: Low Income | D19: 17559921 | E19: 1530590.5 | F19: 1386901.7 | G19: 1320690.4 | H19: 678429.41 | I19: 468765.33 | J19: 473725.65 | K19: 343604.27 | L19: 340659.15 | M19: 359787.73 | N19: 367309.28 | O19: 377112.44 | P19: 390295.27 | Q19: 390036.34 | R19: 428852.85 | S19: 264882.34 | W19: 674796.85 | X19: 4156434.5 | Y19: 4315320.2 | Z19: 4110923.5 | AA19: 4246029.6 | AB19: 4705085.7 | AC19: 4789178.8 | AD19: 718943.29 | AE19: 759633.2 | AF19: 785092.08 | AG19: 821841.37 | AH19: 863986.72
B20: DT | C20: Lower Middle Income | D20: 3364029.3 | E20: 19002103 | F20: 18724673 | G20: 18071980 | H20: 18376274 | I20: 18225152 | J20: 19831936 | K20: 19572618 | L20: 19597297 | M20: 19465616 | N20: 18787990 | O20: 18949188 | P20: 1565811.3 | Q20: 1478823.8 | R20: 1472017.6 | S20: 1622398.4 | T20: 1784486.6 | U20: 2200512.6 | V20: 2217689.2 | W20: 1502990.7 | X20: 906377.51 | Y20: 2089581.7 | Z20: 2331416 | AA20: 2295538.3 | AB20: 1554268.8 | AC20: 1550926 | AD20: 5699436.3 | AE20: 5324019.7 | AF20: 5339861.9 | AG20: 5355310.6 | AH20: 5370201.9
B21: DT | C21: Upper Middle Income | D21: 1130679.7 | E21: 1141336.2 | F21: 1132507 | G21: 1165910.2 | H21: 1156129 | I21: 1164352.2 | J21: 1157269.6 | K21: 1171509.5 | L21: 1522584.7 | M21: 1772267.7 | N21: 2460189.8 | O21: 2698865.2 | P21: 20249975 | Q21: 20803047 | R21: 21468732 | S21: 21404436 | T21: 21433161 | U21: 25055068 | V21: 25107099 | W21: 25126385 | X21: 25114664 | Y21: 23444220 | Z21: 23286004 | AA21: 23891029 | AB21: 22655217 | AC21: 5070868.9 | AD21: 4310614.9 | AE21: 4634200.9 | AF21: 4406115.4 | AG21: 4349721.6 | AH21: 4313357.8
B22: DTaP | C22: -- | D22: 8083.8947 | E22: 7983.4737 | F22: 7977.7895 | G22: 8014.1329 | H22: 8010.675 | I22: 7915.2632 | J22: 7673.6842 | K22: 7588.5474
B23: DTaP | C23: High Income | D23: 10825968 | E23: 11521230 | F23: 11271970 | G23: 14068018 | H23: 11348177 | I23: 11284629 | J23: 11210215 | K23: 11317814 | L23: 11467914 | M23: 11384250 | N23: 11359761 | O23: 11355944 | P23: 6964431.4 | Q23: 7530729 | R23: 7546137.3 | S23: 7669887.5 | T23: 8010425.9 | U23: 7912563.9 | V23: 7582079.2 | W23: 7447860.9 | X23: 7305237.8 | Y23: 7183718.3 | Z23: 7162774.1 | AA23: 7186571.4 | AB23: 7179815 | AC23: 45956969 | AD23: 45554047 | AE23: 45164177 | AF23: 44825038 | AG23: 44551215 | AH23: 44326791
B24: DTaP | C24: Low Income | D24: 41607.368 | E24: 39938.021 | F24: 37677 | G24: 36285.663
B25: DTaP | C25: Lower Middle Income | D25: 3216.8421 | E25: 4331.4779 | F25: 4220.8826 | G25: 4121.8737 | H25: 41648.762 | I25: 41943.776 | J25: 39476.684 | K25: 41243.732 | L25: 40140.863 | M25: 43047.701 | N25: 45402.379 | O25: 46536.082 | P25: 44901.842 | Q25: 47181.512 | R25: 48327.245 | S25: 75591.372 | T25: 26200.221 | U25: 24374.658 | V25: 25532.972 | W25: 25094.192 | X25: 23888.305 | Y25: 22126.295 | Z25: 23119.134 | AA25: 23153.28 | AB25: 23437.405 | AC25: 23890.937 | AD25: 24351.531
B26: DTaP | C26: Upper Middle Income | D26: 2465676.4 | E26: 2832127.2 | F26: 2992012.7 | G26: 49379.684 | H26: 47839.326 | I26: 45676.8 | J26: 43824.505 | K26: 137168.08 | L26: 49309.91 | M26: 49259.314 | N26: 8134.5692 | O26: 8195.5325 | P26: 74019754 | Q26: 74997412 | R26: 73216796 | S26: 71566155 | T26: 70205181 | U26: 71079334 | V26: 63915343 | W26: 57156938 | X26: 51466522 | Y26: 44878448 | Z26: 40973318 | AA26: 39904744 | AB26: 39559369 | AC26: 415706.68 | AD26: 431606.95 | AE26: 459548.38 | AF26: 446100.05 | AG26: 437514.08 | AH26: 430931.21
B27: DTaP-HepB | C27: Lower Middle Income | D27: 9089.3684 | E27: 8715.6316 | F27: 8496.2443 | G27: 9079.9263 | H27: 7227.7895 | I27: 8796.5487 | J27: 6602.4842 | K27: 6929.6141 | L27: 7073.5722 | M27: 8011.65 | N27: 7157.7895 | O27: 7240.7526 | P27: 7066.0526 | Q27: 4075.6905
B28: DTaP-HepB-Hib | C28: High Income | D28: 166958.84 | E28: 165729.92 | X28: 30178.358 | Y28: 28722.505 | Z28: 26301.695 | AA28: 25127.242 | AB28: 24585.347 | AC28: 24138.284 | AD28: 23828.779 | AE28: 23700.6 | AF28: 23759.922 | AG28: 23980.666 | AH28: 24359.106
B29: DTaP-HepB-Hib | C29: Lower Middle Income | W29: 30968.789 | X29: 29065.547 | Y29: 29888.876 | Z29: 29689.843 | AA29: 29609.337 | AB29: 29599.958 | AC29: 29654.121 | AD29: 29663.07
B30: DTaP-HepB-Hib | C30: Upper Middle Income | AE30: 29663.227 | AF30: 29666.353 | AG30: 29665.611 | AH30: 29653.105
B31: DTaP-HepB-Hib-IPV | C31: High Income | D31: 10384358 | E31: 10483052 | F31: 10759557 | G31: 10884669 | H31: 10971477 | I31: 11777902 | J31: 11899978 | K31: 12066440 | L31: 12741743 | M31: 12937984 | N31: 13091003 | O31: 13049889 | P31: 12922980 | Q31: 14708001 | R31: 14748339 | S31: 15106559 | T31: 14872756 | U31: 17180195 | V31: 17503375 | W31: 18417360 | X31: 18044096 | Y31: 20691154 | Z31: 20085170 | AA31: 20961571 | AB31: 20941291 | AC31: 20884037 | AD31: 23015544 | AE31: 22949120 | AF31: 22863374 | AG31: 22780778 | AH31: 22700002
B32: DTaP-HepB-Hib-IPV | C32: Lower Middle Income | D32: 77147.621 | E32: 78898.436 | F32: 77949.259 | S32: 14724.55 | T32: 213958.16 | V32: 896285.53 | W32: 160009.85 | AB32: 278213.57 | AC32: 280005.61 | AD32: 283015.82 | AE32: 286417.42
B33: DTaP-HepB-Hib-IPV | C33: Upper Middle Income | D33: 185887.44 | E33: 177799.52 | F33: 178287.47 | G33: 252247.43 | H33: 252298.51 | I33: 257525.7 | J33: 431009.67 | K33: 891465.99 | L33: 873731.01 | M33: 705871.65 | N33: 508004.28 | O33: 415803.28 | P33: 479914.7 | Q33: 1269962 | R33: 1183118 | S33: 4605731.8 | T33: 9198841.3 | U33: 10381330 | V33: 9706217.5 | W33: 7154165.7 | X33: 9070831.6 | Y33: 11947450 | Z33: 12700792 | AA33: 11877146 | AB33: 11604890 | AC33: 11614621 | AD33: 9393912.3 | AE33: 9380230.2 | AF33: 9661130 | AG33: 9685448.5 | AH33: 9708542.1
B34: DTaP-HepB-IPV | C34: High Income | D34: 2407703.5 | E34: 2450357.3 | F34: 2437018.4 | G34: 2503752.4 | H34: 2507370.8 | I34: 2515769.3 | J34: 2546214.9 | K34: 2580895.8 | L34: 2562868.6 | M34: 2485821.9 | N34: 2449527.1 | O34: 2454264.3 | P34: 2417401.1 | Q34: 2431677 | R34: 2441357 | S34: 2445298.3 | T34: 2439006.4 | U34: 2392607.6 | V34: 2355516.2 | W34: 2317006.7 | X34: 2253566.3 | Y34: 2229094.6 | Z34: 2281604.3 | AA34: 2312483 | AB34: 2326983 | AC34: 2334495.6 | AD34: 2346303.7 | AE34: 2356567.2 | AF34: 2368298.1 | AG34: 2378228.8 | AH34: 2385352
B35: DTaP-HepB-IPV | C35: Lower Middle Income | Q35: 2951.3621 | R35: 7711.3551 | S35: 6483.8105 | T35: 6360.4947 | U35: 6568.8376 | V35: 6541.0676 | W35: 6592.0262 | X35: 6767.9521 | Y35: 6334.8842 | Z35: 6472.9762 | AA35: 6603.1151 | AB35: 6727.6489 | AC35: 6771.0826 | AD35: 6837.5813
B36: DTaP-HepB-IPV | C36: Upper Middle Income | AE36: 6899.4505 | AF36: 6962.2734 | AG36: 6985.8221 | AH36: 6987.9033
B37: DTaP-Hib | C37: High Income | D37: 2124117.9 | E37: 2079776.2 | F37: 2066605.6 | G37: 2556263.6 | H37: 433472.72 | I37: 424260.09 | J37: 110207.11 | K37: 106585 | L37: 102979 | M37: 120355.61 | N37: 119514.77 | O37: 120789.82 | P37: 121734.41 | Q37: 791328.2 | R37: 779124.47 | S37: 866515.26 | T37: 755357.83 | U37: 665387.24 | V37: 677839.5 | W37: 682488.07 | X37: 681634.36 | Y37: 692874.5 | Z37: 685136.08 | AA37: 670789.61 | AB37: 659099.27 | AC37: 3919579.7 | AD37: 3873683.8 | AE37: 3834518.8 | AF37: 3801709.1 | AG37: 3775441.1 | AH37: 3753257.1
B38: DTaP-Hib | C38: Upper Middle Income | D38: 56687.747 | E38: 58370.018 | F38: 59096.088 | G38: 62795.03 | H38: 77079.432 | I38: 75667.958 | J38: 73722.473 | K38: 68607.663 | L38: 67761.45 | M38: 64807.305 | N38: 3506714.7 | O38: 3500885.9 | P38: 60943.305 | Q38: 638003.86 | R38: 627160.36 | S38: 1306608 | T38: 1161672.5 | U38: 1906276.7 | V38: 6114463.9 | W38: 4681815.1 | X38: 4177477.9 | Y38: 3595868.4 | Z38: 3364467 | AA38: 3329664.2 | AB38: 3302080.4
B39: DTaP-Hib-IPV | C39: High Income | D39: 10918706 | E39: 11096836 | F39: 11069755 | G39: 11817034 | H39: 14050497 | I39: 14133436 | J39: 14675710 | K39: 14896974 | L39: 15083190 | M39: 15333262 | N39: 15285142 | O39: 15320404 | P39: 15259188 | Q39: 15259521 | R39: 15009108 | S39: 15033225 | T39: 16180119 | U39: 16216393 | V39: 14677145 | W39: 13719013 | X39: 13029564 | Y39: 10784189 | Z39: 10921290 | AA39: 11058824 | AB39: 11105849 | AC39: 12769336 | AD39: 12841912 | AE39: 13093112 | AF39: 17793069 | AG39: 17761708 | AH39: 17711618
B40: DTaP-Hib-IPV | C40: Lower Middle Income | J40: 458159.49 | K40: 794594.12 | L40: 575027.14 | M40: 488986.45 | N40: 875476.69 | O40: 866095.28 | P40: 441027.39 | Q40: 407293.58 | R40: 307001.84 | S40: 285645.71 | T40: 187528.67 | AB40: 91558.421 | AC40: 91777.185 | AD40: 92382.36 | AE40: 93389.324
...

Sheet Medium_Demand_calc
B1: 1 | C1: 2 | D1: 3 | E1: 4 | F1: 5 | G1: 6 | H1: 7 | I1: 8 | J1: 9 | K1: 10
A2: M | B2: 14777182 | C2: 37949221 | D2: 17547796 | E2: 21303105 | F2: 22347713 | G2: 20946970 | H2: 19884769 | I2: 20824130 | J2: 21884645 | K2: 22913489
A3: MR | B3: 3.3127915e+08 | C3: 2.2738502e+08 | D3: 2.7883599e+08 | E3: 2.516257e+08 | F3: 2.6781107e+08 | G3: 3.7033728e+08 | H3: 2.4042417e+08 | I3: 3.7678179e+08 | J3: 2.7887392e+08 | K3: 3.1287896e+08
A4: MMR | B4: 26052156 | C4: 26626399 | D4: 25785425 | E4: 25268101 | F4: 23536241 | G4: 16205416 | H4: 18650430 | I4: 8909629.5 | J4: 10718460 | K4: 12977659
A5: TT | B5: 7180030.7 | C5: 6811039.8 | D5: 6823077.8 | E5: 6836161.8 | F5: 2892677.8 | G5: 2936861.2 | H5: 2979573.4 | I5: 3019022.7 | J5: 3057248.7 | K5: 3089470.2
A6: Td | B6: 2.4348251e+08 | C6: 2.6568355e+08 | D6: 2.6744926e+08 | E6: 2.5226051e+08 | F6: 2.5478484e+08 | G6: 2.5264906e+08 | H6: 2.5576357e+08 | I6: 2.5352024e+08 | J6: 2.5706799e+08 | K6: 2.5961279e+08
A7: DT | B7: 6404902 | C7: 6442339.5 | D7: 6541567.8 | E7: 6259354.5 | F7: 6340104.9 | G7: 6418379.6 | H7: 6083652.9 | I7: 6124954 | J7: 6177152 | K7: 6234188.6
A8: DTwP | B8: 62054152 | C8: 65413987 | D8: 65841842 | E8: 61952728 | F8: 60519652 | G8: 57998581 | H8: 58117896 | I8: 57893321 | J8: 57748831 | K8: 57596498
A9: DTwP-Hib | B9: 5826576.9 | C9: 5816636.4 | D9: 5854584.9 | E9: 5896822 | F9: 5926170.6 | G9: 5954082.9 | H9: 5991783.4 | I9: 6035049.6 | J9: 6086680.2 | K9: 6145863.4
A10: Penta | B10: 2.5278201e+08 | C10: 2.761834e+08 | D10: 2.8076815e+08 | E10: 2.6784928e+08 | F10: 2.6812943e+08 | G10: 2.6380014e+08 | H10: 2.668414e+08 | I10: 2.6438055e+08 | J10: 2.6762673e+08 | K10: 2.7056962e+08
A11: Hexa | B11: 0 | C11: 0 | D11: 0 | E11: 278213.57 | F11: 280005.61 | G11: 283015.82 | H11: 286417.42 | I11: 0 | J11: 0 | K11: 0
A12: IPV | B12: 83779047 | C12: 1.1191097e+08 | D12: 1.3081826e+08 | E12: 1.303194e+08 | F12: 1.300916e+08 | G12: 1.2819377e+08 | H12: 1.3053771e+08 | I12: 1.2851625e+08 | J12: 1.3080728e+08 | K12: 1.3295598e+08
A13: OPV | B13: 4.3840296e+08 | C13: 4.7027132e+08 | D13: 4.7781351e+08 | E13: 4.6009197e+08 | F13: 4.6137189e+08 | G13: 4.440262e+08 | H13: 0 | I13: 0 | J13: 0 | K13: 0
... A18: PCV | B18: 1.6080023e+08 | C18: 1.869961e+08 | D18: 2.0916547e+08 | E18: 2.0593845e+08 | F18: 2.2099867e+08 | G18: 2.1910658e+08 | H18: 2.2227112e+08 | I18: 2.1733557e+08 | J18: 2.1876457e+08 | K18: 2.2023425e+08
B20: 1 | C20: 2 | D20: 3 | E20: 4 | F20: 5 | G20: 6 | H20: 7 | I20: 8 | J20: 9 | K20: 10
A21: Measles | B21: =+B2+B3+B4 -> 3.7210849e+08 | C21: =+C2+C3+C4 -> 2.9196064e+08 | D21: =+D2+D3+D4 -> 3.2216921e+08 | E21: =+E2+E3+E4 -> 2.981969e+08 | F21: =+F2+F3+F4 -> 3.1369502e+08 | G21: =+G2+G3+G4 -> 4.0748967e+08 | H21: =+H2+H3+H4 -> 2.7895937e+08 | I21: =+I2+I3+I4 -> 4.0651555e+08 | ... K21: =+K2+K3+K4 -> 3.487701e+08
A22: Mumps | B22: =+B4 -> 26052156 | C22: =+C4 -> 26626399 | D22: =+D4 -> 25785425 | E22: =+E4 -> 25268101 | F22: =+F4 -> 23536241 | G22: =+G4 -> 16205416 | H22: =+H4 -> 18650430 | I22: =+I4 -> 8909629.5 | ... K22: =+K4 -> 12977659
A23: Rubella | B23: =+B3+B4 -> 3.5733131e+08 | C23: =+C3+C4 -> 2.5401142e+08 | D23: =+D3+D4 -> 3.0462142e+08 | E23: =+E3+E4 -> 2.768938e+08 | F23: =+F3+F4 -> 2.9134731e+08 | G23: =+G3+G4 -> 3.865427e+08 | H23: =+H3+H4 -> 2.590746e+08 | I23: =+I3+I4 -> 3.8569142e+08 | ... K23: =+K3+K4 -> 3.2585661e+08
A24: Diphtheria | B24: =+B6+B7+B8+B9+B10+B11 -> 5.7055015e+08 | C24: =+C6+C7+C8+C9+C10+C11 -> 6.1953992e+08 | D24: =+D6+D7+D8+D9+D10+D11 -> 6.264554e+08 | E24: =+E6+E7+E8+E9+E10+E11 -> 5.9449691e+08 | F24: =+F6+F7+F8+F9+F10+F11 -> 5.959802e+08 | G24: =+G6+G7+G8+G9+G10+G11 -> 5.8710326e+08 | H24: =+H6+H7+H8+H9+H10+H11 -> 5.9308472e+08 | I24: =+I6+I7+I8+I9+I10+I11 -> 5.8795411e+08 | ... K24: =+K6+K7+K8+K9+K10+K11 -> 6.0015896e+08
A25: Tetanus | B25: =+B5+B6+B7+B8+B9+B10+B11 -> 5.7773018e+08 | C25: =+C5+C6+C7+C8+C9+C10+C11 -> 6.2635096e+08 | D25: =+D5+D6+D7+D8+D9+D10+D11 -> 6.3327848e+08 | E25: =+E5+E6+E7+E8+E9+E10+E11 -> 6.0133308e+08 | F25: =+F5+F6+F7+F8+F9+F10+F11 -> 5.9887288e+08 | G25: =+G5+G6+G7+G8+G9+G10+G11 -> 5.9004012e+08 | H25: =+H5+H6+H7+H8+H9+H10+H11 -> 5.9606429e+08 | I25: =+I5+I6+I7+I8+I9+I10+I11 -> 5.9097313e+08 | ... K25: =+K5+K6+K7+K8+K9+K10+K11 -> 6.0324843e+08
A26: Pertussis | B26: =+B8+B9+B10+B11 -> 3.2066274e+08 | C26: =+C8+C9+C10+C11 -> 3.4741402e+08 | D26: =+D8+D9+D10+D11 -> 3.5246458e+08 | E26: =+E8+E9+E10+E11 -> 3.3597705e+08 | F26: =+F8+F9+F10+F11 -> 3.3485526e+08 | G26: =+G8+G9+G10+G11 -> 3.2803582e+08 | H26: =+H8+H9+H10+H11 -> 3.312375e+08 | I26: =+I8+I9+I10+I11 -> 3.2830892e+08 | ... K26: =+K8+K9+K10+K11 -> 3.3431198e+08
A27: Hepatitis_B | B27: =+B15+B10+B11 -> 3.1228457e+08 | C27: =+C15+C10+C11 -> 3.4300816e+08 | D27: =+D15+D10+D11 -> 3.5171778e+08 | E27: =+E15+E10+E11 -> 3.3497363e+08 | F27: =+F15+F10+F11 -> 3.3445556e+08 | G27: =+G15+G10+G11 -> 3.2843013e+08 | H27: =+H15+H10+H11 -> 3.323089e+08 | I27: =+I15+I10+I11 -> 3.2820051e+08 | ... K27: =+K15+K10+K11 -> 3.3552543e+08
A28: Hib | B28: =+B9+B10+B11+B16 -> 2.5953623e+08 | C28: =+C9+C10+C11+C16 -> 2.827771e+08 | D28: =+D9+D10+D11+D16 -> 2.8725289e+08 | E28: =+E9+E10+E11+E16 -> 2.7402786e+08 | F28: =+F9+F10+F11+F16 -> 2.7433939e+08 | G28: =+G9+G10+G11+G16 -> 2.7004127e+08 | H28: =+H9+H10+H11+H16 -> 2.731196e+08 | I28: =+I9+I10+I11+I16 -> 2.704156e+08 | ... K28: =+K9+K10+K11+K16 -> 2.7671548e+08
A29: IPV | B29: =+B11+B12+B13 -> 5.2218201e+08 | C29: =+C11+C12+C13 -> 5.8218228e+08 | D29: =+D11+D12+D13 -> 6.0863176e+08 | E29: =+E11+E12+E13 -> 5.9068959e+08 | F29: =+F11+F12+F13 -> 5.917435e+08 | G29: =+G11+G12+G13 -> 5.7250299e+08 | H29: =+H11+H12+H13 -> 1.3082413e+08 | I29: =+I11+I12+I13 -> 1.2851625e+08 | ... K29: =+K11+K12+K13 -> 1.3295598e+08
A30: HPV | B30: =+B14 -> 18988210 | C30: =+C14 -> 18779835 | D30: =+D14 -> 27459977 | E30: =+E14 -> 72849487 | F30: =+F14 -> 92670605 | G30: =+G14 -> 64703774 | H30: =+H14 -> 42236975 | I30: =+I14 -> 42368434 | ... K30: =+K14 -> 35038545
A31: Rotavirus | B31: =+B17 -> 1.42479e+08 | C31: =+C17 -> 1.6642208e+08 | D31: =+D17 -> 1.737514e+08 | E31: =+E17 -> 1.8632837e+08 | F31: =+F17 -> 1.9766829e+08 | G31: =+G17 -> 2.0565233e+08 | H31: =+H17 -> 2.0955284e+08 | I31: =+I17 -> 2.0735555e+08 | ... K31: =+K17 -> 2.1180284e+08
A32: PCV | B32: =+B18 -> 1.6080023e+08 | C32: =+C18 -> 1.869961e+08 | D32: =+D18 -> 2.0916547e+08 | E32: =+E18 -> 2.0593845e+08 | F32: =+F18 -> 2.2099867e+08 | G32: =+G18 -> 2.1910658e+08 | H32: =+H18 -> 2.2227112e+08 | I32: =+I18 -> 2.1733557e+08 | ... K32: =+K18 -> 2.2023425e+08
A34: Measles | B34: =+ROUND(B21/100000,0)*100000 -> 372100000 | C34: =+ROUND(C21/100000,0)*100000 -> 292000000 | D34: =+ROUND(D21/100000,0)*100000 -> 322200000 | E34: =+ROUND(E21/100000,0)*100000 -> 298200000 | F34: =+ROUND(F21/100000,0)*100000 -> 313700000 | G34: =+ROUND(G21/100000,0)*100000 -> 407500000 | H34: =+ROUND(H21/100000,0)*100000 -> 279000000 | I34: =+ROUND(I21/100000,0)*100000 -> 406500000 | ... K34: =+ROUND(K21/100000,0)*100000 -> 348800000
A35: Mumps | B35: =+ROUND(B22/100000,0)*100000 -> 26100000 | C35: =+ROUND(C22/100000,0)*100000 -> 26600000 | D35: =+ROUND(D22/100000,0)*100000 -> 25800000 | E35: =+ROUND(E22/100000,0)*100000 -> 25300000 | F35: =+ROUND(F22/100000,0)*100000 -> 23500000 | G35: =+ROUND(G22/100000,0)*100000 -> 16200000 | H35: =+ROUND(H22/100000,0)*100000 -> 18700000 | I35: =+ROUND(I22/100000,0)*100000 -> 8900000 | ... K35: =+ROUND(K22/100000,0)*100000 -> 13000000
A36: Rubella | B36: =+ROUND(B23/100000,0)*100000 -> 357300000 | C36: =+ROUND(C23/100000,0)*100000 -> 254000000 | D36: =+ROUND(D23/100000,0)*100000 -> 304600000 | E36: =+ROUND(E23/100000,0)*100000 -> 276900000 | F36: =+ROUND(F23/100000,0)*100000 -> 291300000 | G36: =+ROUND(G23/100000,0)*100000 -> 386500000 | H36: =+ROUND(H23/100000,0)*100000 -> 259100000 | I36: =+ROUND(I23/100000,0)*100000 -> 385700000 | ... K36: =+ROUND(K23/100000,0)*100000 -> 325900000
A37: Diphtheria | B37: =+ROUND(B24/100000,0)*100000 -> 570600000 | C37: =+ROUND(C24/100000,0)*100000 -> 619500000 | D37: =+ROUND(D24/100000,0)*100000 -> 626500000 | E37: =+ROUND(E24/100000,0)*100000 -> 594500000 | F37: =+ROUND(F24/100000,0)*100000 -> 596000000 | G37: =+ROUND(G24/100000,0)*100000 -> 587100000 | H37: =+ROUND(H24/100000,0)*100000 -> 593100000 | I37: =+ROUND(I24/100000,0)*100000 -> 588000000 | ... K37: =+ROUND(K24/100000,0)*100000 -> 600200000
A38: Tetanus | B38: =+ROUND(B25/100000,0)*100000 -> 577700000 | C38: =+ROUND(C25/100000,0)*100000 -> 626400000 | D38: =+ROUND(D25/100000,0)*100000 -> 633300000 | E38: =+ROUND(E25/100000,0)*100000 -> 601300000 | F38: =+ROUND(F25/100000,0)*100000 -> 598900000 | G38: =+ROUND(G25/100000,0)*100000 -> 590000000 | H38: =+ROUND(H25/100000,0)*100000 -> 596100000 | I38: =+ROUND(I25/100000,0)*100000 -> 591000000 | ... K38: =+ROUND(K25/100000,0)*100000 -> 603200000
A39: Pertussis | B39: =+ROUND(B26/100000,0)*100000 -> 320700000 | C39: =+ROUND(C26/100000,0)*100000 -> 347400000 | D39: =+ROUND(D26/100000,0)*100000 -> 352500000 | E39: =+ROUND(E26/100000,0)*100000 -> 336000000 | F39: =+ROUND(F26/100000,0)*100000 -> 334900000 | G39: =+ROUND(G26/100000,0)*100000 -> 328000000 | H39: =+ROUND(H26/100000,0)*100000 -> 331200000 | I39: =+ROUND(I26/100000,0)*100000 -> 328300000 | ... K39: =+ROUND(K26/100000,0)*100000 -> 334300000
A40: Hepatitis_B | B40: =+ROUND(B27/100000,0)*100000 -> 312300000 | C40: =+ROUND(C27/100000,0)*100000 -> 343000000 | D40: =+ROUND(D27/100000,0)*100000 -> 351700000 | E40: =+ROUND(E27/100000,0)*100000 -> 335000000 | F40: =+ROUND(F27/100000,0)*100000 -> 334500000 | G40: =+ROUND(G27/100000,0)*100000 -> 328400000 | H40: =+ROUND(H27/100000,0)*100000 -> 332300000 | I40: =+ROUND(I27/100000,0)*100000 -> 328200000 | ... K40: =+ROUND(K27/100000,0)*100000 -> 335500000
A41: Hib | B41: =+ROUND(B28/100000,0)*100000 -> 259500000 | C41: =+ROUND(C28/100000,0)*100000 -> 282800000 | D41: =+ROUND(D28/100000,0)*100000 -> 287300000 | E41: =+ROUND(E28/100000,0)*100000 -> 274000000 | F41: =+ROUND(F28/100000,0)*100000 -> 274300000 | G41: =+ROUND(G28/100000,0)*100000 -> 270000000 | H41: =+ROUND(H28/100000,0)*100000 -> 273100000 | I41: =+ROUND(I28/100000,0)*100000 -> 270400000 | ... K41: =+ROUND(K28/100000,0)*100000 -> 276700000
A42: IPV | B42: =+ROUND(B29/100000,0)*100000 -> 522200000 | C42: =+ROUND(C29/100000,0)*100000 -> 582200000 | D42: =+ROUND(D29/100000,0)*100000 -> 608600000 | E42: =+ROUND(E29/100000,0)*100000 -> 590700000 | F42: =+ROUND(F29/100000,0)*100000 -> 591700000 | G42: =+ROUND(G29/100000,0)*100000 -> 572500000 | H42: =+ROUND(H29/100000,0)*100000 -> 130800000 | I42: =+ROUND(I29/100000,0)*100000 -> 128500000 | ... K42: =+ROUND(K29/100000,0)*100000 -> 133000000
A43: HPV | B43: =+ROUND(B30/100000,0)*100000 -> 19000000 | C43: =+ROUND(C30/100000,0)*100000 -> 18800000 | D43: =+ROUND(D30/100000,0)*100000 -> 27500000 | E43: =+ROUND(E30/100000,0)*100000 -> 72800000 | F43: =+ROUND(F30/100000,0)*100000 -> 92700000 | G43: =+ROUND(G30/100000,0)*100000 -> 64700000 | H43: =+ROUND(H30/100000,0)*100000 -> 42200000 | I43: =+ROUND(I30/100000,0)*100000 -> 42400000 | ... K43: =+ROUND(K30/100000,0)*100000 -> 35000000
A44: Rotavirus | B44: =+ROUND(B31/100000,0)*100000 -> 142500000 | C44: =+ROUND(C31/100000,0)*100000 -> 166400000 | D44: =+ROUND(D31/100000,0)*100000 -> 173800000 | E44: =+ROUND(E31/100000,0)*100000 -> 186300000 | F44: =+ROUND(F31/100000,0)*100000 -> 197700000 | G44: =+ROUND(G31/100000,0)*100000 -> 205700000 | H44: =+ROUND(H31/100000,0)*100000 -> 209600000 | I44: =+ROUND(I31/100000,0)*100000 -> 207400000 | ... K44: =+ROUND(K31/100000,0)*100000 -> 211800000
A45: PCV | B45: =+ROUND(B32/100000,0)*100000 -> 160800000 | C45: =+ROUND(C32/100000,0)*100000 -> 187000000 | D45: =+ROUND(D32/100000,0)*100000 -> 209200000 | E45: =+ROUND(E32/100000,0)*100000 -> 205900000 | F45: =+ROUND(F32/100000,0)*100000 -> 221000000 | G45: =+ROUND(G32/100000,0)*100000 -> 219100000 | H45: =+ROUND(H32/100000,0)*100000 -> 222300000 | I45: =+ROUND(I32/100000,0)*100000 -> 217300000 | ... K45: =+ROUND(K32/100000,0)*100000 -> 220200000

Sheet Medium_Demand
B1: 1 | C1: 2 | D1: 3 | E1: 4 | F1: 5 | G1: 6 | H1: 7 | I1: 8 | J1: 9 | K1: 10 | L1: 11 | M1: 12 | N1: 13 | O1: 14 | P1: 15 | Q1: 16 | R1: 17 | S1: 18 | T1: 19 | U1: 20 | V1: 21 | W1: 22 | X1: 23 | Y1: 24 | Z1: 25 | AA1: 26 | AB1: 27 | AC1: 28 | AD1: 29 | AE1: 30 | AF1: 31 | AG1: 32 | AH1: 33 | AI1: 34 | AJ1: 35
A2: Measles | B2: 372100000 | C2: 292000000 | D2: 322200000 | E2: 298200000 | F2: 313700000 | G2: 407500000 | H2: 279000000 | I2: 406500000 | J2: 311500000 | K2: 348800000 | L2: 4.3705233e+08 | M2: 3.3043534e+08 | N2: 4.0937207e+08 | O2: 3.4754365e+08 | P2: 3.7375351e+08 | Q2: 4.6741578e+08 | R2: 3.607988e+08 | S2: 4.3973552e+08 | T2: 3.7790711e+08 | U2: 4.0411696e+08 | V2: 4.9777924e+08 | W2: 3.9116225e+08 | X2: 4.7009897e+08 | Y2: 4.0827056e+08 | Z2: 4.3448041e+08 | AA2: 5.2814269e+08 | AB2: 4.215257e+08 | AC2: 5.0046243e+08 | AD2: 4.3863401e+08 | AE2: 4.6484387e+08 | AF2: 5.5850614e+08 | AG2: 4.5188916e+08 | AH2: 5.3082588e+08 | AI2: 4.6899747e+08 | AJ2: 4.9520732e+08
A3: Mumps | B3: 22148782 | C3: 22105642 | D3: 19837777 | E3: 26434485 | F3: 20737739 | G3: 20303126 | H3: 23934205 | I3: 21792972 | J3: 18694960 | K3: 20718981 | L3: 19221360 | M3: 18654447 | N3: 22289251 | O3: 20153874 | P3: 17182312 | Q3: 21607499 | R3: 18346876 | S3: 17779963 | T3: 21414766 | U3: 19279389 | V3: 16307828 | W3: 20733015 | X3: 17472391 | Y3: 16905478 | Z3: 20540282 | AA3: 18404905 | AB3: 15433343 | AC3: 19858530 | AD3: 16597907 | AE3: 16030994 | AF3: 19665798 | AG3: 17530420 | AH3: 14558859 | AI3: 18984046 | AJ3: 15723422
A4: Rubella | B4: 357300000 | C4: 254000000 | D4: 304600000 | E4: 276900000 | F4: 291300000 | G4: 386500000 | H4: 259100000 | I4: 385700000 | J4: 289600000 | K4: 325900000 | L4: 4.1925699e+08 | M4: 3.0534365e+08 | N4: 3.9354738e+08 | O4: 3.3004828e+08 | P4: 3.5567603e+08 | Q4: 4.5064402e+08 | R4: 3.3673068e+08 | S4: 4.2493441e+08 | T4: 3.6143531e+08 | U4: 3.8706306e+08 | V4: 4.8203106e+08 | W4: 3.6811771e+08 | X4: 4.5632145e+08 | Y4: 3.9282235e+08 | Z4: 4.184501e+08 | AA4: 5.1341809e+08 | AB4: 3.9950475e+08 | AC4: 4.8770848e+08 | AD4: 4.2420938e+08 | AE4: 4.4983713e+08 | AF4: 5.4480512e+08 | AG4: 4.3089178e+08 | AH4: 5.1909551e+08 | AI4: 4.5559641e+08 | AJ4: 4.8122416e+08
A5: Diphtheria | B5: 570600000 | C5: 619500000 | D5: 626500000 | E5: 594500000 | F5: 596000000 | G5: 587100000 | H5: 593100000 | I5: 588000000 | J5: 594700000 | K5: 600200000 | L5: 6.0618086e+08 | M5: 5.8453027e+08 | N5: 5.8650357e+08 | O5: 610748349 | P5: 6.0216042e+08 | Q5: 5.7705549e+08 | R5: 5.7902878e+08 | S5: 5.8478368e+08 | T5: 5.9123128e+08 | U5: 603832834 | V5: 5.9155399e+08 | W5: 5.8930889e+08 | X5: 5.8375649e+08 | Y5: 6.0010591e+08 | Z5: 5.8607921e+08 | AA5: 5.8783411e+08 | AB5: 5.9928171e+08 | AC5: 5.8763112e+08 | AD5: 6.0260442e+08 | AE5: 5.7935932e+08 | AF5: 5.8980692e+08 | AG5: 6.1215633e+08 | AH5: 5.9912963e+08 | AI5: 5.9488453e+08 | AJ5: 5.9133213e+08
A6: Tetanus | B6: 577700000 | C6: 626400000 | D6: 633300000 | E6: 601300000 | F6: 598900000 | G6: 590000000 | H6: 596100000 | I6: 591000000 | J6: 597800000 | K6: 603200000 | L6: 5.9851506e+08 | M6: 5.9776534e+08 | N6: 5.9859086e+08 | O6: 5.8667379e+08 | P6: 5.9797638e+08 | Q6: 5.6876061e+08 | R6: 5.880109e+08 | S6: 5.9983641e+08 | T6: 5.8691934e+08 | U6: 6.0022194e+08 | V6: 5.8900617e+08 | W6: 5.8925645e+08 | X6: 5.9908196e+08 | Y6: 6.0116489e+08 | Z6: 5.8346749e+08 | AA6: 6.0225172e+08 | AB6: 5.89502e+08 | AC6: 5.9932752e+08 | AD6: 6.0541045e+08 | AE6: 6.0371304e+08 | AF6: 5.7949727e+08 | AG6: 5.9874755e+08 | AH6: 5.9957307e+08 | AI6: 6.00656e+08 | AJ6: 5.999586e+08
A7: Pertussis | B7: 320700000 | C7: 347400000 | D7: 352500000 | E7: 336000000 | F7: 334900000 | G7: 328000000 | H7: 331200000 | I7: 328300000 | J7: 331500000 | K7: 334300000 | L7: 323028738 | M7: 336396212 | N7: 340678448 | O7: 340640305 | P7: 342189406 | Q7: 335268003 | R7: 345935661 | S7: 350200717 | T7: 346536600 | U7: 347956777 | V7: 328317441 | W7: 332648930 | X7: 343185197 | Y7: 323884740 | Z7: 337713055 | AA7: 312356594 | AB7: 328931413 | AC7: 336169677 | AD7: 332375643 | AE7: 333665903 | AF7: 311477849 | AG7: 312931306 | AH7: 310867816 | AI7: 319326447 | AJ7: 326520467
A8: Hepatitis_B | B8: 312300000 | C8: 343000000 | D8: 351700000 | E8: 335000000 | F8: 334500000 | G8: 328400000 | H8: 332300000 | I8: 328200000 | J8: 332200000 | K8: 335500000 | L8: 329535961 | M8: 331703251 | N8: 326703251 | O8: 329058447 | P8: 337677793 | Q8: 331875120 | R8: 328475130 | S8: 327867869 | T8: 325642419 | U8: 327997616 | V8: 336616961 | W8: 330814288 | X8: 327414298 | Y8: 327807038 | Z8: 328581588 | AA8: 326936784 | AB8: 335556130 | AC8: 329753457 | AD8: 326353467 | AE8: 330746206 | AF8: 323520756 | AG8: 325875953 | AH8: 334495298 | AI8: 328692625 | AJ8: 325292635
A9: Hib | B9: 259500000 | C9: 282800000 | D9: 287300000 | E9: 274000000 | F9: 274300000 | G9: 270000000 | H9: 273100000 | I9: 270400000 | J9: 273700000 | K9: 276700000 | L9: 2.7215879e+08 | M9: 2.7439498e+08 | N9: 2.7258971e+08 | O9: 2.7176903e+08 | P9: 2.7400522e+08 | Q9: 2.7219995e+08 | R9: 2.7137927e+08 | S9: 2.7361546e+08 | T9: 2.7181019e+08 | U9: 2.7098951e+08 | V9: 2.732257e+08 | W9: 2.7142043e+08 | X9: 2.7059975e+08 | Y9: 2.7283594e+08 | Z9: 2.7103067e+08 | AA9: 2.7020999e+08 | AB9: 2.7244618e+08 | AC9: 2.7064091e+08 | AD9: 2.6982023e+08 | AE9: 2.7205642e+08 | AF9: 2.7025115e+08 | AG9: 2.6943047e+08 | AH9: 2.7166666e+08 | AI9: 2.6986139e+08 | AJ9: 2.6904071e+08
A10: Polio | B10: 522200000 | C10: 582200000 | D10: 608600000 | E10: 590700000 | F10: 591700000 | G10: 572500000 | H10: 130800000 | I10: 128500000 | J10: 130800000 | K10: 133000000 | L10: 1.3932295e+08 | M10: 1.4027261e+08 | N10: 1.4122227e+08 | O10: 1.4217193e+08 | P10: 1.4312159e+08 | Q10: 1.4407125e+08 | R10: 1.4502091e+08 | S10: 1.4597057e+08 | T10: 1.4692023e+08 | U10: 1.4786989e+08 | V10: 1.4881955e+08 | W10: 1.4976921e+08 | X10: 1.5071887e+08 | Y10: 1.5166853e+08 | Z10: 1.5261819e+08 | AA10: 1.5356785e+08 | AB10: 1.5451751e+08 | AC10: 1.5546717e+08 | AD10: 1.5641683e+08 | AE10: 1.5736649e+08 | AF10: 1.5831615e+08 | AG10: 1.5926581e+08 | AH10: 1.6021547e+08 | AI10: 1.6116513e+08 | AJ10: 1.6211479e+08
A11: HPV | B11: 19000000 | C11: 18800000 | D11: 27500000 | E11: 72800000 | F11: 92700000 | G11: 64700000 | H11: 42200000 | I11: 42400000 | J11: 33700000 | K11: 35000000 | L11: 90437327 | M11: 60634149 | N11: 38068021 | O11: 38201979 | P11: 27624394 | Q11: 51713319 | R11: 92582666 | S11: 62779489 | T11: 40213360 | U11: 40347319 | V11: 29769733 | W11: 53858659 | X11: 94728006 | Y11: 64924828 | Z11: 42358700 | AA11: 42492658 | AB11: 31915073 | AC11: 56003998 | AD11: 96873345 | AE11: 67070168 | AF11: 44504039 | AG11: 44637998 | AH11: 34060412 | AI11: 58149337 | AJ11: 99018685
A12: Rotavirus | B12: 142500000 | C12: 166400000 | D12: 173800000 | E12: 186300000 | F12: 197700000 | G12: 205700000 | H12: 209600000 | I12: 207400000 | J12: 209600000 | K12: 211800000 | L12: 2.1298693e+08 | M12: 2.1489232e+08 | N12: 2.1679771e+08 | O12: 2.187031e+08 | P12: 2.2060849e+08 | Q12: 2.2251388e+08 | R12: 2.2441927e+08 | S12: 2.2632467e+08 | T12: 2.2823006e+08 | U12: 2.3013545e+08 | V12: 2.3204084e+08 | W12: 2.3394623e+08 | X12: 2.3585162e+08 | Y12: 2.3775701e+08 | Z12: 2.3966241e+08 | AA12: 2.415678e+08 | AB12: 2.4347319e+08 | AC12: 2.4537858e+08 | AD12: 2.4728397e+08 | AE12: 2.4918936e+08 | AF12: 2.5109475e+08 | AG12: 2.5300015e+08 | AH12: 2.5490554e+08 | AI12: 2.5681093e+08 | AJ12: 2.5871632e+08
A13: PCV | B13: 160800000 | C13: 187000000 | D13: 209200000 | E13: 205900000 | F13: 221000000 | G13: 219100000 | H13: 222300000 | I13: 217300000 | J13: 218800000 | K13: 220200000 | L13: 2.289149e+08 | M13: 2.238492e+08 | N13: 2.3483374e+08 | O13: 2.3731792e+08 | P13: 2.4603136e+08 | Q13: 2.4096566e+08 | R13: 2.519502e+08 | S13: 2.5443439e+08 | T13: 2.6314782e+08 | U13: 2.5808212e+08 | V13: 2.6906666e+08 | W13: 2.7155085e+08 | X13: 2.8026428e+08 | Y13: 2.7519859e+08 | Z13: 2.8618312e+08 | AA13: 2.8866731e+08 | AB13: 2.9738074e+08 | AC13: 2.9231505e+08 | AD13: 3.0329959e+08 | AE13: 3.0578377e+08 | AF13: 3.144972e+08 | AG13: 3.0943151e+08 | AH13: 3.2041605e+08 | AI13: 3.2290023e+08 | AJ13: 3.3161367e+08

Sheet forecast_data
B1: 1 | C1: 2 | D1: 3 | E1: 4 | F1: 5 | G1: 6 | H1: 7 | I1: 8 | J1: 9 | K1: 10
A2: Measles | B2: 372100000 | C2: 292000000 | D2: 322200000 | E2: 298200000 | F2: 313700000 | G2: 407500000 | H2: 279000000 | I2: 406500000 | J2: 311500000 | K2: 348800000
A3: Mumps | B3: 26100000 | C3: 26600000 | D3: 25800000 | E3: 25300000 | F3: 23500000 | G3: 16200000 | H3: 18700000 | I3: 8900000 | J3: 10700000 | K3: 13000000
A4: Rubella | B4: 357300000 | C4: 254000000 | D4: 304600000 | E4: 276900000 | F4: 291300000 | G4: 386500000 | H4: 259100000 | I4: 385700000 | J4: 289600000 | K4: 325900000
A5: MMR | B5: =MAX(B2:B4) -> 372100000 | C5: =MAX(C2:C4) -> 292000000 | D5: =MAX(D2:D4) -> 322200000 | E5: =MAX(E2:E4) -> 298200000 | F5: =MAX(F2:F4) -> 313700000 | G5: =MAX(G2:G4) -> 407500000 | H5: =MAX(H2:H4) -> 279000000 | I5: =MAX(I2:I4) -> 406500000 | ... K5: =MAX(K2:K4) -> 348800000
A6: Diphtheria | B6: 570600000 | C6: 619500000 | D6: 626500000 | E6: 594500000 | F6: 596000000 | G6: 587100000 | H6: 593100000 | I6: 588000000 | J6: 594700000 | K6: 600200000
A7: Tetanus | B7: 577700000 | C7: 626400000 | D7: 633300000 | E7: 601300000 | F7: 598900000 | G7: 590000000 | H7: 596100000 | I7: 591000000 | J7: 597800000 | K7: 603200000
A8: Pertussis | B8: 320700000 | C8: 347400000 | D8: 352500000 | E8: 336000000 | F8: 334900000 | G8: 328000000 | H8: 331200000 | I8: 328300000 | J8: 331500000 | K8: 334300000
A9: Hepatitis_B | B9: 312300000 | C9: 343000000 | D9: 351700000 | E9: 335000000 | F9: 334500000 | G9: 328400000 | H9: 332300000 | I9: 328200000 | J9: 332200000 | K9: 335500000
A10: Hib | B10: 259500000 | C10: 282800000 | D10: 287300000 | E10: 274000000 | F10: 274300000 | G10: 270000000 | H10: 273100000 | I10: 270400000 | J10: 273700000 | K10: 276700000
A11: Polio | B11: 522200000 | C11: 582200000 | D11: 608600000 | E11: 590700000 | F11: 591700000 | G11: 572500000 | H11: 130800000 | I11: 128500000 | J11: 130800000 | K11: 133000000
A12: HPV | B12: 19000000 | C12: 18800000 | D12: 27500000 | E12: 72800000 | F12: 92700000 | G12: 64700000 | H12: 42200000 | I12: 42400000 | J12: 33700000 | K12: 35000000
A13: Rotavirus | B13: 142500000 | C13: 166400000 | D13: 173800000 | E13: 186300000 | F13: 197700000 | G13: 205700000 | H13: 209600000 | I13: 207400000 | J13: 209600000 | K13: 211800000
A14: PCV | B14: 160800000 | C14: 187000000 | D14: 209200000 | E14: 205900000 | F14: 221000000 | G14: 219100000 | H14: 222300000 | I14: 217300000 | J14: 218800000 | K14: 220200000

Sheet Pandemic_Effect
B1: 1 | C1: 2 | D1: 3 | E1: 4 | F1: 5 | G1: 6 | H1: 7 | I1: 8 | J1: 9 | K1: 10
A2: Measles | B2: 372100000 | C2: 292000000 | D2: 322200000 | E2: 298200000 | F2: 313700000 | G2: 326000000 | H2: 223200000 | I2: 487800000 | J2: 373800000 | K2: 348800000 | O2: Demand assumed to be decreased by 20%
A3: Mumps | B3: 26100000 | C3: 26600000 | D3: 25800000 | E3: 25300000 | F3: 23500000 | G3: 12960000 | H3: 14960000 | I3: 10680000 | J3: 12840000 | K3: 13000000 | O3: Demand assumed to be increased by 20%
A4: Rubella | B4: 357300000 | C4: 254000000 | D4: 304600000 | E4: 276900000 | F4: 291300000 | G4: 309200000 | H4: 207280000 | I4: 462840000 | J4: 347520000 | K4: 325900000
A5: Diphtheria | B5: 570600000 | C5: 619500000 | D5: 626500000 | E5: 594500000 | F5: 596000000 | G5: 469680000 | H5: 474480000 | I5: 705600000 | J5: 713640000 | K5: 600200000
A6: Tetanus | B6: 577700000 | C6: 626400000 | D6: 633300000 | E6: 601300000 | F6: 598900000 | G6: 472000000 | H6: 476880000 | I6: 709200000 | J6: 717360000 | K6: 603200000
A7: Pertussis | B7: 320700000 | C7: 347400000 | D7: 352500000 | E7: 336000000 | F7: 334900000 | G7: 262400000 | H7: 264960000 | I7: 393960000 | J7: 397800000 | K7: 334300000
A8: Hepatitis_B | B8: 312300000 | C8: 343000000 | D8: 351700000 | E8: 335000000 | F8: 334500000 | G8: 262720000 | H8: 265840000 | I8: 393840000 | J8: 398640000 | K8: 335500000
A9: Hib | B9: 259500000 | C9: 282800000 | D9: 287300000 | E9: 274000000 | F9: 274300000 | G9: 216000000 | H9: 218480000 | I9: 324480000 | J9: 328440000 | K9: 276700000
A10: IPV | B10: 522200000 | C10: 582200000 | D10: 608600000 | E10: 590700000 | F10: 591700000 | G10: 458000000 | H10: 104640000 | I10: 154200000 | J10: 156960000 | K10: 133000000
A11: HPV | B11: 19000000 | C11: 18800000 | D11: 27500000 | E11: 72800000 | F11: 92700000 | G11: 51760000 | H11: 33760000 | I11: 50880000 | J11: 40440000 | K11: 35000000
A12: Rotavirus | B12: 142500000 | C12: 166400000 | D12: 173800000 | E12: 186300000 | F12: 197700000 | G12: 164560000 | H12: 167680000 | I12: 248880000 | J12: 251520000 | K12: 211800000
A13: PCV | B13: 160800000 | C13: 187000000 | D13: 209200000 | E13: 205900000 | F13: 221000000 | G13: 175280000 | H13: 177840000 | I13: 260760000 | J13: 262560000 | K13: 220200000

Sheet Vaccine_Replacement_Effect
B1: 1 | C1: 2 | D1: 3 | E1: 4 | F1: 5 | G1: 6 | H1: 7 | I1: 8 | J1: 9 | K1: 10
A2: Measles | B2: 372100000 | C2: 292000000 | D2: 322200000 | E2: 298200000 | F2: 313700000 | G2: 407500000 | H2: 279000000 | I2: 406500000 | J2: 311500000 | K2: 348800000 | M2: 50% of MR is replaced by MMR
A3: Mumps | B3: 26100000 | C3: 26600000 | D3: 25800000 | E3: 25300000 | F3: 23500000 | G3: 2.0136864e+08 | H3: 1.3891208e+08 | I3: 1.972909e+08 | J3: 1.5013696e+08 | K3: 1.6943948e+08 | M3: 50% of Penta is replaced by Hexa
A4: Rubella | B4: 357300000 | C4: 254000000 | D4: 304600000 | E4: 276900000 | F4: 291300000 | G4: 386500000 | H4: 259100000 | I4: 385700000 | J4: 289600000 | K4: 325900000
A5: Diphtheria | B5: 570600000 | C5: 619500000 | D5: 626500000 | E5: 594500000 | F5: 596000000 | G5: 587100000 | H5: 593100000 | I5: 588000000 | J5: 594700000 | K5: 600200000 | N5: Demand of Mumps increases by 50% of the demand of MR
A6: Tetanus | B6: 577700000 | C6: 626400000 | D6: 633300000 | E6: 601300000 | F6: 598900000 | G6: 590000000 | H6: 596100000 | I6: 591000000 | J6: 597800000 | K6: 603200000 | N6: Demand of IPV increases by 50% of the demand of Penta
A7: Pertussis | B7: 320700000 | C7: 347400000 | D7: 352500000 | E7: 336000000 | F7: 334900000 | G7: 328000000 | H7: 331200000 | I7: 328300000 | J7: 331500000 | K7: 334300000
A8: Hepatitis_B | B8: 312300000 | C8: 343000000 | D8: 351700000 | E8: 335000000 | F8: 334500000 | G8: 328400000 | H8: 332300000 | I8: 328200000 | J8: 332200000 | K8: 335500000
A9: Hib | B9: 259500000 | C9: 282800000 | D9: 287300000 | E9: 274000000 | F9: 274300000 | G9: 270000000 | H9: 273100000 | I9: 270400000 | J9: 273700000 | K9: 276700000
A10: IPV | B10: 522200000 | C10: 582200000 | D10: 608600000 | E10: 590700000 | F10: 591700000 | G10: 7.0440007e+08 | H10: 2.642207e+08 | I10: 2.6069027e+08 | J10: 2.6461336e+08 | K10: 2.6828481e+08
A11: HPV | B11: 19000000 | C11: 18800000 | D11: 27500000 | E11: 72800000 | F11: 92700000 | G11: 64700000 | H11: 42200000 | I11: 42400000 | J11: 33700000 | K11: 35000000
A12: Rotavirus | B12: 142500000 | C12: 166400000 | D12: 173800000 | E12: 186300000 | F12: 197700000 | G12: 205700000 | H12: 209600000 | I12: 207400000 | J12: 209600000 | K12: 211800000
A13: PCV | B13: 160800000 | C13: 187000000 | D13: 209200000 | E13: 205900000 | F13: 221000000 | G13: 219100000 | H13: 222300000 | I13: 217300000 | J13: 218800000 | K13: 220200000

Sheet Weighted_Avg_Demand_for_Scen.
B1: 1 | C1: 2 | D1: 3 | E1: 4 | F1: 5 | G1: 6 | H1: 7 | I1: 8 | J1: 9 | K1: 10
A2: Measles | B2: =+Vaccine_Replacement_Effect!B2*0.05+Pandemic_Effect!B2*0.05+Medium_Demand!B2*0.3+Medium_Demand!B2*0.3*0.8+Medium_Demand!B2*0.3*1.2 -> 372100000 | C2: =+Vaccine_Replacement_Effect!C2*0.05+Pandemic_Effect!C2*0.05+Medium_Demand!C2*0.3+Medium_Demand!C2*0.3*0.8+Medium_Demand!C2*0.3*1.2 -> 292000000 | D2: =+Vaccine_Replacement_Effect!D2*0.05+Pandemic_Effect!D2*0.05+Medium_Demand!D2*0.3+Medium_Demand!D2*0.3*0.8+Medium_Demand!D2*0.3*1.2 -> 322200000 | E2: =+Vaccine_Replacement_Effect!E2*0.05+Pandemic_Effect!E2*0.05+Medium_Demand!E2*0.3+Medium_Demand!E2*0.3*0.8+Medium_Demand!E2*0.3*1.2 -> 298200000 | F2: =+Vaccine_Replacement_Effect!F2*0.05+Pandemic_Effect!F2*0.05+Medium_Demand!F2*0.3+Medium_Demand!F2*0.3*0.8+Medium_Demand!F2*0.3*1.2 -> 313700000 | G2: =+Vaccine_Replacement_Effect!G2*0.05+Pandemic_Effect!G2*0.05+Medium_Demand!G2*0.3+Medium_Demand!G2*0.3*0.8+Medium_Demand!G2*0.3*1.2 -> 403425000 | H2: =+Vaccine_Replacement_Effect!H2*0.05+Pandemic_Effect!H2*0.05+Medium_Demand!H2*0.3+Medium_Demand!H2*0.3*0.8+Medium_Demand!H2*0.3*1.2 -> 276210000 | I2: =+Vaccine_Replacement_Effect!I2*0.05+Pandemic_Effect!I2*0.05+Medium_Demand!I2*0.3+Medium_Demand!I2*0.3*0.8+Medium_Demand!I2*0.3*1.2 -> 410565000 | ... K2: =+Vaccine_Replacement_Effect!K2*0.05+Pandemic_Effect!K2*0.05+Medium_Demand!K2*0.3+Medium_Demand!K2*0.3*0.8+Medium_Demand!K2*0.3*1.2 -> 348800000 | M2: =+SUM(B2:K2) -> 3351815000 | O2: M | P2: 220618000 | Q2: Measles | R2: =+P2+P3+P4 -> 3351815000
A3: Mumps | B3: =+Vaccine_Replacement_Effect!B3*0.05+Pandemic_Effect!B3*0.05+Medium_Demand!B3*0.3+Medium_Demand!B3*0.3*0.8+Medium_Demand!B3*0.3*1.2 -> 22543904 | C3: =+Vaccine_Replacement_Effect!C3*0.05+Pandemic_Effect!C3*0.05+Medium_Demand!C3*0.3+Medium_Demand!C3*0.3*0.8+Medium_Demand!C3*0.3*1.2 -> 22555078 | D3: =+Vaccine_Replacement_Effect!D3*0.05+Pandemic_Effect!D3*0.05+Medium_Demand!D3*0.3+Medium_Demand!D3*0.3*0.8+Medium_Demand!D3*0.3*1.2 -> 20433999 | E3: =+Vaccine_Replacement_Effect!E3*0.05+Pandemic_Effect!E3*0.05+Medium_Demand!E3*0.3+Medium_Demand!E3*0.3*0.8+Medium_Demand!E3*0.3*1.2 -> 26321036 | F3: =+Vaccine_Replacement_Effect!F3*0.05+Pandemic_Effect!F3*0.05+Medium_Demand!F3*0.3+Medium_Demand!F3*0.3*0.8+Medium_Demand!F3*0.3*1.2 -> 21013965 | G3: =+Vaccine_Replacement_Effect!G3*0.05+Pandemic_Effect!G3*0.05+Medium_Demand!G3*0.3+Medium_Demand!G3*0.3*0.8+Medium_Demand!G3*0.3*1.2 -> 28989245 | H3: =+Vaccine_Replacement_Effect!H3*0.05+Pandemic_Effect!H3*0.05+Medium_Demand!H3*0.3+Medium_Demand!H3*0.3*0.8+Medium_Demand!H3*0.3*1.2 -> 29234389 | I3: =+Vaccine_Replacement_Effect!I3*0.05+Pandemic_Effect!I3*0.05+Medium_Demand!I3*0.3+Medium_Demand!I3*0.3*0.8+Medium_Demand!I3*0.3*1.2 -> 30012220 | ... K3: =+Vaccine_Replacement_Effect!K3*0.05+Pandemic_Effect!K3*0.05+Medium_Demand!K3*0.3+Medium_Demand!K3*0.3*0.8+Medium_Demand!K3*0.3*1.2 -> 27769057 | M3: =+SUM(B3:K3) -> 2.538472e+08 | O3: MR | P3: 2897067597 | Q3: Mumps | R3: =+P4 -> 234129403
A4: Rubella | B4: =+Vaccine_Replacement_Effect!B4*0.05+Pandemic_Effect!B4*0.05+Medium_Demand!B4*0.3+Medium_Demand!B4*0.3*0.8+Medium_Demand!B4*0.3*1.2 -> 357300000 | C4: =+Vaccine_Replacement_Effect!C4*0.05+Pandemic_Effect!C4*0.05+Medium_Demand!C4*0.3+Medium_Demand!C4*0.3*0.8+Medium_Demand!C4*0.3*1.2 -> 254000000 | D4: =+Vaccine_Replacement_Effect!D4*0.05+Pandemic_Effect!D4*0.05+Medium_Demand!D4*0.3+Medium_Demand!D4*0.3*0.8+Medium_Demand!D4*0.3*1.2 -> 304600000 | E4: =+Vaccine_Replacement_Effect!E4*0.05+Pandemic_Effect!E4*0.05+Medium_Demand!E4*0.3+Medium_Demand!E4*0.3*0.8+Medium_Demand!E4*0.3*1.2 -> 276900000 | F4: =+Vaccine_Replacement_Effect!F4*0.05+Pandemic_Effect!F4*0.05+Medium_Demand!F4*0.3+Medium_Demand!F4*0.3*0.8+Medium_Demand!F4*0.3*1.2 -> 291300000 | G4: =+Vaccine_Replacement_Effect!G4*0.05+Pandemic_Effect!G4*0.05+Medium_Demand!G4*0.3+Medium_Demand!G4*0.3*0.8+Medium_Demand!G4*0.3*1.2 -> 382635000 | H4: =+Vaccine_Replacement_Effect!H4*0.05+Pandemic_Effect!H4*0.05+Medium_Demand!H4*0.3+Medium_Demand!H4*0.3*0.8+Medium_Demand!H4*0.3*1.2 -> 256509000 | I4: =+Vaccine_Replacement_Effect!I4*0.05+Pandemic_Effect!I4*0.05+Medium_Demand!I4*0.3+Medium_Demand!I4*0.3*0.8+Medium_Demand!I4*0.3*1.2 -> 389557000 | ... K4: =+Vaccine_Replacement_Effect!K4*0.05+Pandemic_Effect!K4*0.05+Medium_Demand!K4*0.3+Medium_Demand!K4*0.3*0.8+Medium_Demand!K4*0.3*1.2 -> 325900000 | M4: =+SUM(B4:K4) -> 3131197000 | O4: MMR | P4: 234129403 | Q4: Rubella | R4: =+P4+P3 -> 3131197000
A5: Diphtheria | B5: =+Vaccine_Replacement_Effect!B5*0.05+Pandemic_Effect!B5*0.05+Medium_Demand!B5*0.3+Medium_Demand!B5*0.3*0.8+Medium_Demand!B5*0.3*1.2 -> 570600000 | C5: =+Vaccine_Replacement_Effect!C5*0.05+Pandemic_Effect!C5*0.05+Medium_Demand!C5*0.3+Medium_Demand!C5*0.3*0.8+Medium_Demand!C5*0.3*1.2 -> 619500000 | D5: =+Vaccine_Replacement_Effect!D5*0.05+Pandemic_Effect!D5*0.05+Medium_Demand!D5*0.3+Medium_Demand!D5*0.3*0.8+Medium_Demand!D5*0.3*1.2 -> 626500000 | E5: =+Vaccine_Replacement_Effect!E5*0.05+Pandemic_Effect!E5*0.05+Medium_Demand!E5*0.3+Medium_Demand!E5*0.3*0.8+Medium_Demand!E5*0.3*1.2 -> 594500000 | F5: =+Vaccine_Replacement_Effect!F5*0.05+Pandemic_Effect!F5*0.05+Medium_Demand!F5*0.3+Medium_Demand!F5*0.3*0.8+Medium_Demand!F5*0.3*1.2 -> 596000000 | G5: =+Vaccine_Replacement_Effect!G5*0.05+Pandemic_Effect!G5*0.05+Medium_Demand!G5*0.3+Medium_Demand!G5*0.3*0.8+Medium_Demand!G5*0.3*1.2 -> 581229000 | H5: =+Vaccine_Replacement_Effect!H5*0.05+Pandemic_Effect!H5*0.05+Medium_Demand!H5*0.3+Medium_Demand!H5*0.3*0.8+Medium_Demand!H5*0.3*1.2 -> 587169000 | I5: =+Vaccine_Replacement_Effect!I5*0.05+Pandemic_Effect!I5*0.05+Medium_Demand!I5*0.3+Medium_Demand!I5*0.3*0.8+Medium_Demand!I5*0.3*1.2 -> 593880000 | ... K5: =+Vaccine_Replacement_Effect!K5*0.05+Pandemic_Effect!K5*0.05+Medium_Demand!K5*0.3+Medium_Demand!K5*0.3*0.8+Medium_Demand!K5*0.3*1.2 -> 600200000
A6: Tetanus | B6: =+Vaccine_Replacement_Effect!B6*0.05+Pandemic_Effect!B6*0.05+Medium_Demand!B6*0.3+Medium_Demand!B6*0.3*0.8+Medium_Demand!B6*0.3*1.2 -> 577700000 | C6: =+Vaccine_Replacement_Effect!C6*0.05+Pandemic_Effect!C6*0.05+Medium_Demand!C6*0.3+Medium_Demand!C6*0.3*0.8+Medium_Demand!C6*0.3*1.2 -> 626400000 | D6: =+Vaccine_Replacement_Effect!D6*0.05+Pandemic_Effect!D6*0.05+Medium_Demand!D6*0.3+Medium_Demand!D6*0.3*0.8+Medium_Demand!D6*0.3*1.2 -> 633300000 | E6: =+Vaccine_Replacement_Effect!E6*0.05+Pandemic_Effect!E6*0.05+Medium_Demand!E6*0.3+Medium_Demand!E6*0.3*0.8+Medium_Demand!E6*0.3*1.2 -> 601300000 | F6: =+Vaccine_Replacement_Effect!F6*0.05+Pandemic_Effect!F6*0.05+Medium_Demand!F6*0.3+Medium_Demand!F6*0.3*0.8+Medium_Demand!F6*0.3*1.2 -> 598900000 | G6: =+Vaccine_Replacement_Effect!G6*0.05+Pandemic_Effect!G6*0.05+Medium_Demand!G6*0.3+Medium_Demand!G6*0.3*0.8+Medium_Demand!G6*0.3*1.2 -> 584100000 | H6: =+Vaccine_Replacement_Effect!H6*0.05+Pandemic_Effect!H6*0.05+Medium_Demand!H6*0.3+Medium_Demand!H6*0.3*0.8+Medium_Demand!H6*0.3*1.2 -> 590139000 | I6: =+Vaccine_Replacement_Effect!I6*0.05+Pandemic_Effect!I6*0.05+Medium_Demand!I6*0.3+Medium_Demand!I6*0.3*0.8+Medium_Demand!I6*0.3*1.2 -> 596910000 | ... K6: =+Vaccine_Replacement_Effect!K6*0.05+Pandemic_Effect!K6*0.05+Medium_Demand!K6*0.3+Medium_Demand!K6*0.3*0.8+Medium_Demand!K6*0.3*1.2 -> 603200000
A7: Pertussis | B7: =+Vaccine_Replacement_Effect!B7*0.05+Pandemic_Effect!B7*0.05+Medium_Demand!B7*0.3+Medium_Demand!B7*0.3*0.8+Medium_Demand!B7*0.3*1.2 -> 320700000 | C7: =+Vaccine_Replacement_Effect!C7*0.05+Pandemic_Effect!C7*0.05+Medium_Demand!C7*0.3+Medium_Demand!C7*0.3*0.8+Medium_Demand!C7*0.3*1.2 -> 347400000 | D7: =+Vaccine_Replacement_Effect!D7*0.05+Pandemic_Effect!D7*0.05+Medium_Demand!D7*0.3+Medium_Demand!D7*0.3*0.8+Medium_Demand!D7*0.3*1.2 -> 352500000 | E7: =+Vaccine_Replacement_Effect!E7*0.05+Pandemic_Effect!E7*0.05+Medium_Demand!E7*0.3+Medium_Demand!E7*0.3*0.8+Medium_Demand!E7*0.3*1.2 -> 336000000 | F7: =+Vaccine_Replacement_Effect!F7*0.05+Pandemic_Effect!F7*0.05+Medium_Demand!F7*0.3+Medium_Demand!F7*0.3*0.8+Medium_Demand!F7*0.3*1.2 -> 334900000 | G7: =+Vaccine_Replacement_Effect!G7*0.05+Pandemic_Effect!G7*0.05+Medium_Demand!G7*0.3+Medium_Demand!G7*0.3*0.8+Medium_Demand!G7*0.3*1.2 -> 324720000 | H7: =+Vaccine_Replacement_Effect!H7*0.05+Pandemic_Effect!H7*0.05+Medium_Demand!H7*0.3+Medium_Demand!H7*0.3*0.8+Medium_Demand!H7*0.3*1.2 -> 327888000 | I7: =+Vaccine_Replacement_Effect!I7*0.05+Pandemic_Effect!I7*0.05+Medium_Demand!I7*0.3+Medium_Demand!I7*0.3*0.8+Medium_Demand!I7*0.3*1.2 -> 331583000 | ... K7: =+Vaccine_Replacement_Effect!K7*0.05+Pandemic_Effect!K7*0.05+Medium_Demand!K7*0.3+Medium_Demand!K7*0.3*0.8+Medium_Demand!K7*0.3*1.2 -> 334300000
A8: Hepatitis_B | B8: =+Vaccine_Replacement_Effect!B8*0.05+Pandemic_Effect!B8*0.05+Medium_Demand!B8*0.3+Medium_Demand!B8*0.3*0.8+Medium_Demand!B8*0.3*1.2 -> 312300000 | C8: =+Vaccine_Replacement_Effect!C8*0.05+Pandemic_Effect!C8*0.05+Medium_Demand!C8*0.3+Medium_Demand!C8*0.3*0.8+Medium_Demand!C8*0.3*1.2 -> 343000000 | D8: =+Vaccine_Replacement_Effect!D8*0.05+Pandemic_Effect!D8*0.05+Medium_Demand!D8*0.3+Medium_Demand!D8*0.3*0.8+Medium_Demand!D8*0.3*1.2 -> 351700000 | E8: =+Vaccine_Replacement_Effect!E8*0.05+Pandemic_Effect!E8*0.05+Medium_Demand!E8*0.3+Medium_Demand!E8*0.3*0.8+Medium_Demand!E8*0.3*1.2 -> 335000000 | F8: =+Vaccine_Replacement_Effect!F8*0.05+Pandemic_Effect!F8*0.05+Medium_Demand!F8*0.3+Medium_Demand!F8*0.3*0.8+Medium_Demand!F8*0.3*1.2 -> 334500000 | G8: =+Vaccine_Replacement_Effect!G8*0.05+Pandemic_Effect!G8*0.05+Medium_Demand!G8*0.3+Medium_Demand!G8*0.3*0.8+Medium_Demand!G8*0.3*1.2 -> 325116000 | H8: =+Vaccine_Replacement_Effect!H8*0.05+Pandemic_Effect!H8*0.05+Medium_Demand!H8*0.3+Medium_Demand!H8*0.3*0.8+Medium_Demand!H8*0.3*1.2 -> 328977000 | I8: =+Vaccine_Replacement_Effect!I8*0.05+Pandemic_Effect!I8*0.05+Medium_Demand!I8*0.3+Medium_Demand!I8*0.3*0.8+Medium_Demand!I8*0.3*1.2 -> 331482000 | ... K8: =+Vaccine_Replacement_Effect!K8*0.05+Pandemic_Effect!K8*0.05+Medium_Demand!K8*0.3+Medium_Demand!K8*0.3*0.8+Medium_Demand!K8*0.3*1.2 -> 335500000
A9: Hib | B9: =+Vaccine_Replacement_Effect!B9*0.05+Pandemic_Effect!B9*0.05+Medium_Demand!B9*0.3+Medium_Demand!B9*0.3*0.8+Medium_Demand!B9*0.3*1.2 -> 259500000 | C9: =+Vaccine_Replacement_Effect!C9*0.05+Pandemic_Effect!C9*0.05+Medium_Demand!C9*0.3+Medium_Demand!C9*0.3*0.8+Medium_Demand!C9*0.3*1.2 -> 282800000 | D9: =+Vaccine_Replacement_Effect!D9*0.05+Pandemic_Effect!D9*0.05+Medium_Demand!D9*0.3+Medium_Demand!D9*0.3*0.8+Medium_Demand!D9*0.3*1.2 -> 287300000 | E9: =+Vaccine_Replacement_Effect!E9*0.05+Pandemic_Effect!E9*0.05+Medium_Demand!E9*0.3+Medium_Demand!E9*0.3*0.8+Medium_Demand!E9*0.3*1.2 -> 274000000 | F9: =+Vaccine_Replacement_Effect!F9*0.05+Pandemic_Effect!F9*0.05+Medium_Demand!F9*0.3+Medium_Demand!F9*0.3*0.8+Medium_Demand!F9*0.3*1.2 -> 274300000 | G9: =+Vaccine_Replacement_Effect!G9*0.05+Pandemic_Effect!G9*0.05+Medium_Demand!G9*0.3+Medium_Demand!G9*0.3*0.8+Medium_Demand!G9*0.3*1.2 -> 267300000 | H9: =+Vaccine_Replacement_Effect!H9*0.05+Pandemic_Effect!H9*0.05+Medium_Demand!H9*0.3+Medium_Demand!H9*0.3*0.8+Medium_Demand!H9*0.3*1.2 -> 270369000 | I9: =+Vaccine_Replacement_Effect!I9*0.05+Pandemic_Effect!I9*0.05+Medium_Demand!I9*0.3+Medium_Demand!I9*0.3*0.8+Medium_Demand!I9*0.3*1.2 -> 273104000 | ... K9: =+Vaccine_Replacement_Effect!K9*0.05+Pandemic_Effect!K9*0.05+Medium_Demand!K9*0.3+Medium_Demand!K9*0.3*0.8+Medium_Demand!K9*0.3*1.2 -> 276700000
A10: IPV | B10: =+Vaccine_Replacement_Effect!B10*0.05+Pandemic_Effect!B10*0.05+Medium_Demand!B10*0.3+Medium_Demand!B10*0.3*0.8+Medium_Demand!B10*0.3*1.2 -> 522200000 | C10: =+Vaccine_Replacement_Effect!C10*0.05+Pandemic_Effect!C10*0.05+Medium_Demand!C10*0.3+Medium_Demand!C10*0.3*0.8+Medium_Demand!C10*0.3*1.2 -> 582200000 | D10: =+Vaccine_Replacement_Effect!D10*0.05+Pandemic_Effect!D10*0.05+Medium_Demand!D10*0.3+Medium_Demand!D10*0.3*0.8+Medium_Demand!D10*0.3*1.2 -> 608600000 | E10: =+Vaccine_Replacement_Effect!E10*0.05+Pandemic_Effect!E10*0.05+Medium_Demand!E10*0.3+Medium_Demand!E10*0.3*0.8+Medium_Demand!E10*0.3*1.2 -> 590700000 | F10: =+Vaccine_Replacement_Effect!F10*0.05+Pandemic_Effect!F10*0.05+Medium_Demand!F10*0.3+Medium_Demand!F10*0.3*0.8+Medium_Demand!F10*0.3*1.2 -> 591700000 | G10: =+Vaccine_Replacement_Effect!G10*0.05+Pandemic_Effect!G10*0.05+Medium_Demand!G10*0.3+Medium_Demand!G10*0.3*0.8+Medium_Demand!G10*0.3*1.2 -> 5.7337e+08 | H10: =+Vaccine_Replacement_Effect!H10*0.05+Pandemic_Effect!H10*0.05+Medium_Demand!H10*0.3+Medium_Demand!H10*0.3*0.8+Medium_Demand!H10*0.3*1.2 -> 1.3616304e+08 | I10: =+Vaccine_Replacement_Effect!I10*0.05+Pandemic_Effect!I10*0.05+Medium_Demand!I10*0.3+Medium_Demand!I10*0.3*0.8+Medium_Demand!I10*0.3*1.2 -> 1.3639451e+08 | ... K10: =+Vaccine_Replacement_Effect!K10*0.05+Pandemic_Effect!K10*0.05+Medium_Demand!K10*0.3+Medium_Demand!K10*0.3*0.8+Medium_Demand!K10*0.3*1.2 -> 1.3976424e+08
A11: HPV | B11: =+Vaccine_Replacement_Effect!B11*0.05+Pandemic_Effect!B11*0.05+Medium_Demand!B11*0.3+Medium_Demand!B11*0.3*0.8+Medium_Demand!B11*0.3*1.2 -> 19000000 | C11: =+Vaccine_Replacement_Effect!C11*0.05+Pandemic_Effect!C11*0.05+Medium_Demand!C11*0.3+Medium_Demand!C11*0.3*0.8+Medium_Demand!C11*0.3*1.2 -> 18800000 | D11: =+Vaccine_Replacement_Effect!D11*0.05+Pandemic_Effect!D11*0.05+Medium_Demand!D11*0.3+Medium_Demand!D11*0.3*0.8+Medium_Demand!D11*0.3*1.2 -> 27500000 | E11: =+Vaccine_Replacement_Effect!E11*0.05+Pandemic_Effect!E11*0.05+Medium_Demand!E11*0.3+Medium_Demand!E11*0.3*0.8+Medium_Demand!E11*0.3*1.2 -> 72800000 | F11: =+Vaccine_Replacement_Effect!F11*0.05+Pandemic_Effect!F11*0.05+Medium_Demand!F11*0.3+Medium_Demand!F11*0.3*0.8+Medium_Demand!F11*0.3*1.2 -> 92700000 | G11: =+Vaccine_Replacement_Effect!G11*0.05+Pandemic_Effect!G11*0.05+Medium_Demand!G11*0.3+Medium_Demand!G11*0.3*0.8+Medium_Demand!G11*0.3*1.2 -> 64053000 | H11: =+Vaccine_Replacement_Effect!H11*0.05+Pandemic_Effect!H11*0.05+Medium_Demand!H11*0.3+Medium_Demand!H11*0.3*0.8+Medium_Demand!H11*0.3*1.2 -> 41778000 | I11: =+Vaccine_Replacement_Effect!I11*0.05+Pandemic_Effect!I11*0.05+Medium_Demand!I11*0.3+Medium_Demand!I11*0.3*0.8+Medium_Demand!I11*0.3*1.2 -> 42824000 | ... K11: =+Vaccine_Replacement_Effect!K11*0.05+Pandemic_Effect!K11*0.05+Medium_Demand!K11*0.3+Medium_Demand!K11*0.3*0.8+Medium_Demand!K11*0.3*1.2 -> 35000000
