Workbook
Name GAVI_countries: #REF!

Sheet F_start
A1: Antigen | B1: Starting | C1: Ending
A2: Measles | B2: 1 | C2: 1
A3: Mumps | B3: 1 | C3: 1
A4: Rubella | B4: 1 | C4: 1
A5: Diphtheria | B5: 1 | C5: 1
A6: Tetanus | B6: 1 | C6: 1
A7: Pertussis | B7: 1 | C7: 1
A8: Hib | B8: 1 | C8: 1
A9: Hepatitis_B | B9: 1 | C9: 1
A10: Polio | B10: 1 | C10: 1
A11: HPV | B11: 1 | C11: 1
A12: Rotavirus | B12: 1 | C12: 1
A13: PCV | B13: 1 | C13: 1

Sheet Q_start
A1: Vaccine | B1: Producer | C1: Start | D1: End | E1: Amount
A2: M | B2: Serum_Institute | C2: 1 | D2: 1 | E2: =ROUND(F2*G2,0) -> 0 | F2: 0 | G2: 1
A3: M | B3: PT_Bio | C3: 1 | D3: 1 | E3: =ROUND(F3*G3,0) -> 13299464 | F3: 13299464 | G3: 1
A4: MR | B4: Serum_Institute | C4: 1 | D4: 1 | E4: =ROUND(F4*G4,0) -> 0 | F4: 0 | G4: 1
A5: MR | B5: Biological_E | C5: 1 | D5: 1 | E5: =ROUND(F5*G5,0) -> 90279149 | F5: 90279149 | G5: 1
A6: MMR | B6: Serum_Institute | C6: 1 | D6: 1 | E6: =ROUND(F6*G6,0) -> 13547121 | F6: 13547121 | G6: 1
A7: MMR | B7: GSK | C7: 1 | D7: 1 | E7: =ROUND(F7*G7,0) -> 12505034 | F7: 12505034 | G7: 1
A8: MMR | B8: Merck_Sharp | C8: 1 | D8: 1 | E8: =ROUND(F8*G8,0) -> 2182374 | F8: 2182374 | G8: 1
A9: TT | B9: Serum_Institute | C9: 1 | D9: 1 | E9: =ROUND(F9*G9,0) -> 4334425 | F9: 4334425 | G9: 1
A10: TT | B10: PT_Bio | C10: 1 | D10: 1 | E10: =ROUND(F10*G10,0) -> 0 | F10: 0 | G10: 1
A11: TT | B11: BB_NCIPD | C11: 1 | D11: 1 | E11: =ROUND(F11*G11,0) -> 0 | F11: 0 | G11: 1
A12: HepB | B12: Serum_Institute | C12: 1 | D12: 1 | E12: =ROUND(F12*G12,0) -> 0 | F12: 0 | G12: 1
A13: HepB | B13: LG_Chem | C13: 1 | D13: 1 | E13: =ROUND(F13*G13,0) -> 0 | F13: 0 | G13: 1
... A52: PCV | B52: Pfizer | C52: 1 | D52: 1 | E52: =ROUND(F52*G52,0) -> 4000000 | F52: 4000000 | G52: 1

Sheet I_start
A1: Vaccine | B1: Amount | C1: .025 demand | D1: Rand | E1: ran val
A2: M | B2: =ROUND(C2,0) -> 3694296 | C2: =Medium_Capacity!C49*0.25 -> 3694295.6 | D2: =RAND() -> 0.50393182 | E2: =C2*D2 -> 1861673.1
A3: MR | B3: =ROUND(C3,0) -> 82819787 | C3: =Medium_Capacity!C50*0.25 -> 82819787 | D3: =RAND() -> 0.34903804 | E3: =C3*D3 -> 28907256
A4: MMR | B4: =ROUND(C4,0) -> 6513039 | C4: =Medium_Capacity!C51*0.25 -> 6513039 | D4: =RAND() -> 0.74577401 | E4: =C4*D4 -> 4857255.2
A5: TT | B5: =ROUND(C5,0) -> 1795008 | C5: =Medium_Capacity!C52*0.25 -> 1795007.7 | D5: =RAND() -> 0.57136908 | E5: =C5*D5 -> 1025611.9
A6: Td | B6: =ROUND(C6,0) -> 60870627 | C6: =Medium_Capacity!C53*0.25 -> 60870627 | D6: =RAND() -> 0.25749101 | E6: =C6*D6 -> 15673639
A7: DT | B7: =ROUND(C7,0) -> 1601225 | C7: =Medium_Capacity!C54*0.25 -> 1601225.5 | D7: =RAND() -> 0.51354531 | E7: =C7*D7 -> 822301.83
A8: DTwP | B8: =ROUND(C8,0) -> 15513538 | C8: =Medium_Capacity!C55*0.25 -> 15513538 | D8: =RAND() -> 0.78685416 | E8: =C8*D8 -> 12206892
A9: DTwP-Hib | B9: =ROUND(C9,0) -> 1456644 | C9: =Medium_Capacity!C56*0.25 -> 1456644.2 | D9: =RAND() -> 0.4339296 | E9: =C9*D9 -> 632081.05
A10: Penta | B10: =ROUND(C10,0) -> 63195503 | C10: =Medium_Capacity!C57*0.25 -> 63195503 | D10: =RAND() -> 0.79966541 | E10: =C10*D10 -> 50535258
A11: Hexa | B11: =ROUND(C11,0) -> 0 | C11: =Medium_Capacity!C58*0.25 -> 0 | D11: =RAND() -> 0.15012877 | E11: =C11*D11 -> 0
A12: IPV | B12: =ROUND(C12,0) -> 20944762 | C12: =Medium_Capacity!C59*0.25 -> 20944762 | D12: =RAND() -> 0.21541191 | E12: =C12*D12 -> 4511751.2
A13: OPV | B13: =ROUND(C13,0) -> 109600741 | C13: =Medium_Capacity!C60*0.25 -> 1.0960074e+08 | D13: =RAND() -> 0.23192169 | E13: =C13*D13 -> 25418789
... A18: PCV | B18: =ROUND(C18,0) -> 40200058 | C18: =Medium_Capacity!C65*0.25 -> 40200058 | D18: =RAND() -> 0.99257133 | E18: =C18*D18 -> 39901425

Sheet S_start
A1: Antigen | B1: Amount | D1: rand
A2: Measles | B2: =C2 -> 37210000 | C2: 37210000 | D2: =RAND() -> 0.4500482
A3: Mumps | B3: =C3 -> 2610000 | C3: 2610000 | D3: =RAND() -> 0.19565409
A4: Rubella | B4: =C4 -> 35730000 | C4: 35730000 | D4: =RAND() -> 0.12589448
A5: Diphtheria | B5: =C5 -> 5706000 | C5: 5706000 | D5: =RAND() -> 0.95448712
A6: Tetanus | B6: =C6 -> 5777000 | C6: 5777000 | D6: =RAND() -> 0.49764011
A7: Pertussis | B7: =C7 -> 3207000 | C7: 3207000 | D7: =RAND() -> 0.48250569
A8: Hib | B8: =C8 -> 2595000 | C8: 2595000 | D8: =RAND() -> 0.15256383
A9: Hepatitis_B | B9: =C9 -> 3123000 | C9: 3123000 | D9: =RAND() -> 0.45319376
A10: Polio | B10: =C10 -> 5222000 | C10: 5222000 | D10: =RAND() -> 0.80076191
A11: HPV | B11: =C11 -> 1900000 | C11: 1900000 | D11: =RAND() -> 0.19547376
A12: Rotavirus | B12: =C12 -> 14250000 | C12: 14250000 | D12: =RAND() -> 0.88941391
A13: PCV | B13: =C13 -> 1608000 | C13: 1608000 | D13: =RAND() -> 0.9274421

Sheet Medium_Capacity
A1: Producer | B1: 1 | C1: Percent of whole | D1: Check Sum | E1: Capacity | F1: Diffs | J1: percent share | K1: antigen demand
A2: AJ_Vaccines | B2: 12600000 | C2: =B2/$B$20 -> 0.0039562238 | D2: =SUMIFS(Q_start!E:E, Q_start!B:B, Medium_Capacity!A2) -> 0 | E2: =VLOOKUP(Medium_Capacity!A2, Medium_Capacity!A1:A18:B1:B18, 2, FALSE) -> 12600000 | F2: =E2-D2 -> 12600000 | J2: =VLOOKUP(Q_start!B2,Medium_Capacity!$B$30:$C$46,2) -> 0.30437027 | K2: =VLOOKUP(Q_start!A2,Medium_Capacity!$B$49:$C$65,2, FALSE) -> 14777182 | L2: M | M2: Serum_Institute
A3: BB_NCIPD | B3: 24300000 | C3: =B3/$B$20 -> 0.0076298601 | D3: =SUMIFS(Q_start!E:E, Q_start!B:B, Medium_Capacity!A3) -> 13305452 | E3: =VLOOKUP(Medium_Capacity!A3, Medium_Capacity!A2:A19:B2:B19, 2, FALSE) -> 24300000 | F3: =E3-D3 -> 10994548 | J3: =VLOOKUP(Q_start!B3,Medium_Capacity!$B$30:$C$46,2) -> 0.036610769 | K3: =VLOOKUP(Q_start!A3,Medium_Capacity!$B$49:$C$65,2, FALSE) -> 14777182 | L3: M | M3: PT_Bio
A4: Beijing_Institute | B4: 8000000 | C4: =B4/$B$20 -> 0.0025118881 | D4: =SUMIFS(Q_start!E:E, Q_start!B:B, Medium_Capacity!A4) -> 0 | E4: =VLOOKUP(Medium_Capacity!A4, Medium_Capacity!A3:A20:B3:B20, 2, FALSE) -> 8000000 | F4: =E4-D4 -> 8000000 | J4: =VLOOKUP(Q_start!B4,Medium_Capacity!$B$30:$C$46,2) -> 0.30437027 | K4: =VLOOKUP(Q_start!A4,Medium_Capacity!$B$49:$C$65,2, FALSE) -> 3.3127915e+08 | L4: MR | M4: Serum_Institute
A5: Bharat_Biotech | B5: 36000000 | C5: =B5/$B$20 -> 0.011303496 | D5: =SUMIFS(Q_start!E:E, Q_start!B:B, Medium_Capacity!A5) -> 0 | E5: =VLOOKUP(Medium_Capacity!A5, Medium_Capacity!A4:A21:B4:B21, 2, FALSE) -> 36000000 | F5: =E5-D5 -> 36000000 | J5: =VLOOKUP(Q_start!B5,Medium_Capacity!$B$30:$C$46,2) -> 0.050269161 | K5: =VLOOKUP(Q_start!A5,Medium_Capacity!$B$49:$C$65,2, FALSE) -> 3.3127915e+08 | L5: MR | M5: Biological_E
A6: Bilthoven | B6: 8400000 | C6: =B6/$B$20 -> 0.0026374825 | D6: =SUMIFS(Q_start!E:E, Q_start!B:B, Medium_Capacity!A6) -> 0 | E6: =VLOOKUP(Medium_Capacity!A6, Medium_Capacity!A5:A22:B5:B22, 2, FALSE) -> 8400000 | F6: =E6-D6 -> 8400000 | J6: =VLOOKUP(Q_start!B6,Medium_Capacity!$B$30:$C$46,2) -> 0.30437027 | K6: =VLOOKUP(Q_start!A6,Medium_Capacity!$B$49:$C$65,2, FALSE) -> 26052156 | L6: MMR | M6: Serum_Institute
A7: Biological_E | B7: 160100000 | C7: =B7/$B$20 -> 0.050269161 | D7: =SUMIFS(Q_start!E:E, Q_start!B:B, Medium_Capacity!A7) -> 143967364 | E7: =VLOOKUP(Medium_Capacity!A7, Medium_Capacity!A6:A23:B6:B23, 2, FALSE) -> 160100000 | F7: =E7-D7 -> 16132636 | J7: =VLOOKUP(Q_start!B7,Medium_Capacity!$B$30:$C$46,2) -> 0.51693087 | K7: =VLOOKUP(Q_start!A7,Medium_Capacity!$B$49:$C$65,2, FALSE) -> 26052156 | L7: MMR | M7: GSK
A8: Centro_de | B8: 30000 | C8: =B8/$B$20 -> 9.4195804e-06 | D8: =SUMIFS(Q_start!E:E, Q_start!B:B, Medium_Capacity!A8) -> 0 | E8: =VLOOKUP(Medium_Capacity!A8, Medium_Capacity!A7:A24:B7:B24, 2, FALSE) -> 30000 | F8: =E8-D8 -> 30000 | J8: =VLOOKUP(Q_start!B8,Medium_Capacity!$B$30:$C$46,2) -> 0.00097335664 | K8: =VLOOKUP(Q_start!A8,Medium_Capacity!$B$49:$C$65,2, FALSE) -> 26052156 | L8: MMR | M8: Merck_Sharp
A9: GSK | B9: 1646350000 | C9: =B9/$B$20 -> 0.51693087 | D9: =SUMIFS(Q_start!E:E, Q_start!B:B, Medium_Capacity!A9) -> 487344323 | E9: =VLOOKUP(Medium_Capacity!A9, Medium_Capacity!A8:A25:B8:B25, 2, FALSE) -> 1646350000 | F9: =E9-D9 -> 1159005677 | J9: =VLOOKUP(Q_start!B9,Medium_Capacity!$B$30:$C$46,2) -> 0.30437027 | K9: =VLOOKUP(Q_start!A9,Medium_Capacity!$B$49:$C$65,2, FALSE) -> 7180030.7 | L9: TT | M9: Serum_Institute
A10: Haffkine_Bio | B10: 8000000 | C10: =B10/$B$20 -> 0.0025118881 | D10: =SUMIFS(Q_start!E:E, Q_start!B:B, Medium_Capacity!A10) -> 6000000 | E10: =VLOOKUP(Medium_Capacity!A10, Medium_Capacity!A9:A26:B9:B26, 2, FALSE) -> 8000000 | F10: =E10-D10 -> 2000000 | J10: =VLOOKUP(Q_start!B10,Medium_Capacity!$B$30:$C$46,2) -> 0.036610769 | K10: =VLOOKUP(Q_start!A10,Medium_Capacity!$B$49:$C$65,2, FALSE) -> 7180030.7 | L10: TT | M10: PT_Bio
A11: LG_Chem | B11: 60600000 | C11: =B11/$B$20 -> 0.019027552 | D11: =SUMIFS(Q_start!E:E, Q_start!B:B, Medium_Capacity!A11) -> 58110013 | E11: =VLOOKUP(Medium_Capacity!A11, Medium_Capacity!A10:A27:B10:B27, 2, FALSE) -> 60600000 | F11: =E11-D11 -> 2489987 | J11: =VLOOKUP(Q_start!B11,Medium_Capacity!$B$30:$C$46,2) -> 0.0076298601 | K11: =VLOOKUP(Q_start!A11,Medium_Capacity!$B$49:$C$65,2, FALSE) -> 7180030.7 | L11: TT | M11: BB_NCIPD
A12: Merck_Sharp | B12: 3100000 | C12: =B12/$B$20 -> 0.00097335664 | D12: =SUMIFS(Q_start!E:E, Q_start!B:B, Medium_Capacity!A12) -> 2907378 | E12: =VLOOKUP(Medium_Capacity!A12, Medium_Capacity!A11:A28:B11:B28, 2, FALSE) -> 3100000 | F12: =E12-D12 -> 192622 | J12: =VLOOKUP(Q_start!B12,Medium_Capacity!$B$30:$C$46,2) -> 0.30437027 | K12: =VLOOKUP(Q_start!A12,Medium_Capacity!$B$49:$C$65,2, FALSE) -> 59502552 | L12: HepB | M12: Serum_Institute
A13: Panacea_Biotec | B13: 20500000 | C13: =B13/$B$20 -> 0.0064367133 | D13: =SUMIFS(Q_start!E:E, Q_start!B:B, Medium_Capacity!A13) -> 8948035 | E13: =VLOOKUP(Medium_Capacity!A13, Medium_Capacity!A12:A29:B12:B29, 2, FALSE) -> 20500000 | F13: =E13-D13 -> 11551965 | J13: =VLOOKUP(Q_start!B13,Medium_Capacity!$B$30:$C$46,2) -> 0.019027552 | K13: =VLOOKUP(Q_start!A13,Medium_Capacity!$B$49:$C$65,2, FALSE) -> 59502552 | L13: HepB | M13: LG_Chem
... A18: Xiamen_Innovax | B18: 500000 | C18: =B18/$B$20 -> 0.00015699301 | D18: =SUMIFS(Q_start!E:E, Q_start!B:B, Medium_Capacity!A18) -> 0 | E18: =VLOOKUP(Medium_Capacity!A18, Medium_Capacity!A17:A34:B17:B34, 2, FALSE) -> 500000 | F18: =E18-D18 -> 500000 | J18: =VLOOKUP(Q_start!B18,Medium_Capacity!$B$30:$C$46,2) -> 0.0039562238 | K18: =VLOOKUP(Q_start!A18,Medium_Capacity!$B$49:$C$65,2, FALSE) -> 83779047 | L18: IPV | M18: AJ_Vaccines
J19: =VLOOKUP(Q_start!B19,Medium_Capacity!$B$30:$C$46,2) -> 0.0026374825 | K19: =VLOOKUP(Q_start!A19,Medium_Capacity!$B$49:$C$65,2, FALSE) -> 83779047 | L19: IPV | M19: Bilthoven
B20: =SUM(B2:B18) -> 3184855250 | J20: =VLOOKUP(Q_start!B20,Medium_Capacity!$B$30:$C$46,2) -> 0.032842937 | K20: =VLOOKUP(Q_start!A20,Medium_Capacity!$B$49:$C$65,2, FALSE) -> 83779047 | L20: IPV | M20: Sanofi_Pasteur
J21: =VLOOKUP(Q_start!B21,Medium_Capacity!$B$30:$C$46,2) -> 0.30437027 | K21: =VLOOKUP(Q_start!A21,Medium_Capacity!$B$49:$C$65,2, FALSE) -> 4.3840296e+08 | L21: OPV | M21: Serum_Institute
J22: =VLOOKUP(Q_start!B22,Medium_Capacity!$B$30:$C$46,2) -> 0.036610769 | K22: =VLOOKUP(Q_start!A22,Medium_Capacity!$B$49:$C$65,2, FALSE) -> 4.3840296e+08 | L22: OPV | M22: PT_Bio
J23: =VLOOKUP(Q_start!B23,Medium_Capacity!$B$30:$C$46,2) -> 0.51693087 | K23: =VLOOKUP(Q_start!A23,Medium_Capacity!$B$49:$C$65,2, FALSE) -> 4.3840296e+08 | L23: OPV | M23: GSK
J24: =VLOOKUP(Q_start!B24,Medium_Capacity!$B$30:$C$46,2) -> 0.032842937 | K24: =VLOOKUP(Q_start!A24,Medium_Capacity!$B$49:$C$65,2, FALSE) -> 4.3840296e+08 | L24: OPV | M24: Sanofi_Pasteur
J25: =VLOOKUP(Q_start!B25,Medium_Capacity!$B$30:$C$46,2) -> 0.0064367133 | K25: =VLOOKUP(Q_start!A25,Medium_Capacity!$B$49:$C$65,2, FALSE) -> 4.3840296e+08 | L25: OPV | M25: Panacea_Biotec
J26: =VLOOKUP(Q_start!B26,Medium_Capacity!$B$30:$C$46,2) -> 0.0025118881 | K26: =VLOOKUP(Q_start!A26,Medium_Capacity!$B$49:$C$65,2, FALSE) -> 4.3840296e+08 | L26: OPV | M26: Beijing_Institute
J27: =VLOOKUP(Q_start!B27,Medium_Capacity!$B$30:$C$46,2) -> 0.011303496 | K27: =VLOOKUP(Q_start!A27,Medium_Capacity!$B$49:$C$65,2, FALSE) -> 4.3840296e+08 | L27: OPV | M27: Bharat_Biotech
J28: =VLOOKUP(Q_start!B28,Medium_Capacity!$B$30:$C$46,2) -> 0.0025118881 | K28: =VLOOKUP(Q_start!A28,Medium_Capacity!$B$49:$C$65,2, FALSE) -> 4.3840296e+08 | L28: OPV | M28: Haffkine_Bio
J29: =VLOOKUP(Q_start!B29,Medium_Capacity!$B$30:$C$46,2) -> 0.30437027 | K29: =VLOOKUP(Q_start!A29,Medium_Capacity!$B$49:$C$65,2, FALSE) -> 6404902 | L29: DT | M29: Serum_Institute
B30: AJ_Vaccines | C30: 0.0039562238 | J30: =VLOOKUP(Q_start!B30,Medium_Capacity!$B$30:$C$46,2) -> 0.036610769 | K30: =VLOOKUP(Q_start!A30,Medium_Capacity!$B$49:$C$65,2, FALSE) -> 6404902 | L30: DT | M30: PT_Bio
B31: BB_NCIPD | C31: 0.0076298601 | J31: =VLOOKUP(Q_start!B31,Medium_Capacity!$B$30:$C$46,2) -> 0.0076298601 | K31: =VLOOKUP(Q_start!A31,Medium_Capacity!$B$49:$C$65,2, FALSE) -> 6404902 | L31: DT | M31: BB_NCIPD
B32: Beijing_Institute | C32: 0.0025118881 | J32: =VLOOKUP(Q_start!B32,Medium_Capacity!$B$30:$C$46,2) -> 0.30437027 | K32: =VLOOKUP(Q_start!A32,Medium_Capacity!$B$49:$C$65,2, FALSE) -> 2.4348251e+08 | L32: Td | M32: Serum_Institute
B33: Bharat_Biotech | C33: 0.011303496 | J33: =VLOOKUP(Q_start!B33,Medium_Capacity!$B$30:$C$46,2) -> 0.036610769 | K33: =VLOOKUP(Q_start!A33,Medium_Capacity!$B$49:$C$65,2, FALSE) -> 2.4348251e+08 | L33: Td | M33: PT_Bio
B34: Bilthoven | C34: 0.0026374825 | J34: =VLOOKUP(Q_start!B34,Medium_Capacity!$B$30:$C$46,2) -> 0.0076298601 | K34: =VLOOKUP(Q_start!A34,Medium_Capacity!$B$49:$C$65,2, FALSE) -> 2.4348251e+08 | L34: Td | M34: BB_NCIPD
B35: Biological_E | C35: 0.050269161 | J35: =VLOOKUP(Q_start!B35,Medium_Capacity!$B$30:$C$46,2) -> 0.30437027 | K35: =VLOOKUP(Q_start!A35,Medium_Capacity!$B$49:$C$65,2, FALSE) -> 62054152 | L35: DTwP | M35: Serum_Institute
B36: Centro_de | C36: 9.4195804e-06 | J36: =VLOOKUP(Q_start!B36,Medium_Capacity!$B$30:$C$46,2) -> 0.050269161 | K36: =VLOOKUP(Q_start!A36,Medium_Capacity!$B$49:$C$65,2, FALSE) -> 62054152 | L36: DTwP | M36: Biological_E
B37: GSK | C37: 0.51693087 | J37: =VLOOKUP(Q_start!B37,Medium_Capacity!$B$30:$C$46,2) -> 0.30437027 | K37: =VLOOKUP(Q_start!A37,Medium_Capacity!$B$49:$C$65,2, FALSE) -> 5826576.9 | L37: DTwP-Hib | M37: Serum_Institute
B38: Haffkine_Bio | C38: 0.0025118881 | J38: =VLOOKUP(Q_start!B38,Medium_Capacity!$B$30:$C$46,2) -> 0.30437027 | K38: =VLOOKUP(Q_start!A38,Medium_Capacity!$B$49:$C$65,2, FALSE) -> 2.5278201e+08 | L38: Penta | M38: Serum_Institute
B39: LG_Chem | C39: 0.019027552 | J39: =VLOOKUP(Q_start!B39,Medium_Capacity!$B$30:$C$46,2) -> 0.036610769 | K39: =VLOOKUP(Q_start!A39,Medium_Capacity!$B$49:$C$65,2, FALSE) -> 2.5278201e+08 | L39: Penta | M39: PT_Bio
B40: Merck_Sharp | C40: 0.00097335664 | J40: =VLOOKUP(Q_start!B40,Medium_Capacity!$B$30:$C$46,2) -> 0.050269161 | K40: =VLOOKUP(Q_start!A40,Medium_Capacity!$B$49:$C$65,2, FALSE) -> 2.5278201e+08 | L40: Penta | M40: Biological_E
B41: Panacea_Biotec | C41: 0.0064367133 | J41: =VLOOKUP(Q_start!B41,Medium_Capacity!$B$30:$C$46,2) -> 0.019027552 | K41: =VLOOKUP(Q_start!A41,Medium_Capacity!$B$49:$C$65,2, FALSE) -> 2.5278201e+08 | L41: Penta | M41: LG_Chem
... B46: Xiamen_Innovax | C46: 0.00015699301 | J46: =VLOOKUP(Q_start!B46,Medium_Capacity!$B$30:$C$46,2) -> 0.00015699301 | K46: =VLOOKUP(Q_start!A46,Medium_Capacity!$B$49:$C$65,2, FALSE) -> 18988210 | L46: HPV | M46: Xiamen_Innovax
J47: =VLOOKUP(Q_start!B47,Medium_Capacity!$B$30:$C$46,2) -> 0.30437027 | K47: =VLOOKUP(Q_start!A47,Medium_Capacity!$B$49:$C$65,2, FALSE) -> 1.42479e+08 | L47: Rotavirus | M47: Serum_Institute
J48: =VLOOKUP(Q_start!B48,Medium_Capacity!$B$30:$C$46,2) -> 0.51693087 | K48: =VLOOKUP(Q_start!A48,Medium_Capacity!$B$49:$C$65,2, FALSE) -> 1.42479e+08 | L48: Rotavirus | M48: GSK
...
