Workbook
Name GAVI_countries: #REF!

Sheet F_start
A1: Antigen | B1: Starting | C1: Ending
A2: Measles | B2: 1 | C2: 2
A3: Mumps | B3: 1 | C3: 2
A4: Rubella | B4: 1 | C4: 2
A5: Diphtheria | B5: 1 | C5: 2
A6: Tetanus | B6: 1 | C6: 2
A7: Pertussis | B7: 1 | C7: 2
A8: Hib | B8: 1 | C8: 2
A9: Hepatitis_B | B9: 1 | C9: 2
A10: Polio | B10: 1 | C10: 2
A11: HPV | B11: 1 | C11: 2
A12: Rotavirus | B12: 1 | C12: 2
A13: PCV | B13: 1 | C13: 2

Sheet Q_start
A1: Vaccine | B1: Producer | C1: Start | D1: End | E1: Amount
A2: M | B2: Serum_Institute | C2: 1 | D2: 2 | E2: =F2*2 -> 8995469.9 | F2: =Medium_Capacity!J2*Medium_Capacity!K2 -> 4497734.9 | G2: =RAND() -> 0.011167795
A3: M | B3: PT_Bio | C3: 1 | D3: 2 | E3: =F3*2 -> 1082008 | F3: =Medium_Capacity!J3*Medium_Capacity!K3 -> 541004.01 | G3: =RAND() -> 0.2437239
A4: MR | B4: Serum_Institute | C4: 1 | D4: 2 | E4: =F4*2 -> 2.0166305e+08 | F4: =Medium_Capacity!J4*Medium_Capacity!K4 -> 1.0083152e+08 | G4: =RAND() -> 0.16102113
A5: MR | B5: Biological_E | C5: 1 | D5: 2 | E5: =F5*2 -> 33306250 | F5: =Medium_Capacity!J5*Medium_Capacity!K5 -> 16653125 | G5: =RAND() -> 0.38850828
A6: MMR | B6: Serum_Institute | C6: 1 | D6: 2 | E6: =F6*2 -> 15859003 | F6: =Medium_Capacity!J6*Medium_Capacity!K6 -> 7929501.7 | G6: =RAND() -> 0.021628096
A7: MMR | B7: GSK | C7: 1 | D7: 2 | E7: =F7*2 -> 26934327 | F7: =Medium_Capacity!J7*Medium_Capacity!K7 -> 13467164 | G7: =RAND() -> 0.47083813
A8: MMR | B8: Merck_Sharp | C8: 1 | D8: 2 | E8: =F8*2 -> 50716.078 | F8: =Medium_Capacity!J8*Medium_Capacity!K8 -> 25358.039 | G8: =RAND() -> 0.8421291
A9: TT | B9: Serum_Institute | C9: 1 | D9: 2 | E9: =F9*2 -> 4370775.8 | F9: =Medium_Capacity!J9*Medium_Capacity!K9 -> 2185387.9 | G9: =RAND() -> 0.45845727
A10: TT | B10: PT_Bio | C10: 1 | D10: 2 | E10: =F10*2 -> 525732.9 | F10: =Medium_Capacity!J10*Medium_Capacity!K10 -> 262866.45 | G10: =RAND() -> 0.74861865
A11: TT | B11: BB_NCIPD | C11: 1 | D11: 2 | E11: =F11*2 -> 109565.26 | F11: =Medium_Capacity!J11*Medium_Capacity!K11 -> 54782.63 | G11: =RAND() -> 0.42714055
A12: HepB | B12: Serum_Institute | C12: 1 | D12: 2 | E12: =F12*2 -> 36221616 | F12: =Medium_Capacity!J12*Medium_Capacity!K12 -> 18110808 | G12: =RAND() -> 0.87703552
A13: HepB | B13: LG_Chem | C13: 1 | D13: 2 | E13: =F13*2 -> 2264375.9 | F13: =Medium_Capacity!J13*Medium_Capacity!K13 -> 1132187.9 | G13: =RAND() -> 0.73617469
... A52: PCV | B52: Pfizer | C52: 1 | D52: 2 | E52: =F52*2 -> 585672.68 | F52: =Medium_Capacity!J52*Medium_Capacity!K52 -> 292836.34 | G52: =RAND() -> 0.793283

Sheet I_start
A1: Vaccine | B1: Amount
A2: M | B2: =C2 -> 3694295.6 | C2: =Medium_Capacity!C49*0.25 -> 3694295.6
A3: MR | B3: =C3 -> 82819787 | C3: =Medium_Capacity!C50*0.25 -> 82819787
A4: MMR | B4: =C4 -> 6513039 | C4: =Medium_Capacity!C51*0.25 -> 6513039
A5: TT | B5: =C5 -> 1795007.7 | C5: =Medium_Capacity!C52*0.25 -> 1795007.7
A6: Td | B6: =C6 -> 60870627 | C6: =Medium_Capacity!C53*0.25 -> 60870627
A7: DT | B7: =C7 -> 1601225.5 | C7: =Medium_Capacity!C54*0.25 -> 1601225.5
A8: DTwP | B8: =C8 -> 15513538 | C8: =Medium_Capacity!C55*0.25 -> 15513538
A9: DTwP-Hib | B9: =C9 -> 1456644.2 | C9: =Medium_Capacity!C56*0.25 -> 1456644.2
A10: Penta | B10: =C10 -> 63195503 | C10: =Medium_Capacity!C57*0.25 -> 63195503
A11: Hexa | B11: =C11 -> 0 | C11: =Medium_Capacity!C58*0.25 -> 0
A12: IPV | B12: =C12 -> 20944762 | C12: =Medium_Capacity!C59*0.25 -> 20944762
A13: OPV | B13: =C13 -> 1.0960074e+08 | C13: =Medium_Capacity!C60*0.25 -> 1.0960074e+08
... A18: PCV | B18: =C18 -> 40200058 | C18: =Medium_Capacity!C65*0.25 -> 40200058

Sheet S_start
A1: Antigen | B1: Amount
A2: Measles | B2: =C2 -> 37210000 | C2: 37210000
A3: Mumps | B3: =C3 -> 2610000 | C3: 2610000
A4: Rubella | B4: =C4 -> 35730000 | C4: 35730000
A5: Diphtheria | B5: =C5 -> 5706000 | C5: 5706000
A6: Tetanus | B6: =C6 -> 5777000 | C6: 5777000
A7: Pertussis | B7: =C7 -> 3207000 | C7: 3207000
A8: Hib | B8: =C8 -> 2595000 | C8: 2595000
A9: Hepatitis_B | B9: =C9 -> 3123000 | C9: 3123000
A10: Polio | B10: =C10 -> 5222000 | C10: 5222000
A11: HPV | B11: =C11 -> 1900000 | C11: 1900000
A12: Rotavirus | B12: =C12 -> 14250000 | C12: 14250000
A13: PCV | B13: =C13 -> 1608000 | C13: 1608000

Sheet Medium_Capacity
A1: Producer | B1: 1 | C1: Percent of whole | D1: Check Sum | E1: Capacity | F1: Diffs | J1: percent share | K1: antigen demand
A2: AJ_Vaccines | B2: 25200000 | C2: =B2/$B$20 -> 0.0039562238 | D2: =SUMIFS(Q_start!E:E, Q_start!B:B, Medium_Capacity!A2) -> 662897.31 | E2: =VLOOKUP(Medium_Capacity!A2, Medium_Capacity!A1:A18:B1:B18, 2, FALSE) -> 25200000 | F2: =E2-D2 -> 24537103 | J2: =VLOOKUP(Q_start!B2,Medium_Capacity!$B$30:$C$46,2) -> 0.30437027 | K2: =VLOOKUP(Q_start!A2,Medium_Capacity!$B$49:$C$65,2, FALSE) -> 14777182
A3: BB_NCIPD | B3: 48600000 | C3: =B3/$B$20 -> 0.0076298601 | D3: =SUMIFS(Q_start!E:E, Q_start!B:B, Medium_Capacity!A3) -> 3922777.2 | E3: =VLOOKUP(Medium_Capacity!A3, Medium_Capacity!A2:A19:B2:B19, 2, FALSE) -> 48600000 | F3: =E3-D3 -> 44677223 | J3: =VLOOKUP(Q_start!B3,Medium_Capacity!$B$30:$C$46,2) -> 0.036610769 | K3: =VLOOKUP(Q_start!A3,Medium_Capacity!$B$49:$C$65,2, FALSE) -> 14777182
A4: Beijing_Institute | B4: 16000000 | C4: =B4/$B$20 -> 0.0025118881 | D4: =SUMIFS(Q_start!E:E, Q_start!B:B, Medium_Capacity!A4) -> 2202438.4 | E4: =VLOOKUP(Medium_Capacity!A4, Medium_Capacity!A3:A20:B3:B20, 2, FALSE) -> 16000000 | F4: =E4-D4 -> 13797562 | J4: =VLOOKUP(Q_start!B4,Medium_Capacity!$B$30:$C$46,2) -> 0.30437027 | K4: =VLOOKUP(Q_start!A4,Medium_Capacity!$B$49:$C$65,2, FALSE) -> 3.3127915e+08
A5: Bharat_Biotech | B5: 72000000 | C5: =B5/$B$20 -> 0.011303496 | D5: =SUMIFS(Q_start!E:E, Q_start!B:B, Medium_Capacity!A5) -> 13131994 | E5: =VLOOKUP(Medium_Capacity!A5, Medium_Capacity!A4:A21:B4:B21, 2, FALSE) -> 72000000 | F5: =E5-D5 -> 58868006 | J5: =VLOOKUP(Q_start!B5,Medium_Capacity!$B$30:$C$46,2) -> 0.050269161 | K5: =VLOOKUP(Q_start!A5,Medium_Capacity!$B$49:$C$65,2, FALSE) -> 3.3127915e+08
A6: Bilthoven | B6: 16800000 | C6: =B6/$B$20 -> 0.0026374825 | D6: =SUMIFS(Q_start!E:E, Q_start!B:B, Medium_Capacity!A6) -> 441931.54 | E6: =VLOOKUP(Medium_Capacity!A6, Medium_Capacity!A5:A22:B5:B22, 2, FALSE) -> 16800000 | F6: =E6-D6 -> 16358068 | J6: =VLOOKUP(Q_start!B6,Medium_Capacity!$B$30:$C$46,2) -> 0.30437027 | K6: =VLOOKUP(Q_start!A6,Medium_Capacity!$B$49:$C$65,2, FALSE) -> 26052156
A7: Biological_E | B7: 320200000 | C7: =B7/$B$20 -> 0.050269161 | D7: =SUMIFS(Q_start!E:E, Q_start!B:B, Medium_Capacity!A7) -> 64959349 | E7: =VLOOKUP(Medium_Capacity!A7, Medium_Capacity!A6:A23:B6:B23, 2, FALSE) -> 320200000 | F7: =E7-D7 -> 2.5524065e+08 | J7: =VLOOKUP(Q_start!B7,Medium_Capacity!$B$30:$C$46,2) -> 0.51693087 | K7: =VLOOKUP(Q_start!A7,Medium_Capacity!$B$49:$C$65,2, FALSE) -> 26052156
A8: Centro_de | B8: 60000 | C8: =B8/$B$20 -> 9.4195804e-06 | D8: =SUMIFS(Q_start!E:E, Q_start!B:B, Medium_Capacity!A8) -> 17.475918 | E8: =VLOOKUP(Medium_Capacity!A8, Medium_Capacity!A7:A24:B7:B24, 2, FALSE) -> 60000 | F8: =E8-D8 -> 59982.524 | J8: =VLOOKUP(Q_start!B8,Medium_Capacity!$B$30:$C$46,2) -> 0.00097335664 | K8: =VLOOKUP(Q_start!A8,Medium_Capacity!$B$49:$C$65,2, FALSE) -> 26052156
A9: GSK | B9: 3292700000 | C9: =B9/$B$20 -> 0.51693087 | D9: =SUMIFS(Q_start!E:E, Q_start!B:B, Medium_Capacity!A9) -> 8.1336236e+08 | E9: =VLOOKUP(Medium_Capacity!A9, Medium_Capacity!A8:A25:B8:B25, 2, FALSE) -> 3292700000 | F9: =E9-D9 -> 2.4793376e+09 | J9: =VLOOKUP(Q_start!B9,Medium_Capacity!$B$30:$C$46,2) -> 0.30437027 | K9: =VLOOKUP(Q_start!A9,Medium_Capacity!$B$49:$C$65,2, FALSE) -> 7180030.7
A10: Haffkine_Bio | B10: 16000000 | C10: =B10/$B$20 -> 0.0025118881 | D10: =SUMIFS(Q_start!E:E, Q_start!B:B, Medium_Capacity!A10) -> 2202438.4 | E10: =VLOOKUP(Medium_Capacity!A10, Medium_Capacity!A9:A26:B9:B26, 2, FALSE) -> 16000000 | F10: =E10-D10 -> 13797562 | J10: =VLOOKUP(Q_start!B10,Medium_Capacity!$B$30:$C$46,2) -> 0.036610769 | K10: =VLOOKUP(Q_start!A10,Medium_Capacity!$B$49:$C$65,2, FALSE) -> 7180030.7
A11: LG_Chem | B11: 121200000 | C11: =B11/$B$20 -> 0.019027552 | D11: =SUMIFS(Q_start!E:E, Q_start!B:B, Medium_Capacity!A11) -> 15072242 | E11: =VLOOKUP(Medium_Capacity!A11, Medium_Capacity!A10:A27:B10:B27, 2, FALSE) -> 121200000 | F11: =E11-D11 -> 1.0612776e+08 | J11: =VLOOKUP(Q_start!B11,Medium_Capacity!$B$30:$C$46,2) -> 0.0076298601 | K11: =VLOOKUP(Q_start!A11,Medium_Capacity!$B$49:$C$65,2, FALSE) -> 7180030.7
A12: Merck_Sharp | B12: 6200000 | C12: =B12/$B$20 -> 0.00097335664 | D12: =SUMIFS(Q_start!E:E, Q_start!B:B, Medium_Capacity!A12) -> 87680.678 | E12: =VLOOKUP(Medium_Capacity!A12, Medium_Capacity!A11:A28:B11:B28, 2, FALSE) -> 6200000 | F12: =E12-D12 -> 6112319.3 | J12: =VLOOKUP(Q_start!B12,Medium_Capacity!$B$30:$C$46,2) -> 0.30437027 | K12: =VLOOKUP(Q_start!A12,Medium_Capacity!$B$49:$C$65,2, FALSE) -> 59502552
A13: Panacea_Biotec | B13: 41000000 | C13: =B13/$B$20 -> 0.0064367133 | D13: =SUMIFS(Q_start!E:E, Q_start!B:B, Medium_Capacity!A13) -> 8897919 | E13: =VLOOKUP(Medium_Capacity!A13, Medium_Capacity!A12:A29:B12:B29, 2, FALSE) -> 41000000 | F13: =E13-D13 -> 32102081 | J13: =VLOOKUP(Q_start!B13,Medium_Capacity!$B$30:$C$46,2) -> 0.019027552 | K13: =VLOOKUP(Q_start!A13,Medium_Capacity!$B$49:$C$65,2, FALSE) -> 59502552
... A18: Xiamen_Innovax | B18: 1000000 | C18: =B18/$B$20 -> 0.00015699301 | D18: =SUMIFS(Q_start!E:E, Q_start!B:B, Medium_Capacity!A18) -> 5962.0323 | E18: =VLOOKUP(Medium_Capacity!A18, Medium_Capacity!A17:A34:B17:B34, 2, FALSE) -> 1000000 | F18: =E18-D18 -> 994037.97 | J18: =VLOOKUP(Q_start!B18,Medium_Capacity!$B$30:$C$46,2) -> 0.0039562238 | K18: =VLOOKUP(Q_start!A18,Medium_Capacity!$B$49:$C$65,2, FALSE) -> 83779047
J19: =VLOOKUP(Q_start!B19,Medium_Capacity!$B$30:$C$46,2) -> 0.0026374825 | K19: =VLOOKUP(Q_start!A19,Medium_Capacity!$B$49:$C$65,2, FALSE) -> 83779047
B20: =SUM(B2:B18) -> 6369710500 | J20: =VLOOKUP(Q_start!B20,Medium_Capacity!$B$30:$C$46,2) -> 0.032842937 | K20: =VLOOKUP(Q_start!A20,Medium_Capacity!$B$49:$C$65,2, FALSE) -> 83779047
J21: =VLOOKUP(Q_start!B21,Medium_Capacity!$B$30:$C$46,2) -> 0.30437027 | K21: =VLOOKUP(Q_start!A21,Medium_Capacity!$B$49:$C$65,2, FALSE) -> 4.3840296e+08
J22: =VLOOKUP(Q_start!B22,Medium_Capacity!$B$30:$C$46,2) -> 0.036610769 | K22: =VLOOKUP(Q_start!A22,Medium_Capacity!$B$49:$C$65,2, FALSE) -> 4.3840296e+08
J23: =VLOOKUP(Q_start!B23,Medium_Capacity!$B$30:$C$46,2) -> 0.51693087 | K23: =VLOOKUP(Q_start!A23,Medium_Capacity!$B$49:$C$65,2, FALSE) -> 4.3840296e+08
J24: =VLOOKUP(Q_start!B24,Medium_Capacity!$B$30:$C$46,2) -> 0.032842937 | K24: =VLOOKUP(Q_start!A24,Medium_Capacity!$B$49:$C$65,2, FALSE) -> 4.3840296e+08
J25: =VLOOKUP(Q_start!B25,Medium_Capacity!$B$30:$C$46,2) -> 0.0064367133 | K25: =VLOOKUP(Q_start!A25,Medium_Capacity!$B$49:$C$65,2, FALSE) -> 4.3840296e+08
J26: =VLOOKUP(Q_start!B26,Medium_Capacity!$B$30:$C$46,2) -> 0.0025118881 | K26: =VLOOKUP(Q_start!A26,Medium_Capacity!$B$49:$C$65,2, FALSE) -> 4.3840296e+08
J27: =VLOOKUP(Q_start!B27,Medium_Capacity!$B$30:$C$46,2) -> 0.011303496 | K27: =VLOOKUP(Q_start!A27,Medium_Capacity!$B$49:$C$65,2, FALSE) -> 4.3840296e+08
J28: =VLOOKUP(Q_start!B28,Medium_Capacity!$B$30:$C$46,2) -> 0.0025118881 | K28: =VLOOKUP(Q_start!A28,Medium_Capacity!$B$49:$C$65,2, FALSE) -> 4.3840296e+08
J29: =VLOOKUP(Q_start!B29,Medium_Capacity!$B$30:$C$46,2) -> 0.30437027 | K29: =VLOOKUP(Q_start!A29,Medium_Capacity!$B$49:$C$65,2, FALSE) -> 6404902
B30: AJ_Vaccines | C30: 0.0039562238 | J30: =VLOOKUP(Q_start!B30,Medium_Capacity!$B$30:$C$46,2) -> 0.036610769 | K30: =VLOOKUP(Q_start!A30,Medium_Capacity!$B$49:$C$65,2, FALSE) -> 6404902
B31: BB_NCIPD | C31: 0.0076298601 | J31: =VLOOKUP(Q_start!B31,Medium_Capacity!$B$30:$C$46,2) -> 0.0076298601 | K31: =VLOOKUP(Q_start!A31,Medium_Capacity!$B$49:$C$65,2, FALSE) -> 6404902
B32: Beijing_Institute | C32: 0.0025118881 | J32: =VLOOKUP(Q_start!B32,Medium_Capacity!$B$30:$C$46,2) -> 0.30437027 | K32: =VLOOKUP(Q_start!A32,Medium_Capacity!$B$49:$C$65,2, FALSE) -> 2.4348251e+08
B33: Bharat_Biotech | C33: 0.011303496 | J33: =VLOOKUP(Q_start!B33,Medium_Capacity!$B$30:$C$46,2) -> 0.036610769 | K33: =VLOOKUP(Q_start!A33,Medium_Capacity!$B$49:$C$65,2, FALSE) -> 2.4348251e+08
B34: Bilthoven | C34: 0.0026374825 | J34: =VLOOKUP(Q_start!B34,Medium_Capacity!$B$30:$C$46,2) -> 0.0076298601 | K34: =VLOOKUP(Q_start!A34,Medium_Capacity!$B$49:$C$65,2, FALSE) -> 2.4348251e+08
B35: Biological_E | C35: 0.050269161 | J35: =VLOOKUP(Q_start!B35,Medium_Capacity!$B$30:$C$46,2) -> 0.30437027 | K35: =VLOOKUP(Q_start!A35,Medium_Capacity!$B$49:$C$65,2, FALSE) -> 62054152
B36: Centro_de | C36: 9.4195804e-06 | J36: =VLOOKUP(Q_start!B36,Medium_Capacity!$B$30:$C$46,2) -> 0.050269161 | K36: =VLOOKUP(Q_start!A36,Medium_Capacity!$B$49:$C$65,2, FALSE) -> 62054152
B37: GSK | C37: 0.51693087 | J37: =VLOOKUP(Q_start!B37,Medium_Capacity!$B$30:$C$46,2) -> 0.30437027 | K37: =VLOOKUP(Q_start!A37,Medium_Capacity!$B$49:$C$65,2, FALSE) -> 5826576.9
B38: Haffkine_Bio | C38: 0.0025118881 | J38: =VLOOKUP(Q_start!B38,Medium_Capacity!$B$30:$C$46,2) -> 0.30437027 | K38: =VLOOKUP(Q_start!A38,Medium_Capacity!$B$49:$C$65,2, FALSE) -> 2.5278201e+08
B39: LG_Chem | C39: 0.019027552 | J39: =VLOOKUP(Q_start!B39,Medium_Capacity!$B$30:$C$46,2) -> 0.036610769 | K39: =VLOOKUP(Q_start!A39,Medium_Capacity!$B$49:$C$65,2, FALSE) -> 2.5278201e+08
B40: Merck_Sharp | C40: 0.00097335664 | J40: =VLOOKUP(Q_start!B40,Medium_Capacity!$B$30:$C$46,2) -> 0.050269161 | K40: =VLOOKUP(Q_start!A40,Medium_Capacity!$B$49:$C$65,2, FALSE) -> 2.5278201e+08
B41: Panacea_Biotec | C41: 0.0064367133 | J41: =VLOOKUP(Q_start!B41,Medium_Capacity!$B$30:$C$46,2) -> 0.019027552 | K41: =VLOOKUP(Q_start!A41,Medium_Capacity!$B$49:$C$65,2, FALSE) -> 2.5278201e+08
... B46: Xiamen_Innovax | C46: 0.00015699301 | J46: =VLOOKUP(Q_start!B46,Medium_Capacity!$B$30:$C$46,2) -> 0.00015699301 | K46: =VLOOKUP(Q_start!A46,Medium_Capacity!$B$49:$C$65,2, FALSE) -> 18988210
J47: =VLOOKUP(Q_start!B47,Medium_Capacity!$B$30:$C$46,2) -> 0.30437027 | K47: =VLOOKUP(Q_start!A47,Medium_Capacity!$B$49:$C$65,2, FALSE) -> 1.42479e+08
J48: =VLOOKUP(Q_start!B48,Medium_Capacity!$B$30:$C$46,2) -> 0.51693087 | K48: =VLOOKUP(Q_start!A48,Medium_Capacity!$B$49:$C$65,2, FALSE) -> 1.42479e+08
...
