Workbook
Name GAVI_countries: #REF!
Name GAVI_countries: #REF!
Name GAVI_countries: #REF!
Name GAVI_countries: #REF!
Name GAVI_countries: #REF!
Name GAVI_countries: #REF!

Sheet vaccine-producer list
A1: Vaccine | B1: Serum Institute of India Pvt. Ltd. | C1: PT Bio Farma (Persero) | D1: GlaxoSmithKline Biologicals SA | E1: Biological E. Limited | F1: Merck Sharp & Dohme LLC | G1: Sanofi Pasteur | H1: BB- NCIPD Ltd. (Bulgaria) | I1: LG Chem Ltd | J1: Panacea Biotec Ltd. | K1: AJ Vaccines A/S | L1: Bilthoven Biologicals B.V. | M1: Sanofi Healthcare India Private Limited | N1: Beijing Institute of Biological Products Co., Ltd. | O1: Bharat Biotech International Limited | P1: Haffkine Bio Pharmaceutical Corporation Ltd | Q1: Xiamen Innovax Biotech Co. Ltd. | R1: Centro de Ingenieria Genetica y Biotecnologia | S1: Pfizer
A2: Measles | B2: 1 | C2: 1
A3: Measles and Rubella | B3: 1 | E3: 1
A4: Measles, Mumps and Rubella | B4: 1 | D4: 1
A5: Tetanus Toxoid | B5: 1 | C5: 1 | H5: 1
A6: Haemophilus influenzae type b | B6: 1 | G6: 1 | R6: 1
A7: Polio Vaccine - Inactivated (IPV) | I7: 1 | K7: 1 | L7: 1 | M7: 1
A8: Polio Vaccine - Oral (OPV) Bivalent Types 1 and 3 | B8: 1 | C8: 1 | D8: 1 | G8: 1 | J8: 1 | N8: 1 | O8: 1 | P8: 1
A9: Hepatitis B (Pediatric or non-adult specific) | B9: 1 | I9: 1
A10: Tetanus-Diphtheria (Td) | B10: 1 | C10: 1 | H10: 1
A11: Diphtheria-Tetanus (DT) | B11: 1 | C11: 1 | H11: 1
A12: Diphtheria-Tetanus (reduced antigen content) | B12: 1 | C12: 1 | E12: 1 | G12: 1 | H12: 1
A13: Diphtheria-Tetanus-Pertussis (acellular) + (whole cell) | B13: 1 | E13: 1
A14: Diphtheria-Tetanus-Pertussis (whole cell)-Haemophilus influenzae type b | B14: 1
A15: Diphtheria-Tetanus-Pertussis (whole cell)-Hepatitis B-Haemophilus influenzae type b | B15: 1 | C15: 1 | E15: 1 | I15: 1 | J15: 1
A16: Diphtheria-Tetanus-Pertussis (acellular)-Hepatitis B-Haemophilus influenzae type b-Polio (Inactivated) | G16: 1
A17: Human Papillomavirus (Bivalent) + (Quadrivalent) | D17: 1 | F17: 1 | Q17: 1
A18: Rotavirus | B18: 1 | D18: 1 | O18: 1
A19: Pneumococcal Conjugate vaccine | B19: 1 | D19: 1 | S19: 1

Sheet vaccine-antigen list
A1: Vaccine | B1: Measles | C1: Mumps | D1: Rubella | E1: HPV | F1: Polio | G1: Diptheria | H1: Tetanus | I1: Pertussus | J1: Hib | K1: HepB | L1: Rotavirus | M1: PCV
A2: Measles | B2: 1
A3: Measles and Rubella | B3: 1 | D3: 1
A4: Measles, Mumps and Rubella | B4: 1 | C4: 1 | D4: 1
A5: Tetanus Toxoid | H5: 1
A6: Tetanus-Diphtheria | G6: 1 | H6: 1
A7: Diphtheria-Tetanus | G7: 1 | H7: 1
A8: Diphtheria-Tetanus (reduced antigen content) | G8: 1 | H8: 1
A9: Diphtheria-Tetanus-Pertussis (acellular) + (whole cell) | G9: 1 | H9: 1 | I9: 1
A10: Diphtheria-Tetanus-Pertussis (whole cell)-Haemophilus influenzae type b | G10: 1 | H10: 1 | I10: 1 | J10: 1
A11: Diphtheria-Tetanus-Pertussis (whole cell)-Hepatitis B-Haemophilus influenzae type b | G11: 1 | H11: 1 | I11: 1 | J11: 1 | K11: 1
A12: Diphtheria-Tetanus-Pertussis (acellular)-Hepatitis B-Haemophilus influenzae type b-Polio (Inactivated) | F12: 1 | G12: 1 | H12: 1 | I12: 1 | J12: 1 | K12: 1
A13: Polio Vaccine - Inactivated (IPV) | F13: 1
A14: Polio Vaccine - Oral (OPV) Bivalent Types 1 and 3 | F14: 1
A15: Human Papillomavirus (Bivalent) (Quadrivalent) | E15: 1
A16: Hepatitis B (Pediatric or non-adult specific) | K16: 1
A17: Haemophilus influenzae type b | J17: 1
A18: Rotavirus | L18: 1
A19: Pneumococcal Conjugate vaccine | M19: 1

Sheet total_capacity_calcs
B1: Vaccine | C1: wb_status | D1: 2000 | E1: 2001 | F1: 2002 | G1: 2003 | H1: 2004 | I1: 2005 | J1: 2006 | K1: 2007 | L1: 2008 | M1: 2009 | N1: 2010 | O1: 2011 | P1: 2012 | Q1: 2013 | R1: 2014 | S1: 2015 | T1: 2016 | U1: 2017 | V1: 2018 | W1: 2019 | X1: 2020 | Y1: 2021 | Z1: 2022 | AA1: 2023 | AB1: 2024 | AC1: 2025 | AD1: 2026 | AE1: 2027 | AF1: 2028 | AG1: 2029 | AH1: 2030
B2: BCG | C2: -- | D2: 1042187.6 | E2: 1098514.4 | F2: 1139316.4 | G2: 1056462.3 | H2: 1051701.1 | I2: 1036770.5 | J2: 1028029.1 | K2: 1034736.5 | L2: 829922.19 | M2: 867969.62 | N2: 906053.75 | O2: 953703.5 | P2: 862649.67
B3: BCG | C3: High Income | D3: 2545256.6 | E3: 2559662.2 | F3: 2567818.1 | G3: 3399581.7 | H3: 3266002 | I3: 3223511.3 | J3: 3997948.8 | K3: 4078264.1 | L3: 4184322.8 | M3: 4886389.4 | N3: 5108451.9 | O3: 5663738.8 | P3: 5593898.1 | Q3: 5597533.3 | R3: 18987275 | S3: 15562187 | T3: 18480295 | U3: 5499455.8 | V3: 5364867.6 | W3: 6118707.9 | X3: 5286760.6 | Y3: 5785197.8 | Z3: 4993197.9 | AA3: 5858970.7 | AB3: 5818085.5 | AC3: 17983748 | AD3: 22592241 | AE3: 22444567 | AF3: 27261596 | AG3: 27027895 | AH3: 26819201
B4: BCG | C4: Low Income | D4: 1.5860127e+08 | E4: 1.6317939e+08 | F4: 1.7324226e+08 | G4: 1.7956992e+08 | H4: 1.8284175e+08 | I4: 1.6901377e+08 | J4: 1.700889e+08 | K4: 1.7099241e+08 | L4: 1.7454134e+08 | M4: 1.124793e+08 | N4: 85851850 | O4: 79000882 | P4: 76001633 | Q4: 74802167 | R4: 76940109 | S4: 77059752 | T4: 56233339 | U4: 57316201 | V4: 57753367 | W4: 62882877 | X4: 61763126 | Y4: 53246786 | Z4: 53584035 | AA4: 57329428 | AB4: 57632881 | AC4: 58594379 | AD4: 55244165 | AE4: 52333722 | AF4: 53523179 | AG4: 54783761 | AH4: 56018233
B5: BCG | C5: Lower Middle Income | D5: 58901554 | E5: 73089048 | F5: 67602896 | G5: 73879000 | H5: 98274085 | I5: 1.2093176e+08 | J5: 1.0555346e+08 | K5: 1.077091e+08 | L5: 87513041 | M5: 1.55432e+08 | N5: 1.7861927e+08 | O5: 1.8363475e+08 | P5: 1.6048051e+08 | Q5: 1.576214e+08 | R5: 1.4965217e+08 | S5: 1.4688243e+08 | T5: 1.7674045e+08 | U5: 1.8028509e+08 | V5: 1.8378947e+08 | W5: 1.7947828e+08 | X5: 1.7477241e+08 | Y5: 1.5947614e+08 | Z5: 1.8695217e+08 | AA5: 1.8622383e+08 | AB5: 1.6496186e+08 | AC5: 1.6479985e+08 | AD5: 1.6692721e+08 | AE5: 1.7240711e+08 | AF5: 1.6770392e+08 | AG5: 1.6958938e+08 | AH5: 1.7056571e+08
B6: BCG | C6: Upper Middle Income | D6: 40069259 | E6: 37199082 | F6: 41553820 | G6: 32932249 | H6: 11678133 | I6: 11693811 | J6: 30792555 | K6: 31674944 | L6: 54018151 | M6: 54304173 | N6: 59948778 | O6: 64281097 | P6: 90583182 | Q6: 93769359 | R6: 83737644 | S6: 83038288 | T6: 76793202 | U6: 89165212 | V6: 83714957 | W6: 77594157 | X6: 72034157 | Y6: 86134881 | Z6: 62365638 | AA6: 61872426 | AB6: 86002095 | AC6: 75926566 | AD6: 75865839 | AE6: 76859246 | AF6: 78957461 | AG6: 79477821 | AH6: 79877181
B7: bOPV | C7: High Income | T7: 18545880 | U7: 7903173.2 | V7: 5841854.2 | W7: 8610580.6 | X7: 5286878.2 | Y7: 5217133 | Z7: 4921402.6 | AA7: 5052108.6 | AB7: 4998867.7 | AC7: 43876574 | AD7: 51349717
B8: bOPV | C8: Low Income | T8: 72730018 | U8: 1.0570712e+08 | V8: 1.051229e+08 | W8: 1.1719715e+08 | X8: 1.0988395e+08 | Y8: 1.0245493e+08 | Z8: 1.0451565e+08 | AA8: 1.1158238e+08 | AB8: 1.1227561e+08 | AC8: 1.1406168e+08 | AD8: 1.0751713e+08
B9: bOPV | C9: Lower Middle Income | T9: 2.4814683e+08 | U9: 3.5337387e+08 | V9: 3.5043672e+08 | W9: 3.4662104e+08 | X9: 3.3593955e+08 | Y9: 3.3594803e+08 | Z9: 3.6575567e+08 | AA9: 3.6623113e+08 | AB9: 3.4781636e+08 | AC9: 3.4731021e+08 | AD9: 3.3650907e+08
B10: bOPV | C10: Upper Middle Income | T10: 1.1121093e+08 | U10: 1.7289435e+08 | V10: 1.3716887e+08 | W10: 1.2840844e+08 | X10: 1.2021655e+08 | Y10: 1.1577119e+08 | Z10: 89829782 | AA10: 89069211 | AB10: 1.1323213e+08 | AC10: 79625745 | AD10: 97021995
B11: Covid-19 | C11: High Income | X11: 7999629 | Y11: 2230537402 | Z11: 715448467 | AA11: 6.7224673e+08 | AB11: 6.7392758e+08 | AC11: 1.321223e+09 | AD11: 1.3435292e+09 | AE11: 1.3500028e+09 | AF11: 1.3952377e+09 | AG11: 1.400862e+09 | AH11: 1.4032704e+09
B12: Covid-19 | C12: Low Income | X12: 0 | Y12: 89460329 | Z12: 185668356 | AA12: 38756602 | AB12: 39462261 | AC12: 40346977 | AD12: 39721223 | AE12: 38658305 | AF12: 40005995 | AG12: 41580964 | AH12: 43232783
B13: Covid-19 | C13: Lower Middle Income | X13: 0 | Y13: 2654167495 | Z13: 2145751721 | AA13: 7.8264747e+08 | AB13: 7.5033441e+08 | AC13: 7.5297362e+08 | AD13: 7.5857573e+08 | AE13: 7.6908394e+08 | AF13: 7.6835446e+08 | AG13: 7.7884283e+08 | AH13: 7.8920493e+08
B14: Covid-19 | C14: Upper Middle Income | X14: 5098885 | Y14: 5050596480 | Z14: 1296608309 | AA14: 1.1175877e+09 | AB14: 1.1430276e+09 | AC14: 5.1551474e+08 | AD14: 5.1004924e+08 | AE14: 5.1567869e+08 | AF14: 4.9168109e+08 | AG14: 4.962824e+08 | AH14: 5.0081454e+08
B15: Dengue | C15: Lower Middle Income | T15: 2997892 | U15: 3030877.3
B16: Diphtheria | C16: High Income | D16: 45403.453 | E16: 48815.357 | F16: 51631.175 | G16: 52212.651 | H16: 53024.236 | I16: 55945.586 | J16: 57930.892 | K16: 61982.616 | L16: 64672.091 | M16: 67670.596 | N16: 68592.101 | O16: 69972.99 | P16: 76957.952 | Q16: 90017.238 | R16: 101145.22
B17: DT | C17: -- | D17: 94961.4 | E17: 90582.75 | F17: 92029.83 | G17: 119291.91 | H17: 111120 | I17: 98792.175 | J17: 82772.925 | K17: 96983.893
B18: DT | C18: High Income | D18: 1119051.8 | E18: 1222940.2 | F18: 1203400 | G18: 1217230.5 | H18: 1232734 | I18: 1231197.2 | J18: 1230059.9 | K18: 1219766.4 | L18: 1222583.4 | M18: 1268276 | N18: 1261043.9 | O18: 1265252.7 | P18: 1263631 | Q18: 1231828.8 | R18: 5094081 | S18: 5139940.4 | T18: 5130065 | U18: 1220097.5 | V18: 1223262.6 | W18: 1232125.9 | X18: 1208354 | Y18: 1212068.2 | Z18: 1195551.8 | AA18: 1189483.9 | AB18: 1192320.6 | AC18: 16729064 | AD18: 15711239 | AE18: 13744450 | AF18: 13089724 | AG18: 12920093 | AH18: 12788294
B19: DT | C19: Low Income | D19: 17559921 | E19: 1530590.5 | F19: 1386901.7 | G19: 1320690.4 | H19: 678429.41 | I19: 468765.33 | J19: 473725.65 | K19: 343604.27 | L19: 340659.15 | M19: 359787.73 | N19: 367309.28 | O19: 377112.44 | P19: 390295.27 | Q19: 390036.34 | R19: 428852.85 | S19: 264882.34 | W19: 674796.85 | X19: 4156434.5 | Y19: 4315320.2 | Z19: 4110923.5 | AA19: 4246029.6 | AB19: 4705085.7 | AC19: 4789178.8 | AD19: 718943.29 | AE19: 759633.2 | AF19: 785092.08 | AG19: 821841.37 | AH19: 863986.72
B20: DT | C20: Lower Middle Income | D20: 3364029.3 | E20: 19002103 | F20: 18724673 | G20: 18071980 | H20: 18376274 | I20: 18225152 | J20: 19831936 | K20: 19572618 | L20: 19597297 | M20: 19465616 | N20: 18787990 | O20: 18949188 | P20: 1565811.3 | Q20: 1478823.8 | R20: 1472017.6 | S20: 1622398.4 | T20: 1784486.6 | U20: 2200512.6 | V20: 2217689.2 | W20: 1502990.7 | X20: 906377.51 | Y20: 2089581.7 | Z20: 2331416 | AA20: 2295538.3 | AB20: 1554268.8 | AC20: 1550926 | AD20: 5699436.3 | AE20: 5324019.7 | AF20: 5339861.9 | AG20: 5355310.6 | AH20: 5370201.9
B21: DT | C21: Upper Middle Income | D21: 1130679.7 | E21: 1141336.2 | F21: 1132507 | G21: 1165910.2 | H21: 1156129 | I21: 1164352.2 | J21: 1157269.6 | K21: 1171509.5 | L21: 1522584.7 | M21: 1772267.7 | N21: 2460189.8 | O21: 2698865.2 | P21: 20249975 | Q21: 20803047 | R21: 21468732 | S21: 21404436 | T21: 21433161 | U21: 25055068 | V21: 25107099 | W21: 25126385 | X21: 25114664 | Y21: 23444220 | Z21: 23286004 | AA21: 23891029 | AB21: 22655217 | AC21: 5070868.9 | AD21: 4310614.9 | AE21: 4634200.9 | AF21: 4406115.4 | AG21: 4349721.6 | AH21: 4313357.8
B22: DTaP | C22: -- | D22: 8083.8947 | E22: 7983.4737 | F22: 7977.7895 | G22: 8014.1329 | H22: 8010.675 | I22: 7915.2632 | J22: 7673.6842 | K22: 7588.5474
B23: DTaP | C23: High Income | D23: 10825968 | E23: 11521230 | F23: 11271970 | G23: 14068018 | H23: 11348177 | I23: 11284629 | J23: 11210215 | K23: 11317814 | L23: 11467914 | M23: 11384250 | N23: 11359761 | O23: 11355944 | P23: 6964431.4 | Q23: 7530729 | R23: 7546137.3 | S23: 7669887.5 | T23: 8010425.9 | U23: 7912563.9 | V23: 7582079.2 | W23: 7447860.9 | X23: 7305237.8 | Y23: 7183718.3 | Z23: 7162774.1 | AA23: 7186571.4 | AB23: 7179815 | AC23: 45956969 | AD23: 45554047 | AE23: 45164177 | AF23: 44825038 | AG23: 44551215 | AH23: 44326791
B24: DTaP | C24: Low Income | D24: 41607.368 | E24: 39938.021 | F24: 37677 | G24: 36285.663
B25: DTaP | C25: Lower Middle Income | D25: 3216.8421 | E25: 4331.4779 | F25: 4220.8826 | G25: 4121.8737 | H25: 41648.762 | I25: 41943.776 | J25: 39476.684 | K25: 41243.732 | L25: 40140.863 | M25: 43047.701 | N25: 45402.379 | O25: 46536.082 | P25: 44901.842 | Q25: 47181.512 | R25: 48327.245 | S25: 75591.372 | T25: 26200.221 | U25: 24374.658 | V25: 25532.972 | W25: 25094.192 | X25: 23888.305 | Y25: 22126.295 | Z25: 23119.134 | AA25: 23153.28 | AB25: 23437.405 | AC25: 23890.937 | AD25: 24351.531
B26: DTaP | C26: Upper Middle Income | D26: 2465676.4 | E26: 2832127.2 | F26: 2992012.7 | G26: 49379.684 | H26: 47839.326 | I26: 45676.8 | J26: 43824.505 | K26: 137168.08 | L26: 49309.91 | M26: 49259.314 | N26: 8134.5692 | O26: 8195.5325 | P26: 74019754 | Q26: 74997412 | R26: 73216796 | S26: 71566155 | T26: 70205181 | U26: 71079334 | V26: 63915343 | W26: 57156938 | X26: 51466522 | Y26: 44878448 | Z26: 40973318 | AA26: 39904744 | AB26: 39559369 | AC26: 415706.68 | AD26: 431606.95 | AE26: 459548.38 | AF26: 446100.05 | AG26: 437514.08 | AH26: 430931.21
B27: DTaP-HepB | C27: Lower Middle Income | D27: 9089.3684 | E27: 8715.6316 | F27: 8496.2443 | G27: 9079.9263 | H27: 7227.7895 | I27: 8796.5487 | J27: 6602.4842 | K27: 6929.6141 | L27: 7073.5722 | M27: 8011.65 | N27: 7157.7895 | O27: 7240.7526 | P27: 7066.0526 | Q27: 4075.6905
B28: DTaP-HepB-Hib | C28: High Income | D28: 166958.84 | E28: 165729.92 | X28: 30178.358 | Y28: 28722.505 | Z28: 26301.695 | AA28: 25127.242 | AB28: 24585.347 | AC28: 24138.284 | AD28: 23828.779 | AE28: 23700.6 | AF28: 23759.922 | AG28: 23980.666 | AH28: 24359.106
B29: DTaP-HepB-Hib | C29: Lower Middle Income | W29: 30968.789 | X29: 29065.547 | Y29: 29888.876 | Z29: 29689.843 | AA29: 29609.337 | AB29: 29599.958 | AC29: 29654.121 | AD29: 29663.07
B30: DTaP-HepB-Hib | C30: Upper Middle Income | AE30: 29663.227 | AF30: 29666.353 | AG30: 29665.611 | AH30: 29653.105
B31: DTaP-HepB-Hib-IPV | C31: High Income | D31: 10384358 | E31: 10483052 | F31: 10759557 | G31: 10884669 | H31: 10971477 | I31: 11777902 | J31: 11899978 | K31: 12066440 | L31: 12741743 | M31: 12937984 | N31: 13091003 | O31: 13049889 | P31: 12922980 | Q31: 14708001 | R31: 14748339 | S31: 15106559 | T31: 14872756 | U31: 17180195 | V31: 17503375 | W31: 18417360 | X31: 18044096 | Y31: 20691154 | Z31: 20085170 | AA31: 20961571 | AB31: 20941291 | AC31: 20884037 | AD31: 23015544 | AE31: 22949120 | AF31: 22863374 | AG31: 22780778 | AH31: 22700002
B32: DTaP-HepB-Hib-IPV | C32: Lower Middle Income | D32: 77147.621 | E32: 78898.436 | F32: 77949.259 | S32: 14724.55 | T32: 213958.16 | V32: 896285.53 | W32: 160009.85 | AB32: 278213.57 | AC32: 280005.61 | AD32: 283015.82 | AE32: 286417.42
B33: DTaP-HepB-Hib-IPV | C33: Upper Middle Income | D33: 185887.44 | E33: 177799.52 | F33: 178287.47 | G33: 252247.43 | H33: 252298.51 | I33: 257525.7 | J33: 431009.67 | K33: 891465.99 | L33: 873731.01 | M33: 705871.65 | N33: 508004.28 | O33: 415803.28 | P33: 479914.7 | Q33: 1269962 | R33: 1183118 | S33: 4605731.8 | T33: 9198841.3 | U33: 10381330 | V33: 9706217.5 | W33: 7154165.7 | X33: 9070831.6 | Y33: 11947450 | Z33: 12700792 | AA33: 11877146 | AB33: 11604890 | AC33: 11614621 | AD33: 9393912.3 | AE33: 9380230.2 | AF33: 9661130 | AG33: 9685448.5 | AH33: 9708542.1
B34: DTaP-HepB-IPV | C34: High Income | D34: 2407703.5 | E34: 2450357.3 | F34: 2437018.4 | G34: 2503752.4 | H34: 2507370.8 | I34: 2515769.3 | J34: 2546214.9 | K34: 2580895.8 | L34: 2562868.6 | M34: 2485821.9 | N34: 2449527.1 | O34: 2454264.3 | P34: 2417401.1 | Q34: 2431677 | R34: 2441357 | S34: 2445298.3 | T34: 2439006.4 | U34: 2392607.6 | V34: 2355516.2 | W34: 2317006.7 | X34: 2253566.3 | Y34: 2229094.6 | Z34: 2281604.3 | AA34: 2312483 | AB34: 2326983 | AC34: 2334495.6 | AD34: 2346303.7 | AE34: 2356567.2 | AF34: 2368298.1 | AG34: 2378228.8 | AH34: 2385352
B35: DTaP-HepB-IPV | C35: Lower Middle Income | Q35: 2951.3621 | R35: 7711.3551 | S35: 6483.8105 | T35: 6360.4947 | U35: 6568.8376 | V35: 6541.0676 | W35: 6592.0262 | X35: 6767.9521 | Y35: 6334.8842 | Z35: 6472.9762 | AA35: 6603.1151 | AB35: 6727.6489 | AC35: 6771.0826 | AD35: 6837.5813
B36: DTaP-HepB-IPV | C36: Upper Middle Income | AE36: 6899.4505 | AF36: 6962.2734 | AG36: 6985.8221 | AH36: 6987.9033
B37: DTaP-Hib | C37: High Income | D37: 2124117.9 | E37: 2079776.2 | F37: 2066605.6 | G37: 2556263.6 | H37: 433472.72 | I37: 424260.09 | J37: 110207.11 | K37: 106585 | L37: 102979 | M37: 120355.61 | N37: 119514.77 | O37: 120789.82 | P37: 121734.41 | Q37: 791328.2 | R37: 779124.47 | S37: 866515.26 | T37: 755357.83 | U37: 665387.24 | V37: 677839.5 | W37: 682488.07 | X37: 681634.36 | Y37: 692874.5 | Z37: 685136.08 | AA37: 670789.61 | AB37: 659099.27 | AC37: 3919579.7 | AD37: 3873683.8 | AE37: 3834518.8 | AF37: 3801709.1 | AG37: 3775441.1 | AH37: 3753257.1
B38: DTaP-Hib | C38: Upper Middle Income | D38: 56687.747 | E38: 58370.018 | F38: 59096.088 | G38: 62795.03 | H38: 77079.432 | I38: 75667.958 | J38: 73722.473 | K38: 68607.663 | L38: 67761.45 | M38: 64807.305 | N38: 3506714.7 | O38: 3500885.9 | P38: 60943.305 | Q38: 638003.86 | R38: 627160.36 | S38: 1306608 | T38: 1161672.5 | U38: 1906276.7 | V38: 6114463.9 | W38: 4681815.1 | X38: 4177477.9 | Y38: 3595868.4 | Z38: 3364467 | AA38: 3329664.2 | AB38: 3302080.4
B39: DTaP-Hib-IPV | C39: High Income | D39: 10918706 | E39: 11096836 | F39: 11069755 | G39: 11817034 | H39: 14050497 | I39: 14133436 | J39: 14675710 | K39: 14896974 | L39: 15083190 | M39: 15333262 | N39: 15285142 | O39: 15320404 | P39: 15259188 | Q39: 15259521 | R39: 15009108 | S39: 15033225 | T39: 16180119 | U39: 16216393 | V39: 14677145 | W39: 13719013 | X39: 13029564 | Y39: 10784189 | Z39: 10921290 | AA39: 11058824 | AB39: 11105849 | AC39: 12769336 | AD39: 12841912 | AE39: 13093112 | AF39: 17793069 | AG39: 17761708 | AH39: 17711618
B40: DTaP-Hib-IPV | C40: Lower Middle Income | J40: 458159.49 | K40: 794594.12 | L40: 575027.14 | M40: 488986.45 | N40: 875476.69 | O40: 866095.28 | P40: 441027.39 | Q40: 407293.58 | R40: 307001.84 | S40: 285645.71 | T40: 187528.67 | AB40: 91558.421 | AC40: 91777.185 | AD40: 92382.36 | AE40: 93389.324
...

Sheet Demand_data_trend
B1: 2000 | C1: 2001 | D1: 2002 | E1: 2003 | F1: 2004 | G1: 2005 | H1: 2006 | I1: 2007 | J1: 2008 | K1: 2009 | L1: 2010 | M1: 2011 | N1: 2012 | O1: 2013 | P1: 2014 | Q1: 2015 | R1: 2016 | S1: 2017 | T1: 2018 | U1: 2019 | V1: 2020 | W1: 2021 | X1: 2022 | Y1: 2023
A2: M | B2: 78580259 | C2: 11428.56 | D2: 10932.726 | E2: 10567.573 | F2: 10631.537 | G2: 10866.43 | H2: 11173.117 | I2: 11270.145 | J2: 11244.154 | K2: 0 | L2: 17696391 | M2: 17721468 | N2: 8703411.1 | O2: 26868698 | P2: 28597586 | Q2: 31745853 | R2: 19409700 | S2: 36511824 | T2: 18347409 | U2: 14873766 | V2: 9862745.1 | W2: 14777182 | X2: 37949221 | Y2: 17547796
A3: MR | B3: 16708549 | C3: 16708884 | D3: 16621239 | E3: 16912299 | F3: 17990793 | G3: 32224595 | H3: 36010296 | I3: 35638479 | J3: 21093263 | K3: 22353125 | L3: 22384691 | M3: 21083590 | N3: 4248060.8 | O3: 15084549 | P3: 24102254 | Q3: 1.0186838e+08 | R3: 89505897 | S3: 1.6634012e+08 | T3: 4.1016995e+08 | U3: 3.3242543e+08 | V3: 1.9429105e+08 | W3: 3.3127915e+08 | X3: 2.2738502e+08 | Y3: 2.7883599e+08
A4: MMR | B4: 14895547 | C4: 15916937 | D4: 16440302 | E4: 17051794 | F4: 25753121 | G4: 26516485 | H4: 28053836 | I4: 27963867 | J4: 39454389 | K4: 41213109 | L4: 42926745 | M4: 42885187 | N4: 22148782 | O4: 22105642 | P4: 19837777 | Q4: 26434485 | R4: 20737739 | S4: 20303126 | T4: 23934205 | U4: 21792972 | V4: 18694960 | W4: 26052156 | X4: 26626399 | Y4: 25785425
A5: TT | B5: 78159429 | C5: 79754932 | D5: 82572072 | E5: 85747371 | F5: 88823502 | G5: 90980826 | H5: 93434225 | I5: 98105258 | J5: 1.0107845e+08 | K5: 1.045828e+08 | L5: 1.0577618e+08 | M5: 1.3537284e+08 | N5: 1.4858272e+08 | O5: 1.6428276e+08 | P5: 1.7355105e+08 | Q5: 1.7788569e+08 | R5: 1.4983151e+08 | S5: 1.8608543e+08 | T5: 1.6476826e+08 | U5: 42499760 | V5: 10518908 | W5: 7180030.7 | X5: 6811039.8 | Y5: 6823077.8
A6: Td | B6: 50764265 | C6: 50774338 | D6: 50335232 | E6: 52856121 | F6: 69969918 | G6: 68257615 | H6: 54723843 | I6: 53185019 | J6: 38358186 | K6: 36289140 | L6: 31847542 | M6: 29878049 | N6: 27224651 | O6: 28389437 | P6: 29041953 | Q6: 34928665 | R6: 74784906 | S6: 94070116 | T6: 1.2998874e+08 | U6: 2.4447306e+08 | V6: 2.6883403e+08 | W6: 2.4348251e+08 | X6: 2.6568355e+08 | Y6: 2.6744926e+08
A7: DT | B7: 20923950 | C7: 20532694 | D7: 20111575 | E7: 19392670 | F7: 19054703 | G7: 18693918 | H7: 20305662 | I7: 19916222 | J7: 19937956 | K7: 19825404 | L7: 19155299 | M7: 19326301 | N7: 1956106.5 | O7: 1868860.1 | P7: 1900870.4 | Q7: 1887280.7 | R7: 1784486.6 | S7: 2200512.6 | T7: 2217689.2 | U7: 2177787.6 | V7: 5062812 | W7: 6404902 | X7: 6442339.5 | Y7: 6541567.8
A8: DTwP | B8: 3.1159881e+08 | C8: 3.1491321e+08 | D8: 2.7509822e+08 | E8: 2.6287146e+08 | F8: 2.6112864e+08 | G8: 2.57038e+08 | H8: 2.4333695e+08 | I8: 2.2780079e+08 | J8: 2.2594539e+08 | K8: 2.3281353e+08 | L8: 2.3532813e+08 | M8: 2.3295752e+08 | N8: 1.4441783e+08 | O8: 1.4219182e+08 | P8: 1.3898601e+08 | Q8: 91307954 | R8: 64954167 | S8: 66630415 | T8: 66455709 | U8: 65876339 | V8: 61511976 | W8: 62054152 | X8: 65413987 | Y8: 65841842
A9: DTwP-Hib | B9: 4569986.5 | C9: 2613786 | D9: 2314794.7 | E9: 4993056.6 | F9: 6731549.6 | G9: 5829500.6 | H9: 2388879.2 | I9: 2682334 | J9: 5503855 | K9: 6149962.6 | L9: 2755123.1 | M9: 3016433.5 | N9: 2770511.6 | O9: 2616817.9 | P9: 0 | Q9: 0 | R9: 0 | S9: 0 | T9: 0 | U9: 2577182.4 | V9: 2545600.6 | W9: 5826576.9 | X9: 5816636.4 | Y9: 5854584.9
A10: Penta | B10: 5598384.2 | C10: 11321282 | D10: 21742187 | E10: 23354085 | F10: 34313914 | G10: 44391890 | H10: 49168455 | I10: 61360525 | J10: 68262550 | K10: 1.2187766e+08 | L10: 1.237333e+08 | M10: 1.2984514e+08 | N10: 1.4280675e+08 | O10: 1.5122855e+08 | P10: 1.7549308e+08 | Q10: 2.3413333e+08 | R10: 2.6127633e+08 | S10: 2.6675755e+08 | T10: 2.7543893e+08 | U10: 2.8016166e+08 | V10: 2.6901659e+08 | W10: 2.5278201e+08 | X10: 2.761834e+08 | Y10: 2.8076815e+08
A11: Hexa | B11: 77147.621 | C11: 78898.436 | D11: 77949.259 | E11: 0 | F11: 0 | G11: 0 | H11: 0 | I11: 0 | J11: 0 | K11: 0 | L11: 0 | M11: 0 | N11: 0 | O11: 0 | P11: 0 | Q11: 14724.55 | R11: 213958.16 | S11: 0 | T11: 896285.53 | U11: 160009.85 | V11: 0 | W11: 0 | X11: 0 | Y11: 0
A12: IPV | B12: 0 | C12: 0 | D12: 0 | E12: 0 | F12: 0 | G12: 0 | H12: 538568.8 | I12: 572237.68 | J12: 1564054.1 | K12: 1802422.6 | L12: 1596326.4 | M12: 1432203.2 | N12: 1193206.4 | O12: 1051750 | P12: 838163.74 | Q12: 14134727 | R12: 45560280 | S12: 51668556 | T12: 65056521 | U12: 82074179 | V12: 79857578 | W12: 83779047 | X12: 1.1191097e+08 | Y12: 1.3081826e+08
A13: OPV | B13: 0 | C13: 0 | D13: 0 | E13: 0 | F13: 0 | G13: 0 | H13: 0 | I13: 0 | J13: 0 | K13: 0 | L13: 0 | M13: 0 | N13: 0 | O13: 0 | P13: 0 | Q13: 0 | R13: 3.2087685e+08 | S13: 4.5908099e+08 | T13: 4.5555962e+08 | U13: 4.6381819e+08 | V13: 4.458235e+08 | W13: 4.3840296e+08 | X13: 4.7027132e+08 | Y13: 4.7781351e+08
... A18: PCV | B18: 0 | C18: 0 | D18: 0 | E18: 0 | F18: 0 | G18: 0 | H18: 0 | I18: 6300.6316 | J18: 1716887.9 | K18: 1579536.4 | L18: 9327523.8 | M18: 23147609 | N18: 41170015 | O18: 66222136 | P18: 89756384 | Q18: 1.0760398e+08 | R18: 1.2732722e+08 | S18: 1.3652887e+08 | T18: 1.455625e+08 | U18: 1.4181183e+08 | V18: 1.6080023e+08 | W18: 1.869961e+08 | X18: 2.0916547e+08 | Y18: 2.0593845e+08
A20: M | B20: =+"["&ROUND(B2,0)&"," -> [78580259, | C20: =+ROUND(C2,0)&"," -> 11429, | D20: =+ROUND(D2,0)&"," -> 10933, | E20: =+ROUND(E2,0)&"," -> 10568, | F20: =+ROUND(F2,0)&"," -> 10632, | G20: =+ROUND(G2,0)&"," -> 10866, | H20: =+ROUND(H2,0)&"," -> 11173, | I20: =+ROUND(I2,0)&"," -> 11270, | J20: =+ROUND(J2,0)&"," -> 11244, | ... X20: =+ROUND(X2,0)&"," -> 37949221, | Y20: =+ROUND(Y2,0)&"]" -> 17547796]
A21: MR | B21: =+"["&ROUND(B3,0)&"," -> [16708549, | C21: =+ROUND(C3,0)&"," -> 16708884, | D21: =+ROUND(D3,0)&"," -> 16621239, | E21: =+ROUND(E3,0)&"," -> 16912299, | F21: =+ROUND(F3,0)&"," -> 17990793, | G21: =+ROUND(G3,0)&"," -> 32224595, | H21: =+ROUND(H3,0)&"," -> 36010296, | I21: =+ROUND(I3,0)&"," -> 35638479, | J21: =+ROUND(J3,0)&"," -> 21093263, | ... X21: =+ROUND(X3,0)&"," -> 227385022, | Y21: =+ROUND(Y3,0)&"]" -> 278835991]
A22: MMR | B22: =+"["&ROUND(B4,0)&"," -> [14895547, | C22: =+ROUND(C4,0)&"," -> 15916937, | D22: =+ROUND(D4,0)&"," -> 16440302, | E22: =+ROUND(E4,0)&"," -> 17051794, | F22: =+ROUND(F4,0)&"," -> 25753121, | G22: =+ROUND(G4,0)&"," -> 26516485, | H22: =+ROUND(H4,0)&"," -> 28053836, | I22: =+ROUND(I4,0)&"," -> 27963867, | J22: =+ROUND(J4,0)&"," -> 39454389, | ... X22: =+ROUND(X4,0)&"," -> 26626399, | Y22: =+ROUND(Y4,0)&"]" -> 25785425]
A23: TT | B23: =+"["&ROUND(B5,0)&"," -> [78159429, | C23: =+ROUND(C5,0)&"," -> 79754932, | D23: =+ROUND(D5,0)&"," -> 82572072, | E23: =+ROUND(E5,0)&"," -> 85747371, | F23: =+ROUND(F5,0)&"," -> 88823502, | G23: =+ROUND(G5,0)&"," -> 90980826, | H23: =+ROUND(H5,0)&"," -> 93434225, | I23: =+ROUND(I5,0)&"," -> 98105258, | J23: =+ROUND(J5,0)&"," -> 101078446, | ... X23: =+ROUND(X5,0)&"," -> 6811040, | Y23: =+ROUND(Y5,0)&"]" -> 6823078]
A24: Td | B24: =+"["&ROUND(B6,0)&"," -> [50764265, | C24: =+ROUND(C6,0)&"," -> 50774338, | D24: =+ROUND(D6,0)&"," -> 50335232, | E24: =+ROUND(E6,0)&"," -> 52856121, | F24: =+ROUND(F6,0)&"," -> 69969918, | G24: =+ROUND(G6,0)&"," -> 68257615, | H24: =+ROUND(H6,0)&"," -> 54723843, | I24: =+ROUND(I6,0)&"," -> 53185019, | J24: =+ROUND(J6,0)&"," -> 38358186, | ... X24: =+ROUND(X6,0)&"," -> 265683552, | Y24: =+ROUND(Y6,0)&"]" -> 267449255]
A25: DT | B25: =+"["&ROUND(B7,0)&"," -> [20923950, | C25: =+ROUND(C7,0)&"," -> 20532694, | D25: =+ROUND(D7,0)&"," -> 20111575, | E25: =+ROUND(E7,0)&"," -> 19392670, | F25: =+ROUND(F7,0)&"," -> 19054703, | G25: =+ROUND(G7,0)&"," -> 18693918, | H25: =+ROUND(H7,0)&"," -> 20305662, | I25: =+ROUND(I7,0)&"," -> 19916222, | J25: =+ROUND(J7,0)&"," -> 19937956, | ... X25: =+ROUND(X7,0)&"," -> 6442339, | Y25: =+ROUND(Y7,0)&"]" -> 6541568]
A26: DTwP | B26: =+"["&ROUND(B8,0)&"," -> [311598814, | C26: =+ROUND(C8,0)&"," -> 314913213, | D26: =+ROUND(D8,0)&"," -> 275098221, | E26: =+ROUND(E8,0)&"," -> 262871460, | F26: =+ROUND(F8,0)&"," -> 261128636, | G26: =+ROUND(G8,0)&"," -> 257038005, | H26: =+ROUND(H8,0)&"," -> 243336949, | I26: =+ROUND(I8,0)&"," -> 227800791, | J26: =+ROUND(J8,0)&"," -> 225945394, | ... X26: =+ROUND(X8,0)&"," -> 65413987, | Y26: =+ROUND(Y8,0)&"]" -> 65841842]
A27: DTwP-Hib | B27: =+"["&ROUND(B9,0)&"," -> [4569987, | C27: =+ROUND(C9,0)&"," -> 2613786, | D27: =+ROUND(D9,0)&"," -> 2314795, | E27: =+ROUND(E9,0)&"," -> 4993057, | F27: =+ROUND(F9,0)&"," -> 6731550, | G27: =+ROUND(G9,0)&"," -> 5829501, | H27: =+ROUND(H9,0)&"," -> 2388879, | I27: =+ROUND(I9,0)&"," -> 2682334, | J27: =+ROUND(J9,0)&"," -> 5503855, | ... X27: =+ROUND(X9,0)&"," -> 5816636, | Y27: =+ROUND(Y9,0)&"]" -> 5854585]
A28: Penta | B28: =+"["&ROUND(B10,0)&"," -> [5598384, | C28: =+ROUND(C10,0)&"," -> 11321282, | D28: =+ROUND(D10,0)&"," -> 21742187, | E28: =+ROUND(E10,0)&"," -> 23354085, | F28: =+ROUND(F10,0)&"," -> 34313914, | G28: =+ROUND(G10,0)&"," -> 44391890, | H28: =+ROUND(H10,0)&"," -> 49168455, | I28: =+ROUND(I10,0)&"," -> 61360525, | J28: =+ROUND(J10,0)&"," -> 68262550, | ... X28: =+ROUND(X10,0)&"," -> 276183400, | Y28: =+ROUND(Y10,0)&"]" -> 280768151]
A29: Hexa | B29: =+"["&ROUND(B11,0)&"," -> [77148, | C29: =+ROUND(C11,0)&"," -> 78898, | D29: =+ROUND(D11,0)&"," -> 77949, | E29: =+ROUND(E11,0)&"," -> 0, | F29: =+ROUND(F11,0)&"," -> 0, | G29: =+ROUND(G11,0)&"," -> 0, | H29: =+ROUND(H11,0)&"," -> 0, | I29: =+ROUND(I11,0)&"," -> 0, | J29: =+ROUND(J11,0)&"," -> 0, | ... X29: =+ROUND(X11,0)&"," -> 0, | Y29: =+ROUND(Y11,0)&"]" -> 0]
A30: IPV | B30: =+"["&ROUND(B12,0)&"," -> [0, | C30: =+ROUND(C12,0)&"," -> 0, | D30: =+ROUND(D12,0)&"," -> 0, | E30: =+ROUND(E12,0)&"," -> 0, | F30: =+ROUND(F12,0)&"," -> 0, | G30: =+ROUND(G12,0)&"," -> 0, | H30: =+ROUND(H12,0)&"," -> 538569, | I30: =+ROUND(I12,0)&"," -> 572238, | J30: =+ROUND(J12,0)&"," -> 1564054, | ... X30: =+ROUND(X12,0)&"," -> 111910967, | Y30: =+ROUND(Y12,0)&"]" -> 130818258]
A31: OPV | B31: =+"["&ROUND(B13,0)&"," -> [0, | C31: =+ROUND(C13,0)&"," -> 0, | D31: =+ROUND(D13,0)&"," -> 0, | E31: =+ROUND(E13,0)&"," -> 0, | F31: =+ROUND(F13,0)&"," -> 0, | G31: =+ROUND(G13,0)&"," -> 0, | H31: =+ROUND(H13,0)&"," -> 0, | I31: =+ROUND(I13,0)&"," -> 0, | J31: =+ROUND(J13,0)&"," -> 0, | ... X31: =+ROUND(X13,0)&"," -> 470271315, | Y31: =+ROUND(Y13,0)&"]" -> 477813507]
... A36: PCV | B36: =+"["&ROUND(B18,0)&"," -> [0, | C36: =+ROUND(C18,0)&"," -> 0, | D36: =+ROUND(D18,0)&"," -> 0, | E36: =+ROUND(E18,0)&"," -> 0, | F36: =+ROUND(F18,0)&"," -> 0, | G36: =+ROUND(G18,0)&"," -> 0, | H36: =+ROUND(H18,0)&"," -> 0, | I36: =+ROUND(I18,0)&"," -> 6301, | J36: =+ROUND(J18,0)&"," -> 1716888, | ... X36: =+ROUND(X18,0)&"," -> 209165466, | Y36: =+ROUND(Y18,0)&"]" -> 205938451]
A38: M | B38: =+_xlfn.CONCAT(B20:Y20)&"," -> [78580259,11429,10933,10568,10632,10866,11173,11270,11244,0,17696391,17721468,8703411,26868698,28597586,31745853,19409700,36511824,18347409,14873766,9862745,14777182,37949221,17547796],
A39: MR | B39: =+_xlfn.CONCAT(B21:Y21)&"," -> [16708549,16708884,16621239,16912299,17990793,32224595,36010296,35638479,21093263,22353125,22384691,21083590,4248061,15084549,24102254,101868384,89505897,166340121,410169950,332425433,194291047,331279149,227385022,278835991],
A40: MMR | B40: =+_xlfn.CONCAT(B22:Y22)&"," -> [14895547,15916937,16440302,17051794,25753121,26516485,28053836,27963867,39454389,41213109,42926745,42885187,22148782,22105642,19837777,26434485,20737739,20303126,23934205,21792972,18694960,26052156,26626399,25785425],
A41: TT | B41: =+_xlfn.CONCAT(B23:Y23)&"," -> [78159429,79754932,82572072,85747371,88823502,90980826,93434225,98105258,101078446,104582797,105776185,135372841,148582724,164282756,173551045,177885695,149831514,186085427,164768261,42499760,10518908,7180031,6811040,6823078],
A42: Td | B42: =+_xlfn.CONCAT(B24:Y24)&"," -> [50764265,50774338,50335232,52856121,69969918,68257615,54723843,53185019,38358186,36289140,31847542,29878049,27224651,28389437,29041953,34928665,74784906,94070116,129988736,244473057,268834028,243482509,265683552,267449255],
A43: DT | B43: =+_xlfn.CONCAT(B25:Y25)&"," -> [20923950,20532694,20111575,19392670,19054703,18693918,20305662,19916222,19937956,19825404,19155299,19326301,1956107,1868860,1900870,1887281,1784487,2200513,2217689,2177788,5062812,6404902,6442339,6541568],
A44: DTwP | B44: =+_xlfn.CONCAT(B26:Y26)&"," -> [311598814,314913213,275098221,262871460,261128636,257038005,243336949,227800791,225945394,232813533,235328126,232957520,144417830,142191817,138986008,91307954,64954167,66630415,66455709,65876339,61511976,62054152,65413987,65841842],
A45: DTwP-Hib | B45: =+_xlfn.CONCAT(B27:Y27)&"," -> [4569987,2613786,2314795,4993057,6731550,5829501,2388879,2682334,5503855,6149963,2755123,3016434,2770512,2616818,0,0,0,0,0,2577182,2545601,5826577,5816636,5854585],
A46: Penta | B46: =+_xlfn.CONCAT(B28:Y28)&"," -> [5598384,11321282,21742187,23354085,34313914,44391890,49168455,61360525,68262550,121877662,123733297,129845142,142806746,151228547,175493079,234133328,261276329,266757549,275438932,280161656,269016594,252782013,276183400,280768151],
A47: Hexa | B47: =+_xlfn.CONCAT(B29:Y29)&"," -> [77148,78898,77949,0,0,0,0,0,0,0,0,0,0,0,0,14725,213958,0,896286,160010,0,0,0,0],
A48: IPV | B48: =+_xlfn.CONCAT(B30:Y30)&"," -> [0,0,0,0,0,0,538569,572238,1564054,1802423,1596326,1432203,1193206,1051750,838164,14134727,45560280,51668556,65056521,82074179,79857578,83779047,111910967,130818258],
A49: OPV | B49: =+_xlfn.CONCAT(B31:Y31)&"," -> [0,0,0,0,0,0,0,0,0,0,0,0,0,0,0,0,320876850,459080986,455559619,463818185,445823504,438402962,470271315,477813507],
... A54: PCV | B54: =+_xlfn.CONCAT(B36:Y36)&"," -> [0,0,0,0,0,0,0,6301,1716888,1579536,9327524,23147609,41170015,66222136,89756384,107603981,127327221,136528866,145562505,141811833,160800233,186996097,209165466,205938451],
...

Sheet Demand_data_trend_v2
B1: 2000 | C1: 2001 | D1: 2002 | E1: 2003 | F1: 2004 | G1: 2005 | H1: 2006 | I1: 2007 | J1: 2008 | K1: 2009 | L1: 2010 | M1: 2011 | N1: 2012 | O1: 2013 | P1: 2014 | Q1: 2015 | R1: 2016 | S1: 2017 | T1: 2018 | U1: 2019 | V1: 2020 | W1: 2021 | X1: 2022 | Y1: 2023
A2: M | B2: 78580259 | C2: 11428.56 | D2: 10932.726 | E2: 10567.573 | F2: 10631.537 | G2: 10866.43 | H2: 11173.117 | I2: 11270.145 | J2: 11244.154 | K2: 0 | L2: 17696391 | M2: 17721468 | N2: 8703411.1 | O2: 26868698 | P2: 28597586 | Q2: 31745853 | R2: 19409700 | S2: 36511824 | T2: 18347409 | U2: 14873766 | V2: 9862745.1 | W2: 14777182 | X2: 37949221 | Y2: 17547796
A3: MR | B3: 16708549 | C3: 16708884 | D3: 16621239 | E3: 16912299 | F3: 17990793 | G3: 32224595 | H3: 36010296 | I3: 35638479 | J3: 21093263 | K3: 22353125 | L3: 22384691 | M3: 21083590 | N3: 4248060.8 | O3: 15084549 | P3: 24102254 | Q3: 1.0186838e+08 | R3: 89505897 | S3: 1.6634012e+08 | T3: 4.1016995e+08 | U3: 3.3242543e+08 | V3: 1.9429105e+08 | W3: 3.3127915e+08 | X3: 2.2738502e+08 | Y3: 2.7883599e+08
A4: MMR | B4: 14895547 | C4: 15916937 | D4: 16440302 | E4: 17051794 | F4: 25753121 | G4: 26516485 | H4: 28053836 | I4: 27963867 | J4: 39454389 | K4: 41213109 | L4: 42926745 | M4: 42885187 | N4: 22148782 | O4: 22105642 | P4: 19837777 | Q4: 26434485 | R4: 20737739 | S4: 20303126 | T4: 23934205 | U4: 21792972 | V4: 18694960 | W4: 26052156 | X4: 26626399 | Y4: 25785425
A5: TT | B5: 78159429 | C5: 79754932 | D5: 82572072 | E5: 85747371 | F5: 88823502 | G5: 90980826 | H5: 93434225 | I5: 98105258 | J5: 1.0107845e+08 | K5: 1.045828e+08 | L5: 1.0577618e+08 | M5: 1.3537284e+08 | N5: 1.4858272e+08 | O5: 1.6428276e+08 | P5: 1.7355105e+08 | Q5: 1.7788569e+08 | R5: 1.4983151e+08 | S5: 1.8608543e+08 | T5: 1.6476826e+08 | U5: 42499760 | V5: 10518908 | W5: 7180030.7 | X5: 6811039.8 | Y5: 6823077.8
A6: Td | B6: 50764265 | C6: 50774338 | D6: 50335232 | E6: 52856121 | F6: 69969918 | G6: 68257615 | H6: 54723843 | I6: 53185019 | J6: 38358186 | K6: 36289140 | L6: 31847542 | M6: 29878049 | N6: 27224651 | O6: 28389437 | P6: 29041953 | Q6: 34928665 | R6: 74784906 | S6: 94070116 | T6: 1.2998874e+08 | U6: 2.4447306e+08 | V6: 2.6883403e+08 | W6: 2.4348251e+08 | X6: 2.6568355e+08 | Y6: 2.6744926e+08
A7: DT | B7: 20923950 | C7: 20532694 | D7: 20111575 | E7: 19392670 | F7: 19054703 | G7: 18693918 | H7: 20305662 | I7: 19916222 | J7: 19937956 | K7: 19825404 | L7: 19155299 | M7: 19326301 | N7: 1956106.5 | O7: 1868860.1 | P7: 1900870.4 | Q7: 1887280.7 | R7: 1784486.6 | S7: 2200512.6 | T7: 2217689.2 | U7: 2177787.6 | V7: 5062812 | W7: 6404902 | X7: 6442339.5 | Y7: 6541567.8
A8: DTwP | B8: 3.1159881e+08 | C8: 3.1491321e+08 | D8: 2.7509822e+08 | E8: 2.6287146e+08 | F8: 2.6112864e+08 | G8: 2.57038e+08 | H8: 2.4333695e+08 | I8: 2.2780079e+08 | J8: 2.2594539e+08 | K8: 2.3281353e+08 | L8: 2.3532813e+08 | M8: 2.3295752e+08 | N8: 1.4441783e+08 | O8: 1.4219182e+08 | P8: 1.3898601e+08 | Q8: 91307954 | R8: 64954167 | S8: 66630415 | T8: 66455709 | U8: 65876339 | V8: 61511976 | W8: 62054152 | X8: 65413987 | Y8: 65841842
A9: DTwP-Hib | B9: 4569986.5 | C9: 2613786 | D9: 2314794.7 | E9: 4993056.6 | F9: 6731549.6 | G9: 5829500.6 | H9: 2388879.2 | I9: 2682334 | J9: 5503855 | K9: 6149962.6 | L9: 2755123.1 | M9: 3016433.5 | N9: 2770511.6 | O9: 2616817.9 | P9: 0 | Q9: 0 | R9: 0 | S9: 0 | T9: 0 | U9: 2577182.4 | V9: 2545600.6 | W9: 5826576.9 | X9: 5816636.4 | Y9: 5854584.9
A10: Penta | B10: 5598384.2 | C10: 11321282 | D10: 21742187 | E10: 23354085 | F10: 34313914 | G10: 44391890 | H10: 49168455 | I10: 61360525 | J10: 68262550 | K10: 1.2187766e+08 | L10: 1.237333e+08 | M10: 1.2984514e+08 | N10: 1.4280675e+08 | O10: 1.5122855e+08 | P10: 1.7549308e+08 | Q10: 2.3413333e+08 | R10: 2.6127633e+08 | S10: 2.6675755e+08 | T10: 2.7543893e+08 | U10: 2.8016166e+08 | V10: 2.6901659e+08 | W10: 2.5278201e+08 | X10: 2.761834e+08 | Y10: 2.8076815e+08
A11: Hexa | B11: 77147.621 | C11: 78898.436 | D11: 77949.259 | E11: 0 | F11: 0 | G11: 0 | H11: 0 | I11: 0 | J11: 0 | K11: 0 | L11: 0 | M11: 0 | N11: 0 | O11: 0 | P11: 0 | Q11: 14724.55 | R11: 213958.16 | S11: 0 | T11: 896285.53 | U11: 160009.85 | V11: 0 | W11: 0 | X11: 0 | Y11: 0
A12: IPV | B12: 0 | C12: 0 | D12: 0 | E12: 0 | F12: 0 | G12: 0 | H12: 538568.8 | I12: 572237.68 | J12: 1564054.1 | K12: 1802422.6 | L12: 1596326.4 | M12: 1432203.2 | N12: 1193206.4 | O12: 1051750 | P12: 838163.74 | Q12: 14134727 | R12: 45560280 | S12: 51668556 | T12: 65056521 | U12: 82074179 | V12: 79857578 | W12: 83779047 | X12: 1.1191097e+08 | Y12: 1.3081826e+08
A13: OPV | B13: 0 | C13: 0 | D13: 0 | E13: 0 | F13: 0 | G13: 0 | H13: 0 | I13: 0 | J13: 0 | K13: 0 | L13: 0 | M13: 0 | N13: 0 | O13: 0 | P13: 0 | Q13: 0 | R13: 3.2087685e+08 | S13: 4.5908099e+08 | T13: 4.5555962e+08 | U13: 4.6381819e+08 | V13: 4.458235e+08 | W13: 4.3840296e+08 | X13: 4.7027132e+08 | Y13: 4.7781351e+08
... A18: PCV | B18: 0 | C18: 0 | D18: 0 | E18: 0 | F18: 0 | G18: 0 | H18: 0 | I18: 6300.6316 | J18: 1716887.9 | K18: 1579536.4 | L18: 9327523.8 | M18: 23147609 | N18: 41170015 | O18: 66222136 | P18: 89756384 | Q18: 1.0760398e+08 | R18: 1.2732722e+08 | S18: 1.3652887e+08 | T18: 1.455625e+08 | U18: 1.4181183e+08 | V18: 1.6080023e+08 | W18: 1.869961e+08 | X18: 2.0916547e+08 | Y18: 2.0593845e+08
A20: M | B20: =+"["&ROUND(B2,0)&"," -> [78580259, | C20: =+ROUND(C2,0)&"," -> 11429, | D20: =+ROUND(D2,0)&"," -> 10933, | E20: =+ROUND(E2,0)&"," -> 10568, | F20: =+ROUND(F2,0)&"," -> 10632, | G20: =+ROUND(G2,0)&"," -> 10866, | H20: =+ROUND(H2,0)&"," -> 11173, | I20: =+ROUND(I2,0)&"," -> 11270, | J20: =+ROUND(J2,0)&"," -> 11244, | ... X20: =+ROUND(X2,0)&"," -> 37949221, | Y20: =+ROUND(Y2,0)&"]" -> 17547796]
A21: MR | B21: =+"["&ROUND(B3,0)&"," -> [16708549, | C21: =+ROUND(C3,0)&"," -> 16708884, | D21: =+ROUND(D3,0)&"," -> 16621239, | E21: =+ROUND(E3,0)&"," -> 16912299, | F21: =+ROUND(F3,0)&"," -> 17990793, | G21: =+ROUND(G3,0)&"," -> 32224595, | H21: =+ROUND(H3,0)&"," -> 36010296, | I21: =+ROUND(I3,0)&"," -> 35638479, | J21: =+ROUND(J3,0)&"," -> 21093263, | ... X21: =+ROUND(X3,0)&"," -> 227385022, | Y21: =+ROUND(Y3,0)&"]" -> 278835991]
A22: MMR | B22: =+"["&ROUND(B4,0)&"," -> [14895547, | C22: =+ROUND(C4,0)&"," -> 15916937, | D22: =+ROUND(D4,0)&"," -> 16440302, | E22: =+ROUND(E4,0)&"," -> 17051794, | F22: =+ROUND(F4,0)&"," -> 25753121, | G22: =+ROUND(G4,0)&"," -> 26516485, | H22: =+ROUND(H4,0)&"," -> 28053836, | I22: =+ROUND(I4,0)&"," -> 27963867, | J22: =+ROUND(J4,0)&"," -> 39454389, | ... X22: =+ROUND(X4,0)&"," -> 26626399, | Y22: =+ROUND(Y4,0)&"]" -> 25785425]
A23: TT | B23: =+"["&ROUND(B5,0)&"," -> [78159429, | C23: =+ROUND(C5,0)&"," -> 79754932, | D23: =+ROUND(D5,0)&"," -> 82572072, | E23: =+ROUND(E5,0)&"," -> 85747371, | F23: =+ROUND(F5,0)&"," -> 88823502, | G23: =+ROUND(G5,0)&"," -> 90980826, | H23: =+ROUND(H5,0)&"," -> 93434225, | I23: =+ROUND(I5,0)&"," -> 98105258, | J23: =+ROUND(J5,0)&"," -> 101078446, | ... X23: =+ROUND(X5,0)&"," -> 6811040, | Y23: =+ROUND(Y5,0)&"]" -> 6823078]
A24: Td | B24: =+"["&ROUND(B6,0)&"," -> [50764265, | C24: =+ROUND(C6,0)&"," -> 50774338, | D24: =+ROUND(D6,0)&"," -> 50335232, | E24: =+ROUND(E6,0)&"," -> 52856121, | F24: =+ROUND(F6,0)&"," -> 69969918, | G24: =+ROUND(G6,0)&"," -> 68257615, | H24: =+ROUND(H6,0)&"," -> 54723843, | I24: =+ROUND(I6,0)&"," -> 53185019, | J24: =+ROUND(J6,0)&"," -> 38358186, | ... X24: =+ROUND(X6,0)&"," -> 265683552, | Y24: =+ROUND(Y6,0)&"]" -> 267449255]
A25: DT | B25: =+"["&ROUND(B7,0)&"," -> [20923950, | C25: =+ROUND(C7,0)&"," -> 20532694, | D25: =+ROUND(D7,0)&"," -> 20111575, | E25: =+ROUND(E7,0)&"," -> 19392670, | F25: =+ROUND(F7,0)&"," -> 19054703, | G25: =+ROUND(G7,0)&"," -> 18693918, | H25: =+ROUND(H7,0)&"," -> 20305662, | I25: =+ROUND(I7,0)&"," -> 19916222, | J25: =+ROUND(J7,0)&"," -> 19937956, | ... X25: =+ROUND(X7,0)&"," -> 6442339, | Y25: =+ROUND(Y7,0)&"]" -> 6541568]
A26: DTwP | B26: =+"["&ROUND(B8,0)&"," -> [311598814, | C26: =+ROUND(C8,0)&"," -> 314913213, | D26: =+ROUND(D8,0)&"," -> 275098221, | E26: =+ROUND(E8,0)&"," -> 262871460, | F26: =+ROUND(F8,0)&"," -> 261128636, | G26: =+ROUND(G8,0)&"," -> 257038005, | H26: =+ROUND(H8,0)&"," -> 243336949, | I26: =+ROUND(I8,0)&"," -> 227800791, | J26: =+ROUND(J8,0)&"," -> 225945394, | ... X26: =+ROUND(X8,0)&"," -> 65413987, | Y26: =+ROUND(Y8,0)&"]" -> 65841842]
A27: DTwP-Hib | B27: =+"["&ROUND(B9,0)&"," -> [4569987, | C27: =+ROUND(C9,0)&"," -> 2613786, | D27: =+ROUND(D9,0)&"," -> 2314795, | E27: =+ROUND(E9,0)&"," -> 4993057, | F27: =+ROUND(F9,0)&"," -> 6731550, | G27: =+ROUND(G9,0)&"," -> 5829501, | H27: =+ROUND(H9,0)&"," -> 2388879, | I27: =+ROUND(I9,0)&"," -> 2682334, | J27: =+ROUND(J9,0)&"," -> 5503855, | ... X27: =+ROUND(X9,0)&"," -> 5816636, | Y27: =+ROUND(Y9,0)&"]" -> 5854585]
A28: Penta | B28: =+"["&ROUND(B10,0)&"," -> [5598384, | C28: =+ROUND(C10,0)&"," -> 11321282, | D28: =+ROUND(D10,0)&"," -> 21742187, | E28: =+ROUND(E10,0)&"," -> 23354085, | F28: =+ROUND(F10,0)&"," -> 34313914, | G28: =+ROUND(G10,0)&"," -> 44391890, | H28: =+ROUND(H10,0)&"," -> 49168455, | I28: =+ROUND(I10,0)&"," -> 61360525, | J28: =+ROUND(J10,0)&"," -> 68262550, | ... X28: =+ROUND(X10,0)&"," -> 276183400, | Y28: =+ROUND(Y10,0)&"]" -> 280768151]
A29: Hexa | B29: =+"["&ROUND(B11,0)&"," -> [77148, | C29: =+ROUND(C11,0)&"," -> 78898, | D29: =+ROUND(D11,0)&"," -> 77949, | E29: =+ROUND(E11,0)&"," -> 0, | F29: =+ROUND(F11,0)&"," -> 0, | G29: =+ROUND(G11,0)&"," -> 0, | H29: =+ROUND(H11,0)&"," -> 0, | I29: =+ROUND(I11,0)&"," -> 0, | J29: =+ROUND(J11,0)&"," -> 0, | ... X29: =+ROUND(X11,0)&"," -> 0, | Y29: =+ROUND(Y11,0)&"]" -> 0]
A30: IPV | B30: =+"["&ROUND(B12,0)&"," -> [0, | C30: =+ROUND(C12,0)&"," -> 0, | D30: =+ROUND(D12,0)&"," -> 0, | E30: =+ROUND(E12,0)&"," -> 0, | F30: =+ROUND(F12,0)&"," -> 0, | G30: =+ROUND(G12,0)&"," -> 0, | H30: =+ROUND(H12,0)&"," -> 538569, | I30: =+ROUND(I12,0)&"," -> 572238, | J30: =+ROUND(J12,0)&"," -> 1564054, | ... X30: =+ROUND(X12,0)&"," -> 111910967, | Y30: =+ROUND(Y12,0)&"]" -> 130818258]
A31: OPV | B31: =+"["&ROUND(B13,0)&"," -> [0, | C31: =+ROUND(C13,0)&"," -> 0, | D31: =+ROUND(D13,0)&"," -> 0, | E31: =+ROUND(E13,0)&"," -> 0, | F31: =+ROUND(F13,0)&"," -> 0, | G31: =+ROUND(G13,0)&"," -> 0, | H31: =+ROUND(H13,0)&"," -> 0, | I31: =+ROUND(I13,0)&"," -> 0, | J31: =+ROUND(J13,0)&"," -> 0, | ... X31: =+ROUND(X13,0)&"," -> 470271315, | Y31: =+ROUND(Y13,0)&"]" -> 477813507]
... A36: PCV | B36: =+"["&ROUND(B18,0)&"," -> [0, | C36: =+ROUND(C18,0)&"," -> 0, | D36: =+ROUND(D18,0)&"," -> 0, | E36: =+ROUND(E18,0)&"," -> 0, | F36: =+ROUND(F18,0)&"," -> 0, | G36: =+ROUND(G18,0)&"," -> 0, | H36: =+ROUND(H18,0)&"," -> 0, | I36: =+ROUND(I18,0)&"," -> 6301, | J36: =+ROUND(J18,0)&"," -> 1716888, | ... X36: =+ROUND(X18,0)&"," -> 209165466, | Y36: =+ROUND(Y18,0)&"]" -> 205938451]
A38: M | B38: =+_xlfn.CONCAT(B20:Y20)&"," -> [78580259,11429,10933,10568,10632,10866,11173,11270,11244,0,17696391,17721468,8703411,26868698,28597586,31745853,19409700,36511824,18347409,14873766,9862745,14777182,37949221,17547796],
A39: MR | B39: =+_xlfn.CONCAT(B21:Y21)&"," -> [16708549,16708884,16621239,16912299,17990793,32224595,36010296,35638479,21093263,22353125,22384691,21083590,4248061,15084549,24102254,101868384,89505897,166340121,410169950,332425433,194291047,331279149,227385022,278835991],
A40: MMR | B40: =+_xlfn.CONCAT(B22:Y22)&"," -> [14895547,15916937,16440302,17051794,25753121,26516485,28053836,27963867,39454389,41213109,42926745,42885187,22148782,22105642,19837777,26434485,20737739,20303126,23934205,21792972,18694960,26052156,26626399,25785425],
A41: TT | B41: =+_xlfn.CONCAT(B23:Y23)&"," -> [78159429,79754932,82572072,85747371,88823502,90980826,93434225,98105258,101078446,104582797,105776185,135372841,148582724,164282756,173551045,177885695,149831514,186085427,164768261,42499760,10518908,7180031,6811040,6823078],
A42: Td | B42: =+_xlfn.CONCAT(B24:Y24)&"," -> [50764265,50774338,50335232,52856121,69969918,68257615,54723843,53185019,38358186,36289140,31847542,29878049,27224651,28389437,29041953,34928665,74784906,94070116,129988736,244473057,268834028,243482509,265683552,267449255],
A43: DT | B43: =+_xlfn.CONCAT(B25:Y25)&"," -> [20923950,20532694,20111575,19392670,19054703,18693918,20305662,19916222,19937956,19825404,19155299,19326301,1956107,1868860,1900870,1887281,1784487,2200513,2217689,2177788,5062812,6404902,6442339,6541568],
A44: DTwP | B44: =+_xlfn.CONCAT(B26:Y26)&"," -> [311598814,314913213,275098221,262871460,261128636,257038005,243336949,227800791,225945394,232813533,235328126,232957520,144417830,142191817,138986008,91307954,64954167,66630415,66455709,65876339,61511976,62054152,65413987,65841842],
A45: DTwP-Hib | B45: =+_xlfn.CONCAT(B27:Y27)&"," -> [4569987,2613786,2314795,4993057,6731550,5829501,2388879,2682334,5503855,6149963,2755123,3016434,2770512,2616818,0,0,0,0,0,2577182,2545601,5826577,5816636,5854585],
A46: Penta | B46: =+_xlfn.CONCAT(B28:Y28)&"," -> [5598384,11321282,21742187,23354085,34313914,44391890,49168455,61360525,68262550,121877662,123733297,129845142,142806746,151228547,175493079,234133328,261276329,266757549,275438932,280161656,269016594,252782013,276183400,280768151],
A47: Hexa | B47: =+_xlfn.CONCAT(B29:Y29)&"," -> [77148,78898,77949,0,0,0,0,0,0,0,0,0,0,0,0,14725,213958,0,896286,160010,0,0,0,0],
A48: IPV | B48: =+_xlfn.CONCAT(B30:Y30)&"," -> [0,0,0,0,0,0,538569,572238,1564054,1802423,1596326,1432203,1193206,1051750,838164,14134727,45560280,51668556,65056521,82074179,79857578,83779047,111910967,130818258],
A49: OPV | B49: =+_xlfn.CONCAT(B31:Y31)&"," -> [0,0,0,0,0,0,0,0,0,0,0,0,0,0,0,0,320876850,459080986,455559619,463818185,445823504,438402962,470271315,477813507],
... A54: PCV | B54: =+_xlfn.CONCAT(B36:Y36)&"," -> [0,0,0,0,0,0,0,6301,1716888,1579536,9327524,23147609,41170015,66222136,89756384,107603981,127327221,136528866,145562505,141811833,160800233,186996097,209165466,205938451],
...

Sheet Demand_data_trend_predictions
B1: 2000 | C1: 2001 | D1: 2002 | E1: 2003 | F1: 2004 | G1: 2005 | H1: 2006 | I1: 2007 | J1: 2008 | K1: 2009 | L1: 2010 | M1: 2011 | N1: 2012 | O1: 2013 | P1: 2014 | Q1: 2015 | R1: 2016 | S1: 2017 | T1: 2018 | U1: 2019 | V1: 2020 | W1: 2021 | X1: 2022 | Y1: 2023
A2: M | B2: 78580259 | C2: 11428.56 | D2: 10932.726 | E2: 10567.573 | F2: 10631.537 | G2: 10866.43 | H2: 11173.117 | I2: 11270.145 | J2: 11244.154 | K2: 0 | L2: 17696391 | M2: 17721468 | N2: 8703411.1 | O2: 26868698 | P2: 28597586 | Q2: 31745853 | R2: 19409700 | S2: 36511824 | T2: 18347409 | U2: 14873766 | V2: 9862745.1 | W2: 14777182 | X2: 37949221 | Y2: 17547796
A3: MR | B3: 16708549 | C3: 16708884 | D3: 16621239 | E3: 16912299 | F3: 17990793 | G3: 32224595 | H3: 36010296 | I3: 35638479 | J3: 21093263 | K3: 22353125 | L3: 22384691 | M3: 21083590 | N3: 4248060.8 | O3: 15084549 | P3: 24102254 | Q3: 1.0186838e+08 | R3: 89505897 | S3: 1.6634012e+08 | T3: 4.1016995e+08 | U3: 3.3242543e+08 | V3: 1.9429105e+08 | W3: 3.3127915e+08 | X3: 2.2738502e+08 | Y3: 2.7883599e+08
A4: MMR | B4: 14895547 | C4: 15916937 | D4: 16440302 | E4: 17051794 | F4: 25753121 | G4: 26516485 | H4: 28053836 | I4: 27963867 | J4: 39454389 | K4: 41213109 | L4: 42926745 | M4: 42885187 | N4: 22148782 | O4: 22105642 | P4: 19837777 | Q4: 26434485 | R4: 20737739 | S4: 20303126 | T4: 23934205 | U4: 21792972 | V4: 18694960 | W4: 26052156 | X4: 26626399 | Y4: 25785425
A5: TT | B5: 78159429 | C5: 79754932 | D5: 82572072 | E5: 85747371 | F5: 88823502 | G5: 90980826 | H5: 93434225 | I5: 98105258 | J5: 1.0107845e+08 | K5: 1.045828e+08 | L5: 1.0577618e+08 | M5: 1.3537284e+08 | N5: 1.4858272e+08 | O5: 1.6428276e+08 | P5: 1.7355105e+08 | Q5: 1.7788569e+08 | R5: 1.4983151e+08 | S5: 1.8608543e+08 | T5: 1.6476826e+08 | U5: 42499760 | V5: 10518908 | W5: 7180030.7 | X5: 6811039.8 | Y5: 6823077.8
A6: Td | B6: 50764265 | C6: 50774338 | D6: 50335232 | E6: 52856121 | F6: 69969918 | G6: 68257615 | H6: 54723843 | I6: 53185019 | J6: 38358186 | K6: 36289140 | L6: 31847542 | M6: 29878049 | N6: 27224651 | O6: 28389437 | P6: 29041953 | Q6: 34928665 | R6: 74784906 | S6: 94070116 | T6: 1.2998874e+08 | U6: 2.4447306e+08 | V6: 2.6883403e+08 | W6: 2.4348251e+08 | X6: 2.6568355e+08 | Y6: 2.6744926e+08
A7: DT | B7: 20923950 | C7: 20532694 | D7: 20111575 | E7: 19392670 | F7: 19054703 | G7: 18693918 | H7: 20305662 | I7: 19916222 | J7: 19937956 | K7: 19825404 | L7: 19155299 | M7: 19326301 | N7: 1956106.5 | O7: 1868860.1 | P7: 1900870.4 | Q7: 1887280.7 | R7: 1784486.6 | S7: 2200512.6 | T7: 2217689.2 | U7: 2177787.6 | V7: 5062812 | W7: 6404902 | X7: 6442339.5 | Y7: 6541567.8
A8: DTwP | B8: 3.1159881e+08 | C8: 3.1491321e+08 | D8: 2.7509822e+08 | E8: 2.6287146e+08 | F8: 2.6112864e+08 | G8: 2.57038e+08 | H8: 2.4333695e+08 | I8: 2.2780079e+08 | J8: 2.2594539e+08 | K8: 2.3281353e+08 | L8: 2.3532813e+08 | M8: 2.3295752e+08 | N8: 1.4441783e+08 | O8: 1.4219182e+08 | P8: 1.3898601e+08 | Q8: 91307954 | R8: 64954167 | S8: 66630415 | T8: 66455709 | U8: 65876339 | V8: 61511976 | W8: 62054152 | X8: 65413987 | Y8: 65841842
A9: DTwP-Hib | B9: 4569986.5 | C9: 2613786 | D9: 2314794.7 | E9: 4993056.6 | F9: 6731549.6 | G9: 5829500.6 | H9: 2388879.2 | I9: 2682334 | J9: 5503855 | K9: 6149962.6 | L9: 2755123.1 | M9: 3016433.5 | N9: 2770511.6 | O9: 2616817.9 | P9: 0 | Q9: 0 | R9: 0 | S9: 0 | T9: 0 | U9: 2577182.4 | V9: 2545600.6 | W9: 5826576.9 | X9: 5816636.4 | Y9: 5854584.9
A10: Penta | B10: 5598384.2 | C10: 11321282 | D10: 21742187 | E10: 23354085 | F10: 34313914 | G10: 44391890 | H10: 49168455 | I10: 61360525 | J10: 68262550 | K10: 1.2187766e+08 | L10: 1.237333e+08 | M10: 1.2984514e+08 | N10: 1.4280675e+08 | O10: 1.5122855e+08 | P10: 1.7549308e+08 | Q10: 2.3413333e+08 | R10: 2.6127633e+08 | S10: 2.6675755e+08 | T10: 2.7543893e+08 | U10: 2.8016166e+08 | V10: 2.6901659e+08 | W10: 2.5278201e+08 | X10: 2.761834e+08 | Y10: 2.8076815e+08
A11: Hexa | B11: 77147.621 | C11: 78898.436 | D11: 77949.259 | E11: 0 | F11: 0 | G11: 0 | H11: 0 | I11: 0 | J11: 0 | K11: 0 | L11: 0 | M11: 0 | N11: 0 | O11: 0 | P11: 0 | Q11: 14724.55 | R11: 213958.16 | S11: 0 | T11: 896285.53 | U11: 160009.85 | V11: 0 | W11: 0 | X11: 0 | Y11: 0
A12: IPV | B12: 0 | C12: 0 | D12: 0 | E12: 0 | F12: 0 | G12: 0 | H12: 538568.8 | I12: 572237.68 | J12: 1564054.1 | K12: 1802422.6 | L12: 1596326.4 | M12: 1432203.2 | N12: 1193206.4 | O12: 1051750 | P12: 838163.74 | Q12: 14134727 | R12: 45560280 | S12: 51668556 | T12: 65056521 | U12: 82074179 | V12: 79857578 | W12: 83779047 | X12: 1.1191097e+08 | Y12: 1.3081826e+08
A13: OPV | B13: 0 | C13: 0 | D13: 0 | E13: 0 | F13: 0 | G13: 0 | H13: 0 | I13: 0 | J13: 0 | K13: 0 | L13: 0 | M13: 0 | N13: 0 | O13: 0 | P13: 0 | Q13: 0 | R13: 3.2087685e+08 | S13: 4.5908099e+08 | T13: 4.5555962e+08 | U13: 4.6381819e+08 | V13: 4.458235e+08 | W13: 4.3840296e+08 | X13: 4.7027132e+08 | Y13: 4.7781351e+08
... A18: PCV | B18: 0 | C18: 0 | D18: 0 | E18: 0 | F18: 0 | G18: 0 | H18: 0 | I18: 6300.6316 | J18: 1716887.9 | K18: 1579536.4 | L18: 9327523.8 | M18: 23147609 | N18: 41170015 | O18: 66222136 | P18: 89756384 | Q18: 1.0760398e+08 | R18: 1.2732722e+08 | S18: 1.3652887e+08 | T18: 1.455625e+08 | U18: 1.4181183e+08 | V18: 1.6080023e+08 | W18: 1.869961e+08 | X18: 2.0916547e+08 | Y18: 2.0593845e+08
A20: M | B20: =+"["&ROUND(B2,0)&"," -> [78580259, | C20: =+ROUND(C2,0)&"," -> 11429, | D20: =+ROUND(D2,0)&"," -> 10933, | E20: =+ROUND(E2,0)&"," -> 10568, | F20: =+ROUND(F2,0)&"," -> 10632, | G20: =+ROUND(G2,0)&"," -> 10866, | H20: =+ROUND(H2,0)&"," -> 11173, | I20: =+ROUND(I2,0)&"," -> 11270, | J20: =+ROUND(J2,0)&"," -> 11244, | ... X20: =+ROUND(X2,0)&"," -> 37949221, | Y20: =+ROUND(Y2,0)&"]" -> 17547796]
A21: MR | B21: =+"["&ROUND(B3,0)&"," -> [16708549, | C21: =+ROUND(C3,0)&"," -> 16708884, | D21: =+ROUND(D3,0)&"," -> 16621239, | E21: =+ROUND(E3,0)&"," -> 16912299, | F21: =+ROUND(F3,0)&"," -> 17990793, | G21: =+ROUND(G3,0)&"," -> 32224595, | H21: =+ROUND(H3,0)&"," -> 36010296, | I21: =+ROUND(I3,0)&"," -> 35638479, | J21: =+ROUND(J3,0)&"," -> 21093263, | ... X21: =+ROUND(X3,0)&"," -> 227385022, | Y21: =+ROUND(Y3,0)&"]" -> 278835991]
A22: MMR | B22: =+"["&ROUND(B4,0)&"," -> [14895547, | C22: =+ROUND(C4,0)&"," -> 15916937, | D22: =+ROUND(D4,0)&"," -> 16440302, | E22: =+ROUND(E4,0)&"," -> 17051794, | F22: =+ROUND(F4,0)&"," -> 25753121, | G22: =+ROUND(G4,0)&"," -> 26516485, | H22: =+ROUND(H4,0)&"," -> 28053836, | I22: =+ROUND(I4,0)&"," -> 27963867, | J22: =+ROUND(J4,0)&"," -> 39454389, | ... X22: =+ROUND(X4,0)&"," -> 26626399, | Y22: =+ROUND(Y4,0)&"]" -> 25785425]
A23: TT | B23: =+"["&ROUND(B5,0)&"," -> [78159429, | C23: =+ROUND(C5,0)&"," -> 79754932, | D23: =+ROUND(D5,0)&"," -> 82572072, | E23: =+ROUND(E5,0)&"," -> 85747371, | F23: =+ROUND(F5,0)&"," -> 88823502, | G23: =+ROUND(G5,0)&"," -> 90980826, | H23: =+ROUND(H5,0)&"," -> 93434225, | I23: =+ROUND(I5,0)&"," -> 98105258, | J23: =+ROUND(J5,0)&"," -> 101078446, | ... X23: =+ROUND(X5,0)&"," -> 6811040, | Y23: =+ROUND(Y5,0)&"]" -> 6823078]
A24: Td | B24: =+"["&ROUND(B6,0)&"," -> [50764265, | C24: =+ROUND(C6,0)&"," -> 50774338, | D24: =+ROUND(D6,0)&"," -> 50335232, | E24: =+ROUND(E6,0)&"," -> 52856121, | F24: =+ROUND(F6,0)&"," -> 69969918, | G24: =+ROUND(G6,0)&"," -> 68257615, | H24: =+ROUND(H6,0)&"," -> 54723843, | I24: =+ROUND(I6,0)&"," -> 53185019, | J24: =+ROUND(J6,0)&"," -> 38358186, | ... X24: =+ROUND(X6,0)&"," -> 265683552, | Y24: =+ROUND(Y6,0)&"]" -> 267449255]
A25: DT | B25: =+"["&ROUND(B7,0)&"," -> [20923950, | C25: =+ROUND(C7,0)&"," -> 20532694, | D25: =+ROUND(D7,0)&"," -> 20111575, | E25: =+ROUND(E7,0)&"," -> 19392670, | F25: =+ROUND(F7,0)&"," -> 19054703, | G25: =+ROUND(G7,0)&"," -> 18693918, | H25: =+ROUND(H7,0)&"," -> 20305662, | I25: =+ROUND(I7,0)&"," -> 19916222, | J25: =+ROUND(J7,0)&"," -> 19937956, | ... X25: =+ROUND(X7,0)&"," -> 6442339, | Y25: =+ROUND(Y7,0)&"]" -> 6541568]
A26: DTwP | B26: =+"["&ROUND(B8,0)&"," -> [311598814, | C26: =+ROUND(C8,0)&"," -> 314913213, | D26: =+ROUND(D8,0)&"," -> 275098221, | E26: =+ROUND(E8,0)&"," -> 262871460, | F26: =+ROUND(F8,0)&"," -> 261128636, | G26: =+ROUND(G8,0)&"," -> 257038005, | H26: =+ROUND(H8,0)&"," -> 243336949, | I26: =+ROUND(I8,0)&"," -> 227800791, | J26: =+ROUND(J8,0)&"," -> 225945394, | ... X26: =+ROUND(X8,0)&"," -> 65413987, | Y26: =+ROUND(Y8,0)&"]" -> 65841842]
A27: DTwP-Hib | B27: =+"["&ROUND(B9,0)&"," -> [4569987, | C27: =+ROUND(C9,0)&"," -> 2613786, | D27: =+ROUND(D9,0)&"," -> 2314795, | E27: =+ROUND(E9,0)&"," -> 4993057, | F27: =+ROUND(F9,0)&"," -> 6731550, | G27: =+ROUND(G9,0)&"," -> 5829501, | H27: =+ROUND(H9,0)&"," -> 2388879, | I27: =+ROUND(I9,0)&"," -> 2682334, | J27: =+ROUND(J9,0)&"," -> 5503855, | ... X27: =+ROUND(X9,0)&"," -> 5816636, | Y27: =+ROUND(Y9,0)&"]" -> 5854585]
A28: Penta | B28: =+"["&ROUND(B10,0)&"," -> [5598384, | C28: =+ROUND(C10,0)&"," -> 11321282, | D28: =+ROUND(D10,0)&"," -> 21742187, | E28: =+ROUND(E10,0)&"," -> 23354085, | F28: =+ROUND(F10,0)&"," -> 34313914, | G28: =+ROUND(G10,0)&"," -> 44391890, | H28: =+ROUND(H10,0)&"," -> 49168455, | I28: =+ROUND(I10,0)&"," -> 61360525, | J28: =+ROUND(J10,0)&"," -> 68262550, | ... X28: =+ROUND(X10,0)&"," -> 276183400, | Y28: =+ROUND(Y10,0)&"]" -> 280768151]
A29: Hexa | B29: =+"["&ROUND(B11,0)&"," -> [77148, | C29: =+ROUND(C11,0)&"," -> 78898, | D29: =+ROUND(D11,0)&"," -> 77949, | E29: =+ROUND(E11,0)&"," -> 0, | F29: =+ROUND(F11,0)&"," -> 0, | G29: =+ROUND(G11,0)&"," -> 0, | H29: =+ROUND(H11,0)&"," -> 0, | I29: =+ROUND(I11,0)&"," -> 0, | J29: =+ROUND(J11,0)&"," -> 0, | ... X29: =+ROUND(X11,0)&"," -> 0, | Y29: =+ROUND(Y11,0)&"]" -> 0]
A30: IPV | B30: =+"["&ROUND(B12,0)&"," -> [0, | C30: =+ROUND(C12,0)&"," -> 0, | D30: =+ROUND(D12,0)&"," -> 0, | E30: =+ROUND(E12,0)&"," -> 0, | F30: =+ROUND(F12,0)&"," -> 0, | G30: =+ROUND(G12,0)&"," -> 0, | H30: =+ROUND(H12,0)&"," -> 538569, | I30: =+ROUND(I12,0)&"," -> 572238, | J30: =+ROUND(J12,0)&"," -> 1564054, | ... X30: =+ROUND(X12,0)&"," -> 111910967, | Y30: =+ROUND(Y12,0)&"]" -> 130818258]
A31: OPV | B31: =+"["&ROUND(B13,0)&"," -> [0, | C31: =+ROUND(C13,0)&"," -> 0, | D31: =+ROUND(D13,0)&"," -> 0, | E31: =+ROUND(E13,0)&"," -> 0, | F31: =+ROUND(F13,0)&"," -> 0, | G31: =+ROUND(G13,0)&"," -> 0, | H31: =+ROUND(H13,0)&"," -> 0, | I31: =+ROUND(I13,0)&"," -> 0, | J31: =+ROUND(J13,0)&"," -> 0, | ... X31: =+ROUND(X13,0)&"," -> 470271315, | Y31: =+ROUND(Y13,0)&"]" -> 477813507]
... A36: PCV | B36: =+"["&ROUND(B18,0)&"," -> [0, | C36: =+ROUND(C18,0)&"," -> 0, | D36: =+ROUND(D18,0)&"," -> 0, | E36: =+ROUND(E18,0)&"," -> 0, | F36: =+ROUND(F18,0)&"," -> 0, | G36: =+ROUND(G18,0)&"," -> 0, | H36: =+ROUND(H18,0)&"," -> 0, | I36: =+ROUND(I18,0)&"," -> 6301, | J36: =+ROUND(J18,0)&"," -> 1716888, | ... X36: =+ROUND(X18,0)&"," -> 209165466, | Y36: =+ROUND(Y18,0)&"]" -> 205938451]
A38: M | B38: =+_xlfn.CONCAT(B20:Y20)&"," -> [78580259,11429,10933,10568,10632,10866,11173,11270,11244,0,17696391,17721468,8703411,26868698,28597586,31745853,19409700,36511824,18347409,14873766,9862745,14777182,37949221,17547796],
A39: MR | B39: =+_xlfn.CONCAT(B21:Y21)&"," -> [16708549,16708884,16621239,16912299,17990793,32224595,36010296,35638479,21093263,22353125,22384691,21083590,4248061,15084549,24102254,101868384,89505897,166340121,410169950,332425433,194291047,331279149,227385022,278835991],
A40: MMR | B40: =+_xlfn.CONCAT(B22:Y22)&"," -> [14895547,15916937,16440302,17051794,25753121,26516485,28053836,27963867,39454389,41213109,42926745,42885187,22148782,22105642,19837777,26434485,20737739,20303126,23934205,21792972,18694960,26052156,26626399,25785425],
A41: TT | B41: =+_xlfn.CONCAT(B23:Y23)&"," -> [78159429,79754932,82572072,85747371,88823502,90980826,93434225,98105258,101078446,104582797,105776185,135372841,148582724,164282756,173551045,177885695,149831514,186085427,164768261,42499760,10518908,7180031,6811040,6823078],
A42: Td | B42: =+_xlfn.CONCAT(B24:Y24)&"," -> [50764265,50774338,50335232,52856121,69969918,68257615,54723843,53185019,38358186,36289140,31847542,29878049,27224651,28389437,29041953,34928665,74784906,94070116,129988736,244473057,268834028,243482509,265683552,267449255],
A43: DT | B43: =+_xlfn.CONCAT(B25:Y25)&"," -> [20923950,20532694,20111575,19392670,19054703,18693918,20305662,19916222,19937956,19825404,19155299,19326301,1956107,1868860,1900870,1887281,1784487,2200513,2217689,2177788,5062812,6404902,6442339,6541568],
A44: DTwP | B44: =+_xlfn.CONCAT(B26:Y26)&"," -> [311598814,314913213,275098221,262871460,261128636,257038005,243336949,227800791,225945394,232813533,235328126,232957520,144417830,142191817,138986008,91307954,64954167,66630415,66455709,65876339,61511976,62054152,65413987,65841842],
A45: DTwP-Hib | B45: =+_xlfn.CONCAT(B27:Y27)&"," -> [4569987,2613786,2314795,4993057,6731550,5829501,2388879,2682334,5503855,6149963,2755123,3016434,2770512,2616818,0,0,0,0,0,2577182,2545601,5826577,5816636,5854585],
A46: Penta | B46: =+_xlfn.CONCAT(B28:Y28)&"," -> [5598384,11321282,21742187,23354085,34313914,44391890,49168455,61360525,68262550,121877662,123733297,129845142,142806746,151228547,175493079,234133328,261276329,266757549,275438932,280161656,269016594,252782013,276183400,280768151],
A47: Hexa | B47: =+_xlfn.CONCAT(B29:Y29)&"," -> [77148,78898,77949,0,0,0,0,0,0,0,0,0,0,0,0,14725,213958,0,896286,160010,0,0,0,0],
A48: IPV | B48: =+_xlfn.CONCAT(B30:Y30)&"," -> [0,0,0,0,0,0,538569,572238,1564054,1802423,1596326,1432203,1193206,1051750,838164,14134727,45560280,51668556,65056521,82074179,79857578,83779047,111910967,130818258],
A49: OPV | B49: =+_xlfn.CONCAT(B31:Y31)&"," -> [0,0,0,0,0,0,0,0,0,0,0,0,0,0,0,0,320876850,459080986,455559619,463818185,445823504,438402962,470271315,477813507],
... A54: PCV | B54: =+_xlfn.CONCAT(B36:Y36)&"," -> [0,0,0,0,0,0,0,6301,1716888,1579536,9327524,23147609,41170015,66222136,89756384,107603981,127327221,136528866,145562505,141811833,160800233,186996097,209165466,205938451],
...

Sheet Medium_Demand_calc
B1: 1 | C1: 2 | D1: 3 | E1: 4 | F1: 5 | G1: 6 | H1: 7 | I1: 8 | J1: 9 | K1: 10
A2: M | B2: 14777182 | C2: 37949221 | D2: 17547796 | E2: 21303105 | F2: 22347713 | G2: 20946970 | H2: 19884769 | I2: 20824130 | J2: 21884645 | K2: 22913489
A3: MR | B3: 3.3127915e+08 | C3: 2.2738502e+08 | D3: 2.7883599e+08 | E3: 2.516257e+08 | F3: 2.6781107e+08 | G3: 3.7033728e+08 | H3: 2.4042417e+08 | I3: 3.7678179e+08 | J3: 2.7887392e+08 | K3: 3.1287896e+08
A4: MMR | B4: 26052156 | C4: 26626399 | D4: 25785425 | E4: 25268101 | F4: 23536241 | G4: 16205416 | H4: 18650430 | I4: 8909629.5 | J4: 10718460 | K4: 12977659
